Workbook
Name Liste: parameters!$A$2:$A$3
Name liste1: #REF!
Name liste2: #REF!
Name SOCIETE: parameters!$A$8:$A$55

Sheet read me
B1: INSTRUCTIONS FOR USE
B3: The aim of this document is to follow the orderbook per week.
B5: This document has to be sent each Friday afternoon to : | H5: dashboard@diaminter.com
B11: How to fill in the document :
C13: 1 | D13: Select the worksheet for the appropriate week
C15: 2 | D15: Fill in your company name in the cell G2
C17: 3 | D17: The current month corresponding to the week is automatically mentionned: please make sure to report data for this month (and not previous or next one when the week runs over two different months)
C19: 4 | D19: Column E : Fill in product name
C21: 5 | D21: Column F : Fill in customers statut (external or internal customers)
C23: 6 | D23: Column G : fill in the customers name
C25: 7 | D25: Please never correct the worksheet of a past week
C27: 8 | D27: You can update the pivot tables on the worksheet [analysis week] to see the detailed variations by customers in the orderbook from previous week to ongoing week
C29: 9 | D29: This is a synthesis of the orders taken and the sales invoiced during the year. Please update the YTD figures at the end of each months (yellow cells) to show the
B33: IMPORTANT : At the end of the month, orders not yet delivered, have to be automatically transferred to the next month.
D34: Once the orders have been invoiced (and so the amount is indicated as turnover), the orders should disappear of the table.

Sheet parameters
D1: Entity to select
A2: Group | D2: Diam India
A3: External
D4: =VLOOKUP(D2,$A$8:$C$52,3,FALSE) -> k€
A8: TO SELECT | B8: Automatic data
A9: Diam France | B9: DFR | C9: k€ | G9: W1 | H9: January | J9: January | K9: 46023
A10: Diam Lurcy | B10: DLU | C10: k€ | G10: W2 | H10: January | I10: W1 | J10: February | K10: 46054
A11: Diam Yzeure | B11: DYZ | C11: k€ | G11: W3 | H11: January | I11: W2 | J11: March | K11: 46082
A12: Diam Tunisie | B12: DTN | C12: k€ | G12: W4 | H12: January | I12: W3 | J12: April | K12: 46113
A13: Diam Tunisie Prestige | B13: DTP | C13: k€ | G13: W5 | H13: January | I13: W4 | J13: May | K13: 46143
A14: Diam Turkey | B14: DTK | C14: k€ | G14: W6 | H14: February | I14: W5 | J14: June | K14: 46174
A15: Diam Italy | B15: DIT | C15: k€ | G15: W7 | H15: February | I15: W6 | J15: July | K15: 46204
A16: Diam Prestige Europe | B16: PEM | C16: k€ | G16: W8 | H16: February | I16: W7 | J16: August | K16: 46235
A17: Diam UK | B17: DUK | C17: k£ | G17: W9 | H17: February | I17: W8 | J17: September | K17: 46266
A18: Fieldflex UK | B18: FFUK | C18: k£ | G18: W10 | H18: March | I18: W9 | J18: October | K18: 46296
A19: Diam Germany | B19: DEU | C19: k€ | G19: W11 | H19: March | I19: W10 | J19: November | K19: 46327
A20: Diam Poland | B20: DPO | C20: k€ | G20: W12 | H20: March | I20: W11 | J20: December | K20: 46357
A21: Diam Premium North America | B21: DPN | C21: k$ | G21: W13 | H21: March | I21: W12
A22: D 3 LLC | B22: D3 | C22: k$ | G22: W14 | H22: April | I22: W13
A23: CONEX US | B23: CNX | C23: k$ | G23: W15 | H23: April | I23: W14
A24: CONEX EU | B24: CNE | C24: k€ | G24: W16 | H24: April | I24: W15
A25: CONEX APAC | B25: CNA | C25: k$ | G25: W17 | H25: April | I25: W16
A26: PRUGENT US | B26: PUS | C26: k$ | G26: W18 | H26: April | I26: W17
A27: Fieldflex US | B27: FFUS | C27: k$ | G27: W19 | H27: May | I27: W18
A28: Back to Diam | B28: B2D | C28: k$ | G28: W20 | H28: May | I28: W19
A29: Diam Mexico | B29: DMX | C29: k$ | G29: W21 | H29: May | I29: W20
A30: Diam Brazil | B30: DBR | C30: k€ | G30: W22 | H30: May | I30: W21
A31: Diam CHINA | B31: DDC | C31: k€ | G31: W23 | H31: June | I31: W22
A32: DE HONG KONG | B32: DEHK | C32: k€ | G32: W24 | H32: June | I32: W23
... A52: RETAIL 3D | B52: R3D | C52: k€ | G52: W44 | H52: October | I52: W43
G53: W45 | H53: November | I53: W44
G54: W46 | H54: November | I54: W45
G55: W47 | H55: November | I55: W46
G56: W48 | H56: November | I56: W47
G57: W49 | H57: December | I57: W48
G58: W50 | H58: December | I58: W49
G59: W51 | H59: December | I59: W50
G60: W52 | H60: December | I60: W51
G61: W53 | H61: December | I61: W52

Sheet analysis week
B2: Entity | C2: =+'W1'!G2 -> Diam India | D2: =VLOOKUP(C2, parameters!A:B, 2,0) -> DDI
B4: Week | C4: W2 | D4: =VLOOKUP(C4, parameters!G:I,3,0) -> W1
B7: Var 2026 | H7: Var 2027
C9: External | D9: Group | E9: Total | I9: External | J9: Group | K9: Total
B10: ="Var in sales 2025 - "&D4&" to "&C4 -> Var in sales 2025 - W1 to W2 | C10: =+C16-C22 -> 83.29574 | D10: =+D16-D22 -> 2.39 | E10: =+E16-E22 -> 85.68574 | H10: =+"Orderbook "&$C$4 -> Orderbook W2 | I10: {=INDIRECT(ADDRESS(17,12,,,$C$4))} -> 0 | J10: {=INDIRECT(ADDRESS(18,12,,,$C$4))} -> 0 | K10: =SUM(I10:J10) -> 0
B11: ="Var in orderbook 2025 - "&D4&" to "&C4 -> Var in orderbook 2025 - W1 to W2 | C11: =+C17-C23 -> 159.68244 | D11: =+D17-D23 -> 9.676436 | E11: =+E17-E23 -> 169.35888 | H11: =+"Orderbook "&$D$4 -> Orderbook W1 | I11: {=INDIRECT(ADDRESS(17,12,,,$D$4))} -> 0 | J11: {=INDIRECT(ADDRESS(18,12,,,$D$4))} -> 0 | K11: =SUM(I11:J11) -> 0
B12: ="Var in forecast 2025 - "&D4&" to "&C4 -> Var in forecast 2025 - W1 to W2 | C12: =+C18-C24 -> 242.97818 | D12: =+D18-D24 -> 12.066436 | E12: =+E18-E24 -> 255.04462 | H12: ="Var in orderbook - "&D4&" to "&C4 -> Var in orderbook - W1 to W2 | I12: =+I10-I11 -> 0 | J12: =+J10-J11 -> 0 | K12: =+K10-K11 -> 0
C13: =+C12-SUM(C10:C11) -> 0 | D13: =+D12-SUM(D10:D11) -> 0 | E13: =+E12-SUM(E10:E11) -> 0
C15: External | D15: Group | E15: Total | H15: Somme de 2027 | I15: Étiquettes de colonnes
B16: =+"Sales "&$C$4 -> Sales W2 | C16: {=INDIRECT(ADDRESS(10,8,,,$C$4))} -> 93.43 | D16: {=INDIRECT(ADDRESS(11,8,,,$C$4))} -> 2.39 | E16: =SUM(C16:D16) -> 95.82 | H16: Étiquettes de lignes | I16: W2 | J16: W1 | K16: Var
B17: =+"Orderbook "&$C$4 -> Orderbook W2 | C17: {=INDIRECT(ADDRESS(17,11,,,$C$4))} -> 1085.1784 | D17: {=INDIRECT(ADDRESS(18,11,,,$C$4))} -> 9.676436 | E17: =SUM(C17:D17) -> 1094.8548 | H17: 0 | I17: 0 | J17: 0 | K17: =+I17-J17 -> 0
B18: =+"Forecast "&$C$4 -> Forecast W2 | C18: =SUM(C16:C17) -> 1178.6084 | D18: =SUM(D16:D17) -> 12.066436 | E18: =SUM(E16:E17) -> 1190.6748 | H18: Total général | I18: 0 | J18: 0 | K18: =+I18-J18 -> 0
K19: =+I19-J19 -> 0
K20: =+I20-J20 -> 0
C21: External | D21: Group | E21: Total | K21: =+I21-J21 -> 0
B22: =+"Sales "&$D$4 -> Sales W1 | C22: {=INDIRECT(ADDRESS(10,8,,,$D$4))} -> 10.13426 | D22: {=INDIRECT(ADDRESS(11,8,,,$D$4))} -> 0 | E22: =SUM(C22:D22) -> 10.13426 | K22: =+I22-J22 -> 0
B23: =+"Orderbook "&$D$4 -> Orderbook W1 | C23: {=INDIRECT(ADDRESS(17,11,,,$D$4))} -> 925.49593 | D23: {=INDIRECT(ADDRESS(18,11,,,$D$4))} -> 0 | E23: =SUM(C23:D23) -> 925.49593 | K23: =+I23-J23 -> 0
B24: =+"Forecast "&$D$4 -> Forecast W1 | C24: =SUM(C22:C23) -> 935.63019 | D24: =SUM(D22:D23) -> 0 | E24: =SUM(E22:E23) -> 935.63019 | K24: =+I24-J24 -> 0
K25: =+I25-J25 -> 0
K26: =+I26-J26 -> 0
B27: Somme de 2026 | C27: Étiquettes de colonnes | K27: =+I27-J27 -> 0
B28: Étiquettes de lignes | C28: W2 | D28: W1 | E28: Var | K28: =+I28-J28 -> 0
B29: 0 | C29: 0 | D29: 0 | E29: =+C29-D29 -> 0 | K29: =+I29-J29 -> 0
B30: Total général | C30: 0 | D30: 0 | E30: =+C30-D30 -> 0 | K30: =+I30-J30 -> 0
E31: =+C31-D31 -> 0 | K31: =+I31-J31 -> 0
E32: =+C32-D32 -> 0 | K32: =+I32-J32 -> 0
E33: =+C33-D33 -> 0 | K33: =+I33-J33 -> 0
E34: =+C34-D34 -> 0 | K34: =+I34-J34 -> 0
E35: =+C35-D35 -> 0 | K35: =+I35-J35 -> 0
E36: =+C36-D36 -> 0 | K36: =+I36-J36 -> 0
E37: =+C37-D37 -> 0 | K37: =+I37-J37 -> 0
E38: =+C38-D38 -> 0 | K38: =+I38-J38 -> 0
E39: =+C39-D39 -> 0 | K39: =+I39-J39 -> 0
E40: =+C40-D40 -> 0 | K40: =+I40-J40 -> 0
E41: =+C41-D41 -> 0 | K41: =+I41-J41 -> 0
E42: =+C42-D42 -> 0 | K42: =+I42-J42 -> 0
... E93: =+C93-D93 -> 0 | K93: =+I93-J93 -> 0
E94: =+C94-D94 -> 0
E95: =+C95-D95 -> 0
E96: =+C96-D96 -> 0
...

Sheet DB analysis orders
C2: Week | D2: =+'analysis week'!C4 -> W2 | E2: =+'analysis week'!D4 -> W1
C4: 5 | D4: =+C4+1 -> 6 | E4: =+D4+1 -> 7 | F4: =+E4+1 -> 8 | G4: =+F4+1 -> 9 | H4: =+G4+1 -> 10 | I4: =+H4+1 -> 11 | J4: =+I4+1 -> 12
B5: Week | C5: Order to be delivered | D5: External or Group | E5: Customers orders | F5: Quantity | G5: DGC | H5: TOTAL ORDERBOOK | I5: 2026 | J5: 2027
A6: =+INDEX(MATCH("X", 'W1'!D:D,0),,) -> 24 | B6: =+$D$2 -> W2 | C6: {=INDIRECT(ADDRESS($A6,C$4,,,$B6))} -> BACCAROSE PERFUMES AND BEAUTY PRODUCTS PVT LTD | D6: {=INDIRECT(ADDRESS($A6,D$4,,,$B6))} -> External | E6: {=INDIRECT(ADDRESS($A6,E$4,,,$B6))} -> Laura Mercier | F6: {=INDIRECT(ADDRESS($A6,F$4,,,$B6))} -> Prestige Cosmetic | G6: {=INDIRECT(ADDRESS($A6,G$4,,,$B6))} -> CL0540 Laura Mercier | H6: {=INDIRECT(ADDRESS($A6,H$4,,,$B6))} -> 7.2617511 | I6: {=INDIRECT(ADDRESS($A6,I$4,,,$B6))} -> 7.2617511 | J6: {=INDIRECT(ADDRESS($A6,J$4,,,$B6))} -> 0
A7: =+A6+1 -> 25 | B7: =+$D$2 -> W2 | C7: {=INDIRECT(ADDRESS($A7,C$4,,,$B7))} -> BACCAROSE PERFUMES AND BEAUTY PRODUCTS PVT LTD | D7: {=INDIRECT(ADDRESS($A7,D$4,,,$B7))} -> External | E7: {=INDIRECT(ADDRESS($A7,E$4,,,$B7))} -> Shiseido | F7: {=INDIRECT(ADDRESS($A7,F$4,,,$B7))} -> Prestige Cosmetic | G7: {=INDIRECT(ADDRESS($A7,G$4,,,$B7))} -> CL0285 Shiseido | H7: {=INDIRECT(ADDRESS($A7,H$4,,,$B7))} -> 19.0875 | I7: {=INDIRECT(ADDRESS($A7,I$4,,,$B7))} -> 19.0875 | J7: {=INDIRECT(ADDRESS($A7,J$4,,,$B7))} -> 0
A8: =+A7+1 -> 26 | B8: =+$D$2 -> W2 | C8: {=INDIRECT(ADDRESS($A8,C$4,,,$B8))} -> Beauty Impex Pvt. Ltd | D8: {=INDIRECT(ADDRESS($A8,D$4,,,$B8))} -> External | E8: {=INDIRECT(ADDRESS($A8,E$4,,,$B8))} -> Guerlain | F8: {=INDIRECT(ADDRESS($A8,F$4,,,$B8))} -> Prestige Cosmetic | G8: {=INDIRECT(ADDRESS($A8,G$4,,,$B8))} -> CL0130 Guerlain | H8: {=INDIRECT(ADDRESS($A8,H$4,,,$B8))} -> 17.317858 | I8: {=INDIRECT(ADDRESS($A8,I$4,,,$B8))} -> 17.317858 | J8: {=INDIRECT(ADDRESS($A8,J$4,,,$B8))} -> 0
A9: =+A8+1 -> 27 | B9: =+$D$2 -> W2 | C9: {=INDIRECT(ADDRESS($A9,C$4,,,$B9))} -> Best In Brands | D9: {=INDIRECT(ADDRESS($A9,D$4,,,$B9))} -> External | E9: {=INDIRECT(ADDRESS($A9,E$4,,,$B9))} -> Shiseido | F9: {=INDIRECT(ADDRESS($A9,F$4,,,$B9))} -> Prestige Cosmetic | G9: {=INDIRECT(ADDRESS($A9,G$4,,,$B9))} -> CL0285 Shiseido | H9: {=INDIRECT(ADDRESS($A9,H$4,,,$B9))} -> 8.0682141 | I9: {=INDIRECT(ADDRESS($A9,I$4,,,$B9))} -> 8.0682141 | J9: {=INDIRECT(ADDRESS($A9,J$4,,,$B9))} -> 0
A10: =+A9+1 -> 28 | B10: =+$D$2 -> W2 | C10: {=INDIRECT(ADDRESS($A10,C$4,,,$B10))} -> CHANEL INDIA | D10: {=INDIRECT(ADDRESS($A10,D$4,,,$B10))} -> External | E10: {=INDIRECT(ADDRESS($A10,E$4,,,$B10))} -> Chanel | F10: {=INDIRECT(ADDRESS($A10,F$4,,,$B10))} -> Shopfitting | G10: {=INDIRECT(ADDRESS($A10,G$4,,,$B10))} -> CL0065 Chanel | H10: {=INDIRECT(ADDRESS($A10,H$4,,,$B10))} -> 5.922258 | I10: {=INDIRECT(ADDRESS($A10,I$4,,,$B10))} -> 5.922258 | J10: {=INDIRECT(ADDRESS($A10,J$4,,,$B10))} -> 0
A11: =+A10+1 -> 29 | B11: =+$D$2 -> W2 | C11: {=INDIRECT(ADDRESS($A11,C$4,,,$B11))} -> Clarins Pte Ltd | D11: {=INDIRECT(ADDRESS($A11,D$4,,,$B11))} -> External | E11: {=INDIRECT(ADDRESS($A11,E$4,,,$B11))} -> Clarins | F11: {=INDIRECT(ADDRESS($A11,F$4,,,$B11))} -> Shopfitting | G11: {=INDIRECT(ADDRESS($A11,G$4,,,$B11))} -> CL0070 Clarins | H11: {=INDIRECT(ADDRESS($A11,H$4,,,$B11))} -> 2.8162104 | I11: {=INDIRECT(ADDRESS($A11,I$4,,,$B11))} -> 2.8162104 | J11: {=INDIRECT(ADDRESS($A11,J$4,,,$B11))} -> 0
A12: =+A11+1 -> 30 | B12: =+$D$2 -> W2 | C12: {=INDIRECT(ADDRESS($A12,C$4,,,$B12))} -> Coty | D12: {=INDIRECT(ADDRESS($A12,D$4,,,$B12))} -> External | E12: {=INDIRECT(ADDRESS($A12,E$4,,,$B12))} -> Coty Rimmel | F12: {=INDIRECT(ADDRESS($A12,F$4,,,$B12))} -> Shopfitting | G12: {=INDIRECT(ADDRESS($A12,G$4,,,$B12))} -> CL0080 Coty Rimmel | H12: {=INDIRECT(ADDRESS($A12,H$4,,,$B12))} -> 2.8140266 | I12: {=INDIRECT(ADDRESS($A12,I$4,,,$B12))} -> 2.8140266 | J12: {=INDIRECT(ADDRESS($A12,J$4,,,$B12))} -> 0
A13: =+A12+1 -> 31 | B13: =+$D$2 -> W2 | C13: {=INDIRECT(ADDRESS($A13,C$4,,,$B13))} -> DIAM Display Singapore | D13: {=INDIRECT(ADDRESS($A13,D$4,,,$B13))} -> Group | E13: {=INDIRECT(ADDRESS($A13,E$4,,,$B13))} -> Coty Rimmel | F13: {=INDIRECT(ADDRESS($A13,F$4,,,$B13))} -> Shopfitting | G13: {=INDIRECT(ADDRESS($A13,G$4,,,$B13))} -> CL0080 Coty Rimmel | H13: {=INDIRECT(ADDRESS($A13,H$4,,,$B13))} -> 9.676436 | I13: {=INDIRECT(ADDRESS($A13,I$4,,,$B13))} -> 9.676436 | J13: {=INDIRECT(ADDRESS($A13,J$4,,,$B13))} -> 0
A14: =+A13+1 -> 32 | B14: =+$D$2 -> W2 | C14: {=INDIRECT(ADDRESS($A14,C$4,,,$B14))} -> Elca Cosmetics Pvt Ltd | D14: {=INDIRECT(ADDRESS($A14,D$4,,,$B14))} -> External | E14: {=INDIRECT(ADDRESS($A14,E$4,,,$B14))} -> Too Faced | F14: {=INDIRECT(ADDRESS($A14,F$4,,,$B14))} -> Prestige Cosmetic | G14: {=INDIRECT(ADDRESS($A14,G$4,,,$B14))} -> CL0575 Too Faced | H14: {=INDIRECT(ADDRESS($A14,H$4,,,$B14))} -> 39.996064 | I14: {=INDIRECT(ADDRESS($A14,I$4,,,$B14))} -> 39.996064 | J14: {=INDIRECT(ADDRESS($A14,J$4,,,$B14))} -> 0
A15: =+A14+1 -> 33 | B15: =+$D$2 -> W2 | C15: {=INDIRECT(ADDRESS($A15,C$4,,,$B15))} -> ELCA Cosmetics Pvt. Ltd. | D15: {=INDIRECT(ADDRESS($A15,D$4,,,$B15))} -> External | E15: {=INDIRECT(ADDRESS($A15,E$4,,,$B15))} -> Clinique | F15: {=INDIRECT(ADDRESS($A15,F$4,,,$B15))} -> Prestige Cosmetic | G15: {=INDIRECT(ADDRESS($A15,G$4,,,$B15))} -> CL0075 Clinique | H15: {=INDIRECT(ADDRESS($A15,H$4,,,$B15))} -> 50.077315 | I15: {=INDIRECT(ADDRESS($A15,I$4,,,$B15))} -> 50.077315 | J15: {=INDIRECT(ADDRESS($A15,J$4,,,$B15))} -> 0
A16: =+A15+1 -> 34 | B16: =+$D$2 -> W2 | C16: {=INDIRECT(ADDRESS($A16,C$4,,,$B16))} -> ELCA Cosmetics Pvt. Ltd. | D16: {=INDIRECT(ADDRESS($A16,D$4,,,$B16))} -> External | E16: {=INDIRECT(ADDRESS($A16,E$4,,,$B16))} -> Dr Jart+ | F16: {=INDIRECT(ADDRESS($A16,F$4,,,$B16))} -> Prestige Cosmetic | G16: {=INDIRECT(ADDRESS($A16,G$4,,,$B16))} -> CL0680 Estée Lauder - other brands | H16: {=INDIRECT(ADDRESS($A16,H$4,,,$B16))} -> 3.1881163 | I16: {=INDIRECT(ADDRESS($A16,I$4,,,$B16))} -> 3.1881163 | J16: {=INDIRECT(ADDRESS($A16,J$4,,,$B16))} -> 0
A17: =+A16+1 -> 35 | B17: =+$D$2 -> W2 | C17: {=INDIRECT(ADDRESS($A17,C$4,,,$B17))} -> ELCA Cosmetics Pvt. Ltd. | D17: {=INDIRECT(ADDRESS($A17,D$4,,,$B17))} -> External | E17: {=INDIRECT(ADDRESS($A17,E$4,,,$B17))} -> Estee Lauder | F17: {=INDIRECT(ADDRESS($A17,F$4,,,$B17))} -> Prestige Cosmetic | G17: {=INDIRECT(ADDRESS($A17,G$4,,,$B17))} -> CL0110 Estée Lauder | H17: {=INDIRECT(ADDRESS($A17,H$4,,,$B17))} -> 50.54466 | I17: {=INDIRECT(ADDRESS($A17,I$4,,,$B17))} -> 50.54466 | J17: {=INDIRECT(ADDRESS($A17,J$4,,,$B17))} -> 0
A18: =+A17+1 -> 36 | B18: =+$D$2 -> W2 | C18: {=INDIRECT(ADDRESS($A18,C$4,,,$B18))} -> ELCA Cosmetics Pvt. Ltd. | D18: {=INDIRECT(ADDRESS($A18,D$4,,,$B18))} -> External | E18: {=INDIRECT(ADDRESS($A18,E$4,,,$B18))} -> Mac | F18: {=INDIRECT(ADDRESS($A18,F$4,,,$B18))} -> Prestige Cosmetic | G18: {=INDIRECT(ADDRESS($A18,G$4,,,$B18))} -> CL0395 MAC | H18: {=INDIRECT(ADDRESS($A18,H$4,,,$B18))} -> 16.992312 | I18: {=INDIRECT(ADDRESS($A18,I$4,,,$B18))} -> 16.992312 | J18: {=INDIRECT(ADDRESS($A18,J$4,,,$B18))} -> 0
... A233: =+A232+1 -> 251 | B233: =+$D$2 -> W2 | C233: {=INDIRECT(ADDRESS($A233,C$4,,,$B233))} -> 0 | D233: {=INDIRECT(ADDRESS($A233,D$4,,,$B233))} -> 0 | E233: {=INDIRECT(ADDRESS($A233,E$4,,,$B233))} -> 0 | F233: {=INDIRECT(ADDRESS($A233,F$4,,,$B233))} -> 0 | G233: {=INDIRECT(ADDRESS($A233,G$4,,,$B233))} -> 0 | H233: {=INDIRECT(ADDRESS($A233,H$4,,,$B233))} -> 0 | I233: {=INDIRECT(ADDRESS($A233,I$4,,,$B233))} -> 0 | J233: {=INDIRECT(ADDRESS($A233,J$4,,,$B233))} -> 0
A234: =+A6 -> 24 | B234: =+$E$2 -> W1 | C234: {=INDIRECT(ADDRESS($A234,C$4,,,$B234))} -> BACCAROSE PERFUMES AND BEAUTY PRODUCTS PVT LTD | D234: {=INDIRECT(ADDRESS($A234,D$4,,,$B234))} -> External | E234: {=INDIRECT(ADDRESS($A234,E$4,,,$B234))} -> Laura Mercier | F234: {=INDIRECT(ADDRESS($A234,F$4,,,$B234))} -> Prestige Cosmetic | G234: {=INDIRECT(ADDRESS($A234,G$4,,,$B234))} -> 0 | H234: {=INDIRECT(ADDRESS($A234,H$4,,,$B234))} -> 7.2617511 | I234: {=INDIRECT(ADDRESS($A234,I$4,,,$B234))} -> 7.2617511 | J234: {=INDIRECT(ADDRESS($A234,J$4,,,$B234))} -> 0
A235: =+A7 -> 25 | B235: =+$E$2 -> W1 | C235: {=INDIRECT(ADDRESS($A235,C$4,,,$B235))} -> BACCAROSE PERFUMES AND BEAUTY PRODUCTS PVT LTD | D235: {=INDIRECT(ADDRESS($A235,D$4,,,$B235))} -> External | E235: {=INDIRECT(ADDRESS($A235,E$4,,,$B235))} -> Shiseido | F235: {=INDIRECT(ADDRESS($A235,F$4,,,$B235))} -> Prestige Cosmetic | G235: {=INDIRECT(ADDRESS($A235,G$4,,,$B235))} -> 0 | H235: {=INDIRECT(ADDRESS($A235,H$4,,,$B235))} -> 19.0875 | I235: {=INDIRECT(ADDRESS($A235,I$4,,,$B235))} -> 19.0875 | J235: {=INDIRECT(ADDRESS($A235,J$4,,,$B235))} -> 0
A236: =+A8 -> 26 | B236: =+$E$2 -> W1 | C236: {=INDIRECT(ADDRESS($A236,C$4,,,$B236))} -> Beauty Impex Pvt. Ltd | D236: {=INDIRECT(ADDRESS($A236,D$4,,,$B236))} -> External | E236: {=INDIRECT(ADDRESS($A236,E$4,,,$B236))} -> Guerlain | F236: {=INDIRECT(ADDRESS($A236,F$4,,,$B236))} -> Prestige Cosmetic | G236: {=INDIRECT(ADDRESS($A236,G$4,,,$B236))} -> 0 | H236: {=INDIRECT(ADDRESS($A236,H$4,,,$B236))} -> 9.0229322 | I236: {=INDIRECT(ADDRESS($A236,I$4,,,$B236))} -> 9.0229322 | J236: {=INDIRECT(ADDRESS($A236,J$4,,,$B236))} -> 0
A237: =+A9 -> 27 | B237: =+$E$2 -> W1 | C237: {=INDIRECT(ADDRESS($A237,C$4,,,$B237))} -> Best In Brands | D237: {=INDIRECT(ADDRESS($A237,D$4,,,$B237))} -> External | E237: {=INDIRECT(ADDRESS($A237,E$4,,,$B237))} -> Shiseido | F237: {=INDIRECT(ADDRESS($A237,F$4,,,$B237))} -> Prestige Cosmetic | G237: {=INDIRECT(ADDRESS($A237,G$4,,,$B237))} -> 0 | H237: {=INDIRECT(ADDRESS($A237,H$4,,,$B237))} -> 7.9641265 | I237: {=INDIRECT(ADDRESS($A237,I$4,,,$B237))} -> 7.9641265 | J237: {=INDIRECT(ADDRESS($A237,J$4,,,$B237))} -> 0
A238: =+A10 -> 28 | B238: =+$E$2 -> W1 | C238: {=INDIRECT(ADDRESS($A238,C$4,,,$B238))} -> CHANEL INDIA | D238: {=INDIRECT(ADDRESS($A238,D$4,,,$B238))} -> External | E238: {=INDIRECT(ADDRESS($A238,E$4,,,$B238))} -> Chanel | F238: {=INDIRECT(ADDRESS($A238,F$4,,,$B238))} -> Shopfitting | G238: {=INDIRECT(ADDRESS($A238,G$4,,,$B238))} -> 0 | H238: {=INDIRECT(ADDRESS($A238,H$4,,,$B238))} -> 6.2638655 | I238: {=INDIRECT(ADDRESS($A238,I$4,,,$B238))} -> 6.2638655 | J238: {=INDIRECT(ADDRESS($A238,J$4,,,$B238))} -> 0
A239: =+A11 -> 29 | B239: =+$E$2 -> W1 | C239: {=INDIRECT(ADDRESS($A239,C$4,,,$B239))} -> Elca Cosmetics Pvt Ltd | D239: {=INDIRECT(ADDRESS($A239,D$4,,,$B239))} -> External | E239: {=INDIRECT(ADDRESS($A239,E$4,,,$B239))} -> Too Faced | F239: {=INDIRECT(ADDRESS($A239,F$4,,,$B239))} -> Prestige Cosmetic | G239: {=INDIRECT(ADDRESS($A239,G$4,,,$B239))} -> 0 | H239: {=INDIRECT(ADDRESS($A239,H$4,,,$B239))} -> 39.996064 | I239: {=INDIRECT(ADDRESS($A239,I$4,,,$B239))} -> 39.996064 | J239: {=INDIRECT(ADDRESS($A239,J$4,,,$B239))} -> 0
A240: =+A12 -> 30 | B240: =+$E$2 -> W1 | C240: {=INDIRECT(ADDRESS($A240,C$4,,,$B240))} -> ELCA Cosmetics Pvt. Ltd. | D240: {=INDIRECT(ADDRESS($A240,D$4,,,$B240))} -> External | E240: {=INDIRECT(ADDRESS($A240,E$4,,,$B240))} -> Clinique | F240: {=INDIRECT(ADDRESS($A240,F$4,,,$B240))} -> Prestige Cosmetic | G240: {=INDIRECT(ADDRESS($A240,G$4,,,$B240))} -> 0 | H240: {=INDIRECT(ADDRESS($A240,H$4,,,$B240))} -> 40.110492 | I240: {=INDIRECT(ADDRESS($A240,I$4,,,$B240))} -> 40.110492 | J240: {=INDIRECT(ADDRESS($A240,J$4,,,$B240))} -> 0
A241: =+A13 -> 31 | B241: =+$E$2 -> W1 | C241: {=INDIRECT(ADDRESS($A241,C$4,,,$B241))} -> ELCA Cosmetics Pvt. Ltd. | D241: {=INDIRECT(ADDRESS($A241,D$4,,,$B241))} -> External | E241: {=INDIRECT(ADDRESS($A241,E$4,,,$B241))} -> Dr Jart+ | F241: {=INDIRECT(ADDRESS($A241,F$4,,,$B241))} -> Prestige Cosmetic | G241: {=INDIRECT(ADDRESS($A241,G$4,,,$B241))} -> 0 | H241: {=INDIRECT(ADDRESS($A241,H$4,,,$B241))} -> 3.1881163 | I241: {=INDIRECT(ADDRESS($A241,I$4,,,$B241))} -> 3.1881163 | J241: {=INDIRECT(ADDRESS($A241,J$4,,,$B241))} -> 0
A242: =+A14 -> 32 | B242: =+$E$2 -> W1 | C242: {=INDIRECT(ADDRESS($A242,C$4,,,$B242))} -> ELCA Cosmetics Pvt. Ltd. | D242: {=INDIRECT(ADDRESS($A242,D$4,,,$B242))} -> External | E242: {=INDIRECT(ADDRESS($A242,E$4,,,$B242))} -> Estee Lauder | F242: {=INDIRECT(ADDRESS($A242,F$4,,,$B242))} -> Prestige Cosmetic | G242: {=INDIRECT(ADDRESS($A242,G$4,,,$B242))} -> 0 | H242: {=INDIRECT(ADDRESS($A242,H$4,,,$B242))} -> 41.310783 | I242: {=INDIRECT(ADDRESS($A242,I$4,,,$B242))} -> 41.310783 | J242: {=INDIRECT(ADDRESS($A242,J$4,,,$B242))} -> 0
A243: =+A15 -> 33 | B243: =+$E$2 -> W1 | C243: {=INDIRECT(ADDRESS($A243,C$4,,,$B243))} -> ELCA Cosmetics Pvt. Ltd. | D243: {=INDIRECT(ADDRESS($A243,D$4,,,$B243))} -> External | E243: {=INDIRECT(ADDRESS($A243,E$4,,,$B243))} -> Mac | F243: {=INDIRECT(ADDRESS($A243,F$4,,,$B243))} -> Prestige Cosmetic | G243: {=INDIRECT(ADDRESS($A243,G$4,,,$B243))} -> 0 | H243: {=INDIRECT(ADDRESS($A243,H$4,,,$B243))} -> 16.992312 | I243: {=INDIRECT(ADDRESS($A243,I$4,,,$B243))} -> 16.992312 | J243: {=INDIRECT(ADDRESS($A243,J$4,,,$B243))} -> 0
A244: =+A16 -> 34 | B244: =+$E$2 -> W1 | C244: {=INDIRECT(ADDRESS($A244,C$4,,,$B244))} -> ELCA Cosmetics Pvt. Ltd. | D244: {=INDIRECT(ADDRESS($A244,D$4,,,$B244))} -> External | E244: {=INDIRECT(ADDRESS($A244,E$4,,,$B244))} -> The Ordinary | F244: {=INDIRECT(ADDRESS($A244,F$4,,,$B244))} -> Prestige Cosmetic | G244: {=INDIRECT(ADDRESS($A244,G$4,,,$B244))} -> 0 | H244: {=INDIRECT(ADDRESS($A244,H$4,,,$B244))} -> 30.265831 | I244: {=INDIRECT(ADDRESS($A244,I$4,,,$B244))} -> 30.265831 | J244: {=INDIRECT(ADDRESS($A244,J$4,,,$B244))} -> 0
A245: =+A17 -> 35 | B245: =+$E$2 -> W1 | C245: {=INDIRECT(ADDRESS($A245,C$4,,,$B245))} -> ELCA Cosmetics Pvt. Ltd. | D245: {=INDIRECT(ADDRESS($A245,D$4,,,$B245))} -> External | E245: {=INDIRECT(ADDRESS($A245,E$4,,,$B245))} -> Tom Ford | F245: {=INDIRECT(ADDRESS($A245,F$4,,,$B245))} -> Prestige Cosmetic | G245: {=INDIRECT(ADDRESS($A245,G$4,,,$B245))} -> 0 | H245: {=INDIRECT(ADDRESS($A245,H$4,,,$B245))} -> 24.496051 | I245: {=INDIRECT(ADDRESS($A245,I$4,,,$B245))} -> 24.496051 | J245: {=INDIRECT(ADDRESS($A245,J$4,,,$B245))} -> 0
... A461: =+A233 -> 251 | B461: =+$E$2 -> W1 | C461: {=INDIRECT(ADDRESS($A461,C$4,,,$B461))} -> 0 | D461: {=INDIRECT(ADDRESS($A461,D$4,,,$B461))} -> 0 | E461: {=INDIRECT(ADDRESS($A461,E$4,,,$B461))} -> 0 | F461: {=INDIRECT(ADDRESS($A461,F$4,,,$B461))} -> 0 | G461: {=INDIRECT(ADDRESS($A461,G$4,,,$B461))} -> 0 | H461: {=INDIRECT(ADDRESS($A461,H$4,,,$B461))} -> 0 | I461: {=INDIRECT(ADDRESS($A461,I$4,,,$B461))} -> 0 | J461: {=INDIRECT(ADDRESS($A461,J$4,,,$B461))} -> 0

Sheet Synth
A1: SYNTHESIS
A3: To be filled in (TURNOVER = BO)
A5: YTD : Year to date turnover. This means the cumulated turnover since the begining of the year.
A6: This turnover should the same as the turnover fill in Business Object (BO). See with your local accountant to know this turnover.
A8: TURNOVER | D8: ORDERBOOK 2026 | F8: FORECAST 2026 | H8: NEW ORDERS 2026 | J8: ORDERBOOK 2027
A10: W52 2025
A12: W1 | B12: =+'W1'!$J$12 -> 10.13426 | D12: =+'W1'!$K$19 -> 925.49593 | F12: =+B12+D12 -> 935.63019 | H12: =D12+B12-D10 -> 935.63019 | J12: =+'W1'!$L$19 -> 0
A13: W2 | B13: =+'W2'!$J$12 -> 95.82 | D13: =+'W2'!$K$19 -> 1094.8548 | F13: =+B13+D13 -> 1190.6748 | H13: =F13-F12 -> 255.04462 | J13: =+'W2'!$L$19 -> 0
A14: W3 | B14: =+'W3'!$J$12 -> 230.38956 | D14: =+'W3'!$K$19 -> 1262.1782 | F14: =+B14+D14 -> 1492.5677 | H14: =F14-F13 -> 301.89292 | J14: =+'W3'!$L$19 -> 0
A15: W4 | B15: =+'W4'!$J$12 -> 352.24882 | D15: =+'W4'!$K$19 -> 1263.81 | F15: =+B15+D15 -> 1616.0588 | H15: =F15-F14 -> 123.49109 | J15: =+'W4'!$L$19 -> 0
A16: W5 | B16: =+'W5'!$J$12 -> 542.53 | D16: =+'W5'!$K$19 -> 1055.63 | F16: =+B16+D16 -> 1598.16 | H16: =F16-F15 -> -17.89882 | J16: =+'W5'!$L$19 -> 0
A17: January YTD
A18: W6 | B18: =+'W6'!$J$12 -> 69.68 | D18: =+'W6'!$K$19 -> 869.1505 | F18: =+B17+B18+D18 -> 938.8305 | H18: =F18-F16 -> -659.3295 | J18: =+'W6'!$L$19 -> 0
A19: W7 | B19: =+'W7'!$J$12 -> 83 | D19: =+'W7'!$K$19 -> 1009.6434 | F19: =+B17+B19+D19 -> 1092.6434 | H19: =F19-F18 -> 153.81289 | J19: =+'W7'!$L$19 -> 0
A20: W8 | B20: =+'W8'!$J$12 -> 156.24735 | D20: =+'W8'!$K$19 -> 1266.28 | F20: =+B17+B20+D20 -> 1422.5273 | H20: =F20-F19 -> 329.88395 | J20: =+'W8'!$L$19 -> 0
A21: W9 | B21: =+'W9'!$J$12 -> 573 | D21: =+'W9'!$K$19 -> 2302.9324 | F21: =+B22+B21+D21 -> 2875.9324 | H21: =F21-F20 -> 1453.4051 | J21: =+'W9'!$L$19 -> 0
A22: February YTD
A23: W10 | B23: =+'W10'!$J$12 -> 31 | D23: =+'W10'!$K$19 -> 2342.7469 | F23: =+B22+B23+D23 -> 2373.7469 | H23: =F23-F21 -> -502.18548 | J23: =+'W10'!$L$19 -> 0
A24: W11 | B24: =+'W11'!$J$12 -> 78 | D24: =+'W11'!$K$19 -> 2998.0455 | F24: =+B22+B24+D24 -> 3076.0455 | H24: =F24-F23 -> 702.29861 | J24: =+'W11'!$L$19 -> 0
A25: W12 | B25: =+'W12'!$J$12 -> 197.22 | D25: =+'W12'!$K$19 -> 2975.9453 | F25: =+B22+B25+D25 -> 3173.1653 | H25: =F25-F24 -> 97.11976 | J25: =+'W12'!$L$19 -> 0
A26: W13 | B26: =+'W13'!$J$12 -> 441.52 | D26: =+'W13'!$K$19 -> 3365.0094 | F26: =+B22+B26+D26 -> 3806.5294 | H26: =F26-F25 -> 633.36414 | J26: =+'W13'!$L$19 -> 0
A27: March YTD
A28: W14 | B28: =+'W14'!$J$12 -> 6.5 | D28: =+'W14'!$K$19 -> 3097.8574 | F28: =+B27+B28+D28 -> 3104.3574 | H28: =F28-F26 -> -702.17198 | J28: =+'W14'!$L$19 -> 0
A29: W15 | B29: =+'W15'!$J$12 -> 59.37 | D29: =+'W15'!$K$19 -> 3181.8574 | F29: =+B27+B29+D29 -> 3241.2274 | H29: =F29-F28 -> 136.87 | J29: =+'W15'!$L$19 -> 0
A30: W16 | B30: =+'W16'!$J$12 -> 177 | D30: =+'W16'!$K$19 -> 3286.2972 | F30: =+B27+B30+D30 -> 3463.2972 | H30: =F30-F29 -> 222.06979 | J30: =+'W16'!$L$19 -> 0
A31: W17 | B31: =+'W17'!$J$12 -> 278.27815 | D31: =+'W17'!$K$19 -> 3398.1054 | F31: =+B27+B31+D31 -> 3676.3836 | H31: =F31-F30 -> 213.08637 | J31: =+'W17'!$L$19 -> 0
A32: W18 | B32: =+'W18'!$J$12 -> 472 | D32: =+'W18'!$K$19 -> 3501.5122 | F32: =+B33+B32+D32 -> 3973.5122 | H32: =F32-F31 -> 297.12863 | J32: =+'W18'!$L$19 -> 0
A33: April YTD
A34: W19 | B34: =+'W19'!$J$12 -> 117 | D34: =+'W19'!$K$19 -> 3494.8518 | F34: =+B33+B34+D34 -> 3611.8518 | H34: =F34-F32 -> -361.66047 | J34: =+'W19'!$L$19 -> 0
A35: W20 | B35: =+'W20'!$J$12 -> 152 | D35: =+'W20'!$K$19 -> 3709.0806 | F35: =+B33+B35+D35 -> 3861.0806 | H35: =F35-F34 -> 249.2288 | J35: =+'W20'!$L$19 -> 0
A36: W21 | B36: =+'W21'!$J$12 -> 272 | D36: =+'W21'!$K$19 -> 3657.2127 | F36: =+B33+B36+D36 -> 3929.2127 | H36: =F36-F35 -> 68.132142 | J36: =+'W21'!$L$19 -> 0
A37: W22 | B37: =+'W22'!$J$12 -> 466 | D37: =+'W22'!$K$19 -> 3649.4797 | F37: =+B38+B37+D37 -> 4115.4797 | H37: =F37-F36 -> 186.26703 | J37: =+'W22'!$L$19 -> 0
A38: May YTD
A39: W23 | B39: =+'W23'!$J$12 -> 158 | D39: =+'W23'!$K$19 -> 3464.4907 | F39: =+B38+B39+D39 -> 3622.4907 | H39: =F39-F37 -> -492.98899 | J39: =+'W23'!$L$19 -> 0
A40: W24 | B40: =+'W24'!$J$12 -> 311 | D40: =+'W24'!$K$19 -> 3343.2065 | F40: =+B38+B40+D40 -> 3654.2065 | H40: =F40-F39 -> 31.715812 | J40: =+'W24'!$L$19 -> 0
A41: W25 | B41: =+'W25'!$J$12 -> 488 | D41: =+'W25'!$K$19 -> 3338.7145 | F41: =+B38+B41+D41 -> 3826.7145 | H41: =F41-F40 -> 172.50798 | J41: =+'W25'!$L$19 -> 0
A42: W26 | B42: =+'W26'!$J$12 -> 656 | D42: =+'W26'!$K$19 -> 3502.0385 | F42: =+B38+B42+D42 -> 4158.0385 | H42: =F42-F41 -> 331.32396 | J42: =+'W26'!$L$19 -> 0
A43: June YTD
A44: W27 | B44: =+'W27'!$J$12 -> 215 | D44: =+'W27'!$K$19 -> 3246.6092 | F44: =+B43+B44+D44 -> 3461.6092 | H44: =F44-F42 -> -696.42933 | J44: =+'W27'!$L$19 -> 0
A45: W28 | B45: =+'W28'!$J$12 -> 407 | D45: =+'W28'!$K$19 -> 3233.1982 | F45: =+B43+B45+D45 -> 3640.1982 | H45: =F45-F44 -> 178.58909 | J45: =+'W28'!$L$19 -> 0
...

Sheet W1
E2: ENTITY NAME : | G2: =+parameters!D2 -> Diam India | I2: ORDER BOOK SYNTHESIS in K€
E4: WEEK : | G4: W1 | I4: Cells to be filled in
E6: MONTH : | G6: =+VLOOKUP(G4, parameters!G:H, 2, 0) -> January
E8: TURNOVER | F8: =parameters!D4 -> k€ | H8: YTD Turnover | J8: =+G6&" Turnover" -> January Turnover | L8: Last estim. for the month: | O8: Forecast 2026
H9: =+"from January 1 until end of "&G4 -> from January 1 until end of W1 | J9: =+"from "&G6&" 1 until end of "&G4 -> from January 1 until end of W1 | L9: =+G6 -> January | O9: =+G4 -> W1
E10: EXTERNAL SALES INVOICED (=outside group) | H10: =J10 -> 10.13426 | J10: =1013426/100000 -> 10.13426 | L10: =J10+N19 -> 507.82698 | O10: =+H10+K17 -> 935.63019
E11: GROUP SALES INVOICED | H11: =J11 -> 0 | J11: 0 | L11: 0 | O11: =+H11+K18 -> 0 | S11: Definition orders : you consider the orders which are sure even if the order customers paper order is not yet received
E12: TOTAL | H12: =SUM(H10:H11) -> 10.13426 | J12: =SUM(J10:J11) -> 10.13426 | L12: =SUM(L10:L11) -> 507.82698 | O12: =SUM(O10:O11) -> 935.63019 | S12: The quantity, value, and delivery date can be changed before final delivery
E16: ORDERBOOK | F16: =+F8 -> k€ | J16: TOTAL ORDERBOOK | K16: Total amount 2026 | L16: Total amount 2027 | N16: 46023 | O16: 46054 | P16: 46082 | Q16: 46113 | R16: 46143 | S16: 46174 | T16: 46204 | U16: 46235 | V16: 46266 | W16: 46296 | X16: 46327 | Y16: 46357 | AA16: 46388 | AB16: 46419 | AC16: 46447 | AD16: 46478 | AE16: 46508 | AF16: 46539 | AG16: 46569 | AH16: 46600 | AI16: 46631 | AJ16: 46661 | AK16: 46692 | AL16: 46722
E17: External | J17: =+SUMIF($F$24:$F$252,"External",$J$24:$J$252) -> 925.49593 | K17: =+SUMIF($F$24:$F$252,"External",$K$24:$K$252) -> 925.49593 | L17: =+SUMIF($F$24:$F$252,"External",$L$24:$L$252) -> 0 | N17: =+SUMIF($F$24:$F$252,"External",N$24:N$252) -> 497.69272 | O17: =+SUMIF($F$24:$F$252,"External",O$24:O$252) -> 279.30503 | P17: =+SUMIF($F$24:$F$252,"External",P$24:P$252) -> 27.305477 | Q17: =+SUMIF($F$24:$F$252,"External",Q$24:Q$252) -> 39.714621 | R17: =+SUMIF($F$24:$F$252,"External",R$24:R$252) -> 81.478071 | S17: =+SUMIF($F$24:$F$252,"External",S$24:S$252) -> 0 | T17: =+SUMIF($F$24:$F$252,"External",T$24:T$252) -> 0 | U17: =+SUMIF($F$24:$F$252,"External",U$24:U$252) -> 0 | ... Y17: =+SUMIF($F$24:$F$252,"External",Y$24:Y$252) -> 0 | AA17: =+SUMIF($F$24:$F$252,"External",AA$24:AA$252) -> 0 | AB17: =+SUMIF($F$24:$F$252,"External",AB$24:AB$252) -> 0 | AC17: =+SUMIF($F$24:$F$252,"External",AC$24:AC$252) -> 0 | AD17: =+SUMIF($F$24:$F$252,"External",AD$24:AD$252) -> 0 | AE17: =+SUMIF($F$24:$F$252,"External",AE$24:AE$252) -> 0 | AF17: =+SUMIF($F$24:$F$252,"External",AF$24:AF$252) -> 0 | AG17: =+SUMIF($F$24:$F$252,"External",AG$24:AG$252) -> 0 | AH17: =+SUMIF($F$24:$F$252,"External",AH$24:AH$252) -> 0 | ... AL17: =+SUMIF($F$24:$F$252,"External",AL$24:AL$252) -> 0
E18: Group | J18: =+SUMIF($F$24:$F$252,"Group",$J$24:$J$252) -> 0 | K18: =+SUMIF($F$24:$F$252,"Group",$K$24:$K$252) -> 0 | L18: =SUMIF($F$24:$F$252,"Group",$L$24:$L$252) -> 0 | N18: =+SUMIF($F$24:$F$252,"Group",N$24:N$252) -> 0 | O18: =+SUMIF($F$24:$F$252,"Group",O$24:O$252) -> 0 | P18: =+SUMIF($F$24:$F$252,"Group",P$24:P$252) -> 0 | Q18: =+SUMIF($F$24:$F$252,"Group",Q$24:Q$252) -> 0 | R18: =+SUMIF($F$24:$F$252,"Group",R$24:R$252) -> 0 | S18: =+SUMIF($F$24:$F$252,"Group",S$24:S$252) -> 0 | T18: =+SUMIF($F$24:$F$252,"Group",T$24:T$252) -> 0 | U18: =+SUMIF($F$24:$F$252,"Group",U$24:U$252) -> 0 | ... Y18: =+SUMIF($F$24:$F$252,"Group",Y$24:Y$252) -> 0 | AA18: =+SUMIF($F$24:$F$252,"Group",AA$24:AA$252) -> 0 | AB18: =+SUMIF($F$24:$F$252,"Group",AB$24:AB$252) -> 0 | AC18: =+SUMIF($F$24:$F$252,"Group",AC$24:AC$252) -> 0 | AD18: =+SUMIF($F$24:$F$252,"Group",AD$24:AD$252) -> 0 | AE18: =+SUMIF($F$24:$F$252,"Group",AE$24:AE$252) -> 0 | AF18: =+SUMIF($F$24:$F$252,"Group",AF$24:AF$252) -> 0 | AG18: =+SUMIF($F$24:$F$252,"Group",AG$24:AG$252) -> 0 | AH18: =+SUMIF($F$24:$F$252,"Group",AH$24:AH$252) -> 0 | ... AL18: =+SUMIF($F$24:$F$252,"Group",AL$24:AL$252) -> 0
E19: TOTAL | J19: =SUM(J17:J18) -> 925.49593 | K19: =SUM(K17:K18) -> 925.49593 | L19: =SUM(L17:L18) -> 0 | N19: =SUM(N17:N18) -> 497.69272 | O19: =SUM(O17:O18) -> 279.30503 | P19: =SUM(P17:P18) -> 27.305477 | Q19: =SUM(Q17:Q18) -> 39.714621 | R19: =SUM(R17:R18) -> 81.478071 | S19: =SUM(S17:S18) -> 0 | T19: =SUM(T17:T18) -> 0 | U19: =SUM(U17:U18) -> 0 | ... Y19: =SUM(Y17:Y18) -> 0 | AA19: =SUM(AA17:AA18) -> 0 | AB19: =SUM(AB17:AB18) -> 0 | AC19: =SUM(AC17:AC18) -> 0 | AD19: =SUM(AD17:AD18) -> 0 | AE19: =SUM(AE17:AE18) -> 0 | AF19: =SUM(AF17:AF18) -> 0 | AG19: =SUM(AG17:AG18) -> 0 | AH19: =SUM(AH17:AH18) -> 0 | ... AL19: =SUM(AL17:AL18) -> 0
I21: check | J21: =IF(SUM(J24:J252)=J19, "OK", "Please correct: the sum of orders below is not equal to the total calculated above. Make sure to pick External or Group for each order and don't change the formulas in columns K and L") -> OK | N21: 2026 | AA21: 2027
E23: Order (Tooling including) to be delivered | F23: External or Group | G23: Customers orders | H23: Quantity | I23: DGC | J23: TOTAL ORDERBOOK | K23: Total amount 2026 | L23: Total amount 2026 | N23: 46023 | O23: 46054 | P23: 46082 | Q23: 46113 | R23: 46143 | S23: 46174 | T23: 46204 | U23: 46235 | V23: 46266 | W23: 46296 | X23: 46327 | Y23: 46357 | AA23: 46388 | AB23: 46419 | AC23: 46447 | AD23: 46478 | AE23: 46508 | AF23: 46539 | AG23: 46569 | AH23: 46600 | AI23: 46631 | AJ23: 46661 | AK23: 46692 | AL23: 46722
D24: X | E24: BACCAROSE PERFUMES AND BEAUTY PRODUCTS PVT LTD | F24: External | G24: Laura Mercier | H24: Prestige Cosmetic | J24: =+K24+L24 -> 7.2617511 | K24: =SUM(N24:Y24) -> 7.2617511 | L24: =SUM(AA24:AL24) -> 0 | Q24: 7.2617511
E25: BACCAROSE PERFUMES AND BEAUTY PRODUCTS PVT LTD | F25: External | G25: Shiseido | H25: Prestige Cosmetic | J25: =+K25+L25 -> 19.0875 | K25: =SUM(N25:Y25) -> 19.0875 | L25: =SUM(AA25:AL25) -> 0 | P25: 19.0875
E26: Beauty Impex Pvt. Ltd | F26: External | G26: Guerlain | H26: Prestige Cosmetic | J26: =+K26+L26 -> 9.0229322 | K26: =SUM(N26:Y26) -> 9.0229322 | L26: =SUM(AA26:AL26) -> 0 | N26: 9.0229322
E27: Best In Brands | F27: External | G27: Shiseido | H27: Prestige Cosmetic | J27: =+K27+L27 -> 7.9641265 | K27: =SUM(N27:Y27) -> 7.9641265 | L27: =SUM(AA27:AL27) -> 0 | P27: 7.9641265
E28: CHANEL INDIA | F28: External | G28: Chanel | H28: Shopfitting | J28: =+K28+L28 -> 6.2638655 | K28: =SUM(N28:Y28) -> 6.2638655 | L28: =SUM(AA28:AL28) -> 0 | N28: 6.2638655
E29: Elca Cosmetics Pvt Ltd | F29: External | G29: Too Faced | H29: Prestige Cosmetic | J29: =+K29+L29 -> 39.996064 | K29: =SUM(N29:Y29) -> 39.996064 | L29: =SUM(AA29:AL29) -> 0 | R29: 39.996064
E30: ELCA Cosmetics Pvt. Ltd. | F30: External | G30: Clinique | H30: Prestige Cosmetic | J30: =+K30+L30 -> 40.110492 | K30: =SUM(N30:Y30) -> 40.110492 | L30: =SUM(AA30:AL30) -> 0 | N30: 40.110492
E31: ELCA Cosmetics Pvt. Ltd. | F31: External | G31: Dr Jart+ | H31: Prestige Cosmetic | J31: =+K31+L31 -> 3.1881163 | K31: =SUM(N31:Y31) -> 3.1881163 | L31: =SUM(AA31:AL31) -> 0 | N31: 3.1881163
E32: ELCA Cosmetics Pvt. Ltd. | F32: External | G32: Estee Lauder | H32: Prestige Cosmetic | J32: =+K32+L32 -> 41.310783 | K32: =SUM(N32:Y32) -> 41.310783 | L32: =SUM(AA32:AL32) -> 0 | N32: 41.310783
E33: ELCA Cosmetics Pvt. Ltd. | F33: External | G33: Mac | H33: Prestige Cosmetic | J33: =+K33+L33 -> 16.992312 | K33: =SUM(N33:Y33) -> 16.992312 | L33: =SUM(AA33:AL33) -> 0 | N33: 7.9570146 | R33: 9.035297
E34: ELCA Cosmetics Pvt. Ltd. | F34: External | G34: The Ordinary | H34: Prestige Cosmetic | J34: =+K34+L34 -> 30.265831 | K34: =SUM(N34:Y34) -> 30.265831 | L34: =SUM(AA34:AL34) -> 0 | N34: 30.265831
E35: ELCA Cosmetics Pvt. Ltd. | F35: External | G35: Tom Ford | H35: Prestige Cosmetic | J35: =+K35+L35 -> 24.496051 | K35: =SUM(N35:Y35) -> 24.496051 | L35: =SUM(AA35:AL35) -> 0 | N35: 24.496051
E36: ELCA Cosmetics Pvt. Ltd. | F36: External | G36: Too Faced | H36: Prestige Cosmetic | J36: =+K36+L36 -> 146.6935 | K36: =SUM(N36:Y36) -> 146.6935 | L36: =SUM(AA36:AL36) -> 0 | O36: 146.6935
E37: Estee Lauder AG Lachen | F37: External | G37: Jo Malone | H37: Prestige Cosmetic | J37: =+K37+L37 -> 1.8251618 | K37: =SUM(N37:Y37) -> 1.8251618 | L37: =SUM(AA37:AL37) -> 0 | N37: 1.8251618
E38: Global Shoppers Stop Beauty Brands Ltd | F38: External | G38: Nars | H38: Prestige Cosmetic | J38: =+K38+L38 -> 112.31055 | K38: =SUM(N38:Y38) -> 112.31055 | L38: =SUM(AA38:AL38) -> 0 | N38: 0.84615 | O38: 46.31097 | P38: 0.25385 | Q38: 32.45287 | R38: 32.44671
E39: Indosing Distribution | F39: External | G39: Benefit | H39: Prestige Cosmetic | J39: =+K39+L39 -> 2.12327 | K39: =SUM(N39:Y39) -> 2.12327 | L39: =SUM(AA39:AL39) -> 0 | N39: 2.12327
E40: L Beauty Pte | F40: External | G40: Benefit | H40: Prestige Cosmetic | J40: =+K40+L40 -> 17.255213 | K40: =SUM(N40:Y40) -> 17.255213 | L40: =SUM(AA40:AL40) -> 0 | N40: 5.963903 | O40: 11.29131
E41: L'Oreal India | F41: External | G41: Lancome | H41: Prestige Cosmetic | J41: =+K41+L41 -> 23.444373 | K41: =SUM(N41:Y41) -> 23.444373 | L41: =SUM(AA41:AL41) -> 0 | N41: 23.444373
E42: L'Oreal India | F42: External | G42: Lancome | H42: Shopfitting | J42: =+K42+L42 -> 11.615179 | K42: =SUM(N42:Y42) -> 11.615179 | L42: =SUM(AA42:AL42) -> 0 | N42: 11.615179
E43: L'Oreal India | F43: External | G43: YSL | H43: Shopfitting | J43: =+K43+L43 -> 83.958234 | K43: =SUM(N43:Y43) -> 83.958234 | L43: =SUM(AA43:AL43) -> 0 | N43: 83.958234
E44: L'Oreal Travel Retail | F44: External | G44: Armani | H44: Shopfitting | J44: =+K44+L44 -> 25.675854 | K44: =SUM(N44:Y44) -> 25.675854 | L44: =SUM(AA44:AL44) -> 0 | N44: 25.675854
E45: L'Oreal Travel Retail | F45: External | G45: Lancome | H45: Shopfitting | J45: =+K45+L45 -> 13.609436 | K45: =SUM(N45:Y45) -> 13.609436 | L45: =SUM(AA45:AL45) -> 0 | N45: 13.609436
E46: L'Oreal Travel Retail | F46: External | G46: Loreal Paris | H46: Shopfitting | J46: =+K46+L46 -> 7.748713 | K46: =SUM(N46:Y46) -> 7.748713 | L46: =SUM(AA46:AL46) -> 0 | N46: 7.748713
E47: L'Oreal Travel Retail | F47: External | G47: Multi | H47: Shopfitting | J47: =+K47+L47 -> 49.267677 | K47: =SUM(N47:Y47) -> 49.267677 | L47: =SUM(AA47:AL47) -> 0 | N47: 49.267677
E48: L'Oreal Travel Retail | F48: External | G48: OAP | H48: Shopfitting | J48: =+K48+L48 -> 7.50618 | K48: =SUM(N48:Y48) -> 7.50618 | L48: =SUM(AA48:AL48) -> 0 | N48: 7.50618
E49: Rare Beauty LLC | F49: External | G49: Rare Beauty | H49: Prestige Cosmetic | J49: =+K49+L49 -> 101.96075 | K49: =SUM(N49:Y49) -> 101.96075 | L49: =SUM(AA49:AL49) -> 0 | N49: 48.488266 | O49: 53.47248
...

Sheet W2
E2: ENTITY NAME : | G2: =+parameters!D2 -> Diam India | I2: ORDER BOOK SYNTHESIS in K€
E4: WEEK : | G4: W2 | I4: Cells to be filled in
E6: MONTH : | G6: =+VLOOKUP(G4, parameters!G:H, 2, 0) -> January
E8: TURNOVER | F8: =parameters!D4 -> k€ | H8: YTD Turnover | J8: =+G6&" Turnover" -> January Turnover | L8: Last estim. for the month: | O8: Forecast 2026
H9: =+"from January 1 until end of "&G4 -> from January 1 until end of W2 | J9: =+"from "&G6&" 1 until end of "&G4 -> from January 1 until end of W2 | L9: =+G6 -> January | O9: =+G4 -> W2 | P9: =+VLOOKUP(G4, parameters!$G$9:$I$61,3,0) -> W1 | Q9: Var
E10: EXTERNAL SALES INVOICED (=outside group) | H10: =J10 -> 93.43 | J10: 93.43 | L10: =J10+N17 -> 541.53462 | O10: =+H10+K17 -> 1178.6084 | P10: {=INDIRECT(ADDRESS(10,15,,,VLOOKUP($G$4,parameters!$G:$I,3,0)))} -> 935.63019 | Q10: =O10-P10 -> 242.97818
E11: GROUP SALES INVOICED | H11: =J11 -> 2.39 | J11: 2.39 | L11: =J11+N18 -> 5.2762906 | O11: =+H11+K18 -> 12.066436 | P11: {=INDIRECT(ADDRESS(11,15,,,VLOOKUP($G$4,parameters!$G:$I,3,0)))} -> 0 | Q11: =O11-P11 -> 12.066436 | S11: Definition orders : you consider the orders which are sure even if the order customers paper order is not yet received
E12: TOTAL | H12: =SUM(H10:H11) -> 95.82 | J12: =SUM(J10:J11) -> 95.82 | L12: =SUM(L10:L11) -> 546.81091 | O12: =SUM(O10:O11) -> 1190.6748 | P12: =SUM(P10:P11) -> 935.63019 | Q12: =O12-P12 -> 255.04462 | S12: The quantity, value, and delivery date can be changed before final delivery
E16: ORDERBOOK | F16: =+F8 -> k€ | J16: TOTAL ORDERBOOK | K16: Total amount 2026 | L16: Total amount 2027 | N16: 46023 | O16: 46054 | P16: 46082 | Q16: 46113 | R16: 46143 | S16: 46174 | T16: 46204 | U16: 46235 | V16: 46266 | W16: 46296 | X16: 46327 | Y16: 46357 | AA16: 46388 | AB16: 46419 | AC16: 46447 | AD16: 46478 | AE16: 46508 | AF16: 46539 | AG16: 46569 | AH16: 46600 | AI16: 46631 | AJ16: 46661 | AK16: 46692 | AL16: 46722
E17: External | J17: =+SUMIF($F$24:$F$251,"External",$J$24:$J$251) -> 1085.1784 | K17: =+SUMIF($F$24:$F$251,"External",$K$24:$K$251) -> 1085.1784 | L17: =+SUMIF($F$24:$F$251,"External",$L$24:$L$251) -> 0 | N17: =+SUMIF($F$24:$F$251,"External",N$24:N$251) -> 448.10462 | O17: =+SUMIF($F$24:$F$251,"External",O$24:O$251) -> 388.30574 | P17: =+SUMIF($F$24:$F$251,"External",P$24:P$251) -> 39.398119 | Q17: =+SUMIF($F$24:$F$251,"External",Q$24:Q$251) -> 155.89933 | R17: =+SUMIF($F$24:$F$251,"External",R$24:R$251) -> 41.482007 | S17: =+SUMIF($F$24:$F$251,"External",S$24:S$251) -> 11.988554 | T17: =+SUMIF($F$24:$F$251,"External",T$24:T$251) -> 0 | U17: =+SUMIF($F$24:$F$251,"External",U$24:U$251) -> 0 | ... Y17: =+SUMIF($F$24:$F$251,"External",Y$24:Y$251) -> 0 | AA17: =+SUMIF($F$24:$F$251,"External",AA$24:AA$251) -> 0 | AB17: =+SUMIF($F$24:$F$251,"External",AB$24:AB$251) -> 0 | AC17: =+SUMIF($F$24:$F$251,"External",AC$24:AC$251) -> 0 | AD17: =+SUMIF($F$24:$F$251,"External",AD$24:AD$251) -> 0 | AE17: =+SUMIF($F$24:$F$251,"External",AE$24:AE$251) -> 0 | AF17: =+SUMIF($F$24:$F$251,"External",AF$24:AF$251) -> 0 | AG17: =+SUMIF($F$24:$F$251,"External",AG$24:AG$251) -> 0 | AH17: =+SUMIF($F$24:$F$251,"External",AH$24:AH$251) -> 0 | ... AL17: =+SUMIF($F$24:$F$251,"External",AL$24:AL$251) -> 0
E18: Group | J18: =+SUMIF($F$24:$F$251,"Group",$J$24:$J$251) -> 9.676436 | K18: =+SUMIF($F$24:$F$251,"Group",$K$24:$K$251) -> 9.676436 | L18: =SUMIF($F$24:$F$251,"Group",$L$24:$L$251) -> 0 | N18: =+SUMIF($F$24:$F$251,"Group",N$24:N$251) -> 2.8862906 | O18: =+SUMIF($F$24:$F$251,"Group",O$24:O$251) -> 0 | P18: =+SUMIF($F$24:$F$251,"Group",P$24:P$251) -> 6.7901454 | Q18: =+SUMIF($F$24:$F$251,"Group",Q$24:Q$251) -> 0 | R18: =+SUMIF($F$24:$F$251,"Group",R$24:R$251) -> 0 | S18: =+SUMIF($F$24:$F$251,"Group",S$24:S$251) -> 0 | T18: =+SUMIF($F$24:$F$251,"Group",T$24:T$251) -> 0 | U18: =+SUMIF($F$24:$F$251,"Group",U$24:U$251) -> 0 | ... Y18: =+SUMIF($F$24:$F$251,"Group",Y$24:Y$251) -> 0 | AA18: =+SUMIF($F$24:$F$251,"Group",AA$24:AA$251) -> 0 | AB18: =+SUMIF($F$24:$F$251,"Group",AB$24:AB$251) -> 0 | AC18: =+SUMIF($F$24:$F$251,"Group",AC$24:AC$251) -> 0 | AD18: =+SUMIF($F$24:$F$251,"Group",AD$24:AD$251) -> 0 | AE18: =+SUMIF($F$24:$F$251,"Group",AE$24:AE$251) -> 0 | AF18: =+SUMIF($F$24:$F$251,"Group",AF$24:AF$251) -> 0 | AG18: =+SUMIF($F$24:$F$251,"Group",AG$24:AG$251) -> 0 | AH18: =+SUMIF($F$24:$F$251,"Group",AH$24:AH$251) -> 0 | ... AL18: =+SUMIF($F$24:$F$251,"Group",AL$24:AL$251) -> 0
E19: TOTAL | J19: =SUM(J17:J18) -> 1094.8548 | K19: =SUM(K17:K18) -> 1094.8548 | L19: =SUM(L17:L18) -> 0 | N19: =SUM(N17:N18) -> 450.99091 | O19: =SUM(O17:O18) -> 388.30574 | P19: =SUM(P17:P18) -> 46.188264 | Q19: =SUM(Q17:Q18) -> 155.89933 | R19: =SUM(R17:R18) -> 41.482007 | S19: =SUM(S17:S18) -> 11.988554 | T19: =SUM(T17:T18) -> 0 | U19: =SUM(U17:U18) -> 0 | ... Y19: =SUM(Y17:Y18) -> 0 | AA19: =SUM(AA17:AA18) -> 0 | AB19: =SUM(AB17:AB18) -> 0 | AC19: =SUM(AC17:AC18) -> 0 | AD19: =SUM(AD17:AD18) -> 0 | AE19: =SUM(AE17:AE18) -> 0 | AF19: =SUM(AF17:AF18) -> 0 | AG19: =SUM(AG17:AG18) -> 0 | AH19: =SUM(AH17:AH18) -> 0 | ... AL19: =SUM(AL17:AL18) -> 0
I21: check | J21: =IF(SUM(J24:J251)=J19, "OK", "Please correct: the sum of orders below is not equal to the total calculated above. Make sure to pick External or Group for each order and don't change the formulas in columns K and L") -> OK | N21: 2026 | AA21: 2027
E23: Order (Tooling including) to be delivered | F23: External or Group | G23: Brand Name | H23: Segment | I23: Outgroup | J23: TOTAL ORDERBOOK | K23: Total amount 2026 | L23: Total amount 2026 | N23: 46023 | O23: 46054 | P23: 46082 | Q23: 46113 | R23: 46143 | S23: 46174 | T23: 46204 | U23: 46235 | V23: 46266 | W23: 46296 | X23: 46327 | Y23: 46357 | AA23: 46388 | AB23: 46419 | AC23: 46447 | AD23: 46478 | AE23: 46508 | AF23: 46539 | AG23: 46569 | AH23: 46600 | AI23: 46631 | AJ23: 46661 | AK23: 46692 | AL23: 46722
D24: X | E24: BACCAROSE PERFUMES AND BEAUTY PRODUCTS PVT LTD | F24: External | G24: Laura Mercier | H24: Prestige Cosmetic | I24: CL0540 Laura Mercier | J24: =+K24+L24 -> 7.2617511 | K24: =SUM(N24:Y24) -> 7.2617511 | L24: =SUM(AA24:AL24) -> 0 | Q24: 7.2617511
E25: BACCAROSE PERFUMES AND BEAUTY PRODUCTS PVT LTD | F25: External | G25: Shiseido | H25: Prestige Cosmetic | I25: CL0285 Shiseido | J25: =+K25+L25 -> 19.0875 | K25: =SUM(N25:Y25) -> 19.0875 | L25: =SUM(AA25:AL25) -> 0 | P25: 19.0875
E26: Beauty Impex Pvt. Ltd | F26: External | G26: Guerlain | H26: Prestige Cosmetic | I26: CL0130 Guerlain | J26: =+K26+L26 -> 17.317858 | K26: =SUM(N26:Y26) -> 17.317858 | L26: =SUM(AA26:AL26) -> 0 | N26: 5.9515956 | O26: 11.366263
E27: Best In Brands | F27: External | G27: Shiseido | H27: Prestige Cosmetic | I27: CL0285 Shiseido | J27: =+K27+L27 -> 8.0682141 | K27: =SUM(N27:Y27) -> 8.0682141 | L27: =SUM(AA27:AL27) -> 0 | P27: 8.0682141
E28: CHANEL INDIA | F28: External | G28: Chanel | H28: Shopfitting | I28: CL0065 Chanel | J28: =+K28+L28 -> 5.922258 | K28: =SUM(N28:Y28) -> 5.922258 | L28: =SUM(AA28:AL28) -> 0 | N28: 5.922258
E29: Clarins Pte Ltd | F29: External | G29: Clarins | H29: Shopfitting | I29: CL0070 Clarins | J29: =+K29+L29 -> 2.8162104 | K29: =SUM(N29:Y29) -> 2.8162104 | L29: =SUM(AA29:AL29) -> 0 | N29: 2.8162104
E30: Coty | F30: External | G30: Coty Rimmel | H30: Shopfitting | I30: CL0080 Coty Rimmel | J30: =+K30+L30 -> 2.8140266 | K30: =SUM(N30:Y30) -> 2.8140266 | L30: =SUM(AA30:AL30) -> 0 | N30: 2.8140266
E31: DIAM Display Singapore | F31: Group | G31: Coty Rimmel | H31: Shopfitting | I31: CL0080 Coty Rimmel | J31: =+K31+L31 -> 9.676436 | K31: =SUM(N31:Y31) -> 9.676436 | L31: =SUM(AA31:AL31) -> 0 | N31: 2.8862906 | P31: 6.7901454
E32: Elca Cosmetics Pvt Ltd | F32: External | G32: Too Faced | H32: Prestige Cosmetic | I32: CL0575 Too Faced | J32: =+K32+L32 -> 39.996064 | K32: =SUM(N32:Y32) -> 39.996064 | L32: =SUM(AA32:AL32) -> 0 | N32: 39.996064
E33: ELCA Cosmetics Pvt. Ltd. | F33: External | G33: Clinique | H33: Prestige Cosmetic | I33: CL0075 Clinique | J33: =+K33+L33 -> 50.077315 | K33: =SUM(N33:Y33) -> 50.077315 | L33: =SUM(AA33:AL33) -> 0 | N33: 40.735585 | P33: 4.6708654 | S33: 4.6708654
E34: ELCA Cosmetics Pvt. Ltd. | F34: External | G34: Dr Jart+ | H34: Prestige Cosmetic | I34: CL0680 Estée Lauder - other brands | J34: =+K34+L34 -> 3.1881163 | K34: =SUM(N34:Y34) -> 3.1881163 | L34: =SUM(AA34:AL34) -> 0 | N34: 3.1881163
E35: ELCA Cosmetics Pvt. Ltd. | F35: External | G35: Estee Lauder | H35: Prestige Cosmetic | I35: CL0110 Estée Lauder | J35: =+K35+L35 -> 50.54466 | K35: =SUM(N35:Y35) -> 50.54466 | L35: =SUM(AA35:AL35) -> 0 | N35: 43.172395 | O35: 2.7014 | P35: 2.3354327 | S35: 2.3354327
E36: ELCA Cosmetics Pvt. Ltd. | F36: External | G36: Mac | H36: Prestige Cosmetic | I36: CL0395 MAC | J36: =+K36+L36 -> 16.992312 | K36: =SUM(N36:Y36) -> 16.992312 | L36: =SUM(AA36:AL36) -> 0 | N36: 7.9570146 | R36: 9.035297
E37: ELCA Cosmetics Pvt. Ltd. | F37: External | G37: Smashbox | H37: Prestige Cosmetic | I37: CL0525 Smashbox | J37: =+K37+L37 -> 3.2735576 | K37: =SUM(N37:Y37) -> 3.2735576 | L37: =SUM(AA37:AL37) -> 0 | P37: 1.6367788 | S37: 1.6367788
E38: ELCA Cosmetics Pvt. Ltd. | F38: External | G38: The Ordinary | H38: Prestige Cosmetic | I38: CL0680 Estée Lauder - other brands | J38: =+K38+L38 -> 18.166287 | K38: =SUM(N38:Y38) -> 18.166287 | L38: =SUM(AA38:AL38) -> 0 | N38: 15.152247 | P38: 1.50702 | S38: 1.50702
E39: ELCA Cosmetics Pvt. Ltd. | F39: External | G39: Tom Ford | H39: Prestige Cosmetic | I39: CL0570 Tom Ford | J39: =+K39+L39 -> 26.053007 | K39: =SUM(N39:Y39) -> 26.053007 | L39: =SUM(AA39:AL39) -> 0 | N39: 24.496051 | P39: 0.7784776 | S39: 0.7784776
E40: ELCA Cosmetics Pvt. Ltd. | F40: External | G40: Too Faced | H40: Prestige Cosmetic | I40: CL0575 Too Faced | J40: =+K40+L40 -> 157.2171 | K40: =SUM(N40:Y40) -> 157.2171 | L40: =SUM(AA40:AL40) -> 0 | O40: 155.09714 | P40: 1.05998 | S40: 1.05998
E41: Estee Lauder AG Lachen | F41: External | G41: Jo Malone | H41: Prestige Cosmetic | I41: CL0535 Joe Malone | J41: =+K41+L41 -> 0.2784152 | K41: =SUM(N41:Y41) -> 0.2784152 | L41: =SUM(AA41:AL41) -> 0 | N41: 0.2784152
E42: Fenty Beauty LLC | F42: External | G42: Fenty | H42: Prestige Cosmetic | I42: CL0550 Kendo - Fenty | J42: =+K42+L42 -> 9.0120765 | K42: =SUM(N42:Y42) -> 9.0120765 | L42: =SUM(AA42:AL42) -> 0 | N42: 9.0120765
E43: Forma Brands, LLC f/k/a FB Acquisition LLC | F43: External | G43: Forma | H43: Prestige Cosmetic | I43: CL0735 Morphe | J43: =+K43+L43 -> 53.752461 | K43: =SUM(N43:Y43) -> 53.752461 | L43: =SUM(AA43:AL43) -> 0 | O43: 53.752461
E44: Global Shoppers Stop Beauty Brands Ltd | F44: External | G44: Clarins | H44: Shopfitting | I44: CL0070 Clarins | J44: =+K44+L44 -> 3.0947403 | K44: =SUM(N44:Y44) -> 3.0947403 | L44: =SUM(AA44:AL44) -> 0 | N44: 3.0947403
E45: Global Shoppers Stop Beauty Brands Ltd | F45: External | G45: Nars | H45: Prestige Cosmetic | I45: CL0226 Nars | J45: =+K45+L45 -> 112.31055 | K45: =SUM(N45:Y45) -> 112.31055 | L45: =SUM(AA45:AL45) -> 0 | N45: 0.84615 | O45: 46.31097 | P45: 0.25385 | Q45: 32.45287 | R45: 32.44671
E46: Global Shoppers Stop Beauty Brands Ltd | F46: External | G46: Prada | H46: Shopfitting | I46: CL0180 L'Oréal Divers | J46: =+K46+L46 -> 23.23065 | K46: =SUM(N46:Y46) -> 23.23065 | L46: =SUM(AA46:AL46) -> 0 | N46: 23.23065
E47: Indosing Distribution | F47: External | G47: Benefit | H47: Prestige Cosmetic | I47: CL0315 Benefit | J47: =+K47+L47 -> 10.12327 | K47: =SUM(N47:Y47) -> 10.12327 | L47: =SUM(AA47:AL47) -> 0 | N47: 10.12327
E48: L Beauty Pte | F48: External | G48: Benefit | H48: Prestige Cosmetic | I48: CL0315 Benefit | J48: =+K48+L48 -> 17.257267 | K48: =SUM(N48:Y48) -> 17.257267 | L48: =SUM(AA48:AL48) -> 0 | N48: 5.9646117 | O48: 11.292655
E49: L'Oreal India | F49: External | G49: Lancome | H49: Prestige Cosmetic | I49: CL0155 Lancôme | J49: =+K49+L49 -> 32.380149 | K49: =SUM(N49:Y49) -> 32.380149 | L49: =SUM(AA49:AL49) -> 0 | N49: 26.343352 | O49: 6.0367966
...

Sheet W3
E2: ENTITY NAME : | G2: =+parameters!D2 -> Diam India | I2: ORDER BOOK SYNTHESIS in K€
E4: WEEK : | G4: W3 | I4: Cells to be filled in
E6: MONTH : | G6: =+VLOOKUP(G4, parameters!G:H, 2, 0) -> January
E8: TURNOVER | F8: =parameters!D4 -> k€ | H8: YTD Turnover | J8: =+G6&" Turnover" -> January Turnover | L8: Last estim. for the month: | O8: Forecast 2026
H9: =+"from January 1 until end of "&G4 -> from January 1 until end of W3 | J9: =+"from "&G6&" 1 until end of "&G4 -> from January 1 until end of W3 | L9: =+G6 -> January | O9: =+G4 -> W3 | P9: =+VLOOKUP(G4, parameters!$G$9:$I$61,3,0) -> W2 | Q9: Var
E10: EXTERNAL SALES INVOICED (=outside group) | H10: 228 | J10: 228 | L10: =J10+N17 -> 659.92081 | O10: =+H10+K17 -> 1474.7035 | P10: {=INDIRECT(ADDRESS(10,15,,,VLOOKUP($G$4,parameters!$G:$I,3,0)))} -> 1178.6084 | Q10: =O10-P10 -> 296.0951
E11: GROUP SALES INVOICED | H11: 2.38956 | J11: 2.38956 | L11: =J11+N18 -> 11.074109 | O11: =+H11+K18 -> 17.864254 | P11: {=INDIRECT(ADDRESS(11,15,,,VLOOKUP($G$4,parameters!$G:$I,3,0)))} -> 12.066436 | Q11: =O11-P11 -> 5.7978183 | S11: Definition orders : you consider the orders which are sure even if the order customers paper order is not yet received
E12: TOTAL | H12: =SUM(H10:H11) -> 230.38956 | J12: =SUM(J10:J11) -> 230.38956 | L12: =SUM(L10:L11) -> 670.99492 | O12: =SUM(O10:O11) -> 1492.5677 | P12: =SUM(P10:P11) -> 1190.6748 | Q12: =O12-P12 -> 301.89292 | S12: The quantity, value, and delivery date can be changed before final delivery
E16: ORDERBOOK | F16: =+F8 -> k€ | J16: TOTAL ORDERBOOK | K16: Total amount 2026 | L16: Total amount 2027 | N16: 46023 | O16: 46054 | P16: 46082 | Q16: 46113 | R16: 46143 | S16: 46174 | T16: 46204 | U16: 46235 | V16: 46266 | W16: 46296 | X16: 46327 | Y16: 46357 | AA16: 46388 | AB16: 46419 | AC16: 46447 | AD16: 46478 | AE16: 46508 | AF16: 46539 | AG16: 46569 | AH16: 46600 | AI16: 46631 | AJ16: 46661 | AK16: 46692 | AL16: 46722
E17: External | J17: =+SUMIF($F$24:$F$251,"External",$J$24:$J$251) -> 1246.7035 | K17: =+SUMIF($F$24:$F$251,"External",$K$24:$K$251) -> 1246.7035 | L17: =+SUMIF($F$24:$F$251,"External",$L$24:$L$251) -> 0 | N17: =+SUMIF($F$24:$F$251,"External",N$24:N$251) -> 431.92081 | O17: =+SUMIF($F$24:$F$251,"External",O$24:O$251) -> 467.13681 | P17: =+SUMIF($F$24:$F$251,"External",P$24:P$251) -> 164.10562 | Q17: =+SUMIF($F$24:$F$251,"External",Q$24:Q$251) -> 123.44646 | R17: =+SUMIF($F$24:$F$251,"External",R$24:R$251) -> 9.035297 | S17: =+SUMIF($F$24:$F$251,"External",S$24:S$251) -> 39.069912 | T17: =+SUMIF($F$24:$F$251,"External",T$24:T$251) -> 11.988554 | U17: =+SUMIF($F$24:$F$251,"External",U$24:U$251) -> 0 | ... Y17: =+SUMIF($F$24:$F$251,"External",Y$24:Y$251) -> 0 | AA17: =+SUMIF($F$24:$F$251,"External",AA$24:AA$251) -> 0 | AB17: =+SUMIF($F$24:$F$251,"External",AB$24:AB$251) -> 0 | AC17: =+SUMIF($F$24:$F$251,"External",AC$24:AC$251) -> 0 | AD17: =+SUMIF($F$24:$F$251,"External",AD$24:AD$251) -> 0 | AE17: =+SUMIF($F$24:$F$251,"External",AE$24:AE$251) -> 0 | AF17: =+SUMIF($F$24:$F$251,"External",AF$24:AF$251) -> 0 | AG17: =+SUMIF($F$24:$F$251,"External",AG$24:AG$251) -> 0 | AH17: =+SUMIF($F$24:$F$251,"External",AH$24:AH$251) -> 0 | ... AL17: =+SUMIF($F$24:$F$251,"External",AL$24:AL$251) -> 0
E18: Group | J18: =+SUMIF($F$24:$F$251,"Group",$J$24:$J$251) -> 15.474694 | K18: =+SUMIF($F$24:$F$251,"Group",$K$24:$K$251) -> 15.474694 | L18: =SUMIF($F$24:$F$251,"Group",$L$24:$L$251) -> 0 | N18: =+SUMIF($F$24:$F$251,"Group",N$24:N$251) -> 8.6845489 | O18: =+SUMIF($F$24:$F$251,"Group",O$24:O$251) -> 0 | P18: =+SUMIF($F$24:$F$251,"Group",P$24:P$251) -> 6.7901454 | Q18: =+SUMIF($F$24:$F$251,"Group",Q$24:Q$251) -> 0 | R18: =+SUMIF($F$24:$F$251,"Group",R$24:R$251) -> 0 | S18: =+SUMIF($F$24:$F$251,"Group",S$24:S$251) -> 0 | T18: =+SUMIF($F$24:$F$251,"Group",T$24:T$251) -> 0 | U18: =+SUMIF($F$24:$F$251,"Group",U$24:U$251) -> 0 | ... Y18: =+SUMIF($F$24:$F$251,"Group",Y$24:Y$251) -> 0 | AA18: =+SUMIF($F$24:$F$251,"Group",AA$24:AA$251) -> 0 | AB18: =+SUMIF($F$24:$F$251,"Group",AB$24:AB$251) -> 0 | AC18: =+SUMIF($F$24:$F$251,"Group",AC$24:AC$251) -> 0 | AD18: =+SUMIF($F$24:$F$251,"Group",AD$24:AD$251) -> 0 | AE18: =+SUMIF($F$24:$F$251,"Group",AE$24:AE$251) -> 0 | AF18: =+SUMIF($F$24:$F$251,"Group",AF$24:AF$251) -> 0 | AG18: =+SUMIF($F$24:$F$251,"Group",AG$24:AG$251) -> 0 | AH18: =+SUMIF($F$24:$F$251,"Group",AH$24:AH$251) -> 0 | ... AL18: =+SUMIF($F$24:$F$251,"Group",AL$24:AL$251) -> 0
E19: TOTAL | J19: =SUM(J17:J18) -> 1262.1782 | K19: =SUM(K17:K18) -> 1262.1782 | L19: =SUM(L17:L18) -> 0 | N19: =SUM(N17:N18) -> 440.60536 | O19: =SUM(O17:O18) -> 467.13681 | P19: =SUM(P17:P18) -> 170.89577 | Q19: =SUM(Q17:Q18) -> 123.44646 | R19: =SUM(R17:R18) -> 9.035297 | S19: =SUM(S17:S18) -> 39.069912 | T19: =SUM(T17:T18) -> 11.988554 | U19: =SUM(U17:U18) -> 0 | ... Y19: =SUM(Y17:Y18) -> 0 | AA19: =SUM(AA17:AA18) -> 0 | AB19: =SUM(AB17:AB18) -> 0 | AC19: =SUM(AC17:AC18) -> 0 | AD19: =SUM(AD17:AD18) -> 0 | AE19: =SUM(AE17:AE18) -> 0 | AF19: =SUM(AF17:AF18) -> 0 | AG19: =SUM(AG17:AG18) -> 0 | AH19: =SUM(AH17:AH18) -> 0 | ... AL19: =SUM(AL17:AL18) -> 0
I21: check | J21: =IF(SUM(J24:J251)=J19, "OK", "Please correct: the sum of orders below is not equal to the total calculated above. Make sure to pick External or Group for each order and don't change the formulas in columns K and L") -> OK | N21: 2026 | AA21: 2027
E23: Order (Tooling including) to be delivered | F23: External or Group | G23: Customers orders | H23: Segment | I23: Outgroup | J23: TOTAL ORDERBOOK | K23: Total amount 2026 | L23: Total amount 2026 | N23: 46023 | O23: 46054 | P23: 46082 | Q23: 46113 | R23: 46143 | S23: 46174 | T23: 46204 | U23: 46235 | V23: 46266 | W23: 46296 | X23: 46327 | Y23: 46357 | AA23: 46388 | AB23: 46419 | AC23: 46447 | AD23: 46478 | AE23: 46508 | AF23: 46539 | AG23: 46569 | AH23: 46600 | AI23: 46631 | AJ23: 46661 | AK23: 46692 | AL23: 46722
D24: X | E24: Gucci | F24: External | G24: BACCAROSE PERFUMES AND BEAUTY PRODUCTS PVT LTD | H24: Shopfitting | I24: CL0920 Coty - other brands | J24: =+K24+L24 -> 1.52838 | K24: =SUM(N24:Y24) -> 1.52838 | L24: =SUM(AA24:AL24) -> 0 | N24: 1.52838
E25: Laura Mercier | F25: External | G25: BACCAROSE PERFUMES AND BEAUTY PRODUCTS PVT LTD | H25: Prestige Cosmetic | I25: CL0540 Laura Mercier | J25: =+K25+L25 -> 7.2617511 | K25: =SUM(N25:Y25) -> 7.2617511 | L25: =SUM(AA25:AL25) -> 0 | Q25: 7.2617511
E26: Shiseido | F26: External | G26: BACCAROSE PERFUMES AND BEAUTY PRODUCTS PVT LTD | H26: Prestige Cosmetic | I26: CL0285 Shiseido | J26: =+K26+L26 -> 19.0875 | K26: =SUM(N26:Y26) -> 19.0875 | L26: =SUM(AA26:AL26) -> 0 | P26: 19.0875
E27: Guerlain | F27: External | G27: Beauty Impex Pvt. Ltd | H27: Prestige Cosmetic | I27: CL0130 Guerlain | J27: =+K27+L27 -> 29.542426 | K27: =SUM(N27:Y27) -> 29.542426 | L27: =SUM(AA27:AL27) -> 0 | N27: 18.176164 | O27: 11.366263
E28: Shiseido | F28: External | G28: Best In Brands | H28: Prestige Cosmetic | I28: CL0285 Shiseido | J28: =+K28+L28 -> 8.0682141 | K28: =SUM(N28:Y28) -> 8.0682141 | L28: =SUM(AA28:AL28) -> 0 | P28: 8.0682141
E29: Chanel | F29: External | G29: CHANEL INDIA | H29: Shopfitting | I29: CL0065 Chanel | J29: =+K29+L29 -> 5.922258 | K29: =SUM(N29:Y29) -> 5.922258 | L29: =SUM(AA29:AL29) -> 0 | N29: 5.922258
E30: Clarins | F30: External | G30: Clarins Pte Ltd | H30: Shopfitting | I30: CL0070 Clarins | J30: =+K30+L30 -> 2.8162104 | K30: =SUM(N30:Y30) -> 2.8162104 | L30: =SUM(AA30:AL30) -> 0 | N30: 2.8162104
E31: L'Oreal TR | F31: External | G31: Connectiv FZCO | H31: Shopfitting | I31: CL0170 L'Oréal Paris (L'OAP) | J31: =+K31+L31 -> 0.8584046 | K31: =SUM(N31:Y31) -> 0.8584046 | L31: =SUM(AA31:AL31) -> 0 | P31: 0.8584046
E32: Coty | F32: External | G32: Coty | H32: Shopfitting | I32: CL0920 Coty - other brands | J32: =+K32+L32 -> 2.7684359 | K32: =SUM(N32:Y32) -> 2.7684359 | L32: =SUM(AA32:AL32) -> 0 | N32: 2.7684359
E33: Coty | F33: Group | G33: DIAM Display Singapore | H33: Shopfitting | I33: CL0920 Coty - other brands | J33: =+K33+L33 -> 8.3150404 | K33: =SUM(N33:Y33) -> 8.3150404 | L33: =SUM(AA33:AL33) -> 0 | N33: 1.524895 | P33: 6.7901454
E34: Fenty Beauty | F34: Group | G34: DIAM Turkey | H34: Prestige Cosmetic | I34: CL0550 Kendo - Fenty | J34: =+K34+L34 -> 7.1596539 | K34: =SUM(N34:Y34) -> 7.1596539 | L34: =SUM(AA34:AL34) -> 0 | N34: 7.1596539
E35: Too Faced | F35: External | G35: Elca Cosmetics Pvt Ltd | H35: Prestige Cosmetic | I35: CL0575 Too Faced | J35: =+K35+L35 -> 39.069912 | K35: =SUM(N35:Y35) -> 39.069912 | L35: =SUM(AA35:AL35) -> 0 | S35: 39.069912
E36: Clinique | F36: External | G36: ELCA Cosmetics Pvt. Ltd. | H36: Prestige Cosmetic | I36: CL0075 Clinique | J36: =+K36+L36 -> 59.043613 | K36: =SUM(N36:Y36) -> 59.043613 | L36: =SUM(AA36:AL36) -> 0 | N36: 54.372748 | P36: 2.3354327 | T36: 2.3354327
E37: Dr Jart+ | F37: External | G37: ELCA Cosmetics Pvt. Ltd. | H37: Prestige Cosmetic | I37: CL0680 Estée Lauder - other brands | J37: =+K37+L37 -> 3.1881163 | K37: =SUM(N37:Y37) -> 3.1881163 | L37: =SUM(AA37:AL37) -> 0 | P37: 3.1881163
E38: Estee Lauder | F38: External | G38: ELCA Cosmetics Pvt. Ltd. | H38: Prestige Cosmetic | I38: CL0110 Estée Lauder | J38: =+K38+L38 -> 170.93034 | K38: =SUM(N38:Y38) -> 170.93034 | L38: =SUM(AA38:AL38) -> 0 | N38: 77.954743 | O38: 88.304735 | P38: 2.3354327 | T38: 2.3354327
E39: Mac | F39: External | G39: ELCA Cosmetics Pvt. Ltd. | H39: Prestige Cosmetic | I39: CL0395 MAC | J39: =+K39+L39 -> 13.706164 | K39: =SUM(N39:Y39) -> 13.706164 | L39: =SUM(AA39:AL39) -> 0 | N39: 2e-06 | P39: 2.3354327 | R39: 9.035297 | T39: 2.3354327
E40: Smashbox | F40: External | G40: ELCA Cosmetics Pvt. Ltd. | H40: Prestige Cosmetic | I40: CL0525 Smashbox | J40: =+K40+L40 -> 3.2735576 | K40: =SUM(N40:Y40) -> 3.2735576 | L40: =SUM(AA40:AL40) -> 0 | P40: 1.6367788 | T40: 1.6367788
E41: The Ordinary | F41: External | G41: ELCA Cosmetics Pvt. Ltd. | H41: Prestige Cosmetic | I41: CL0680 Estée Lauder - other brands | J41: =+K41+L41 -> 14.566856 | K41: =SUM(N41:Y41) -> 14.566856 | L41: =SUM(AA41:AL41) -> 0 | N41: 0.0386618 | P41: 13.021174 | T41: 1.50702
E42: Tom Ford | F42: External | G42: ELCA Cosmetics Pvt. Ltd. | H42: Prestige Cosmetic | I42: CL0570 Tom Ford | J42: =+K42+L42 -> 26.053007 | K42: =SUM(N42:Y42) -> 26.053007 | L42: =SUM(AA42:AL42) -> 0 | P42: 25.274529 | T42: 0.7784776
