Workbook
Name Liste: parameters!$A$2:$A$3
Name liste1: #REF!
Name liste2: #REF!
Name SOCIETE: parameters!$A$8:$A$55

Sheet read me
B1: INSTRUCTIONS FOR USE
B3: The aim of this document is to follow the orderbook per week.
B5: This document has to be sent each Friday afternoon to : | H5: dashboard@diaminter.com
B11: How to fill in the document :
C13: 1 | D13: Select the worksheet for the appropriate week
C15: 2 | D15: Fill in your company name in the cell G2
C17: 3 | D17: The current month corresponding to the week is automatically mentionned: please make sure to report data for this month (and not previous or next one when the week runs over two different months)
C19: 4 | D19: Column E : Fill in product name
C21: 5 | D21: Column F : Fill in customers statut (external or internal customers)
C23: 6 | D23: Column G : fill in the customers name
C25: 7 | D25: Please never correct the worksheet of a past week
C27: 8 | D27: You can update the pivot tables on the worksheet [analysis week] to see the detailed variations by customers in the orderbook from previous week to ongoing week
C29: 9 | D29: This is a synthesis of the orders taken and the sales invoiced during the year. Please update the YTD figures at the end of each months (yellow cells) to show the
B33: IMPORTANT : At the end of the month, orders not yet delivered, have to be automatically transferred to the next month.
D34: Once the orders have been invoiced (and so the amount is indicated as turnover), the orders should disappear of the table.

Sheet parameters
D1: Entity to select
A2: Group | D2: Diam CHINA
A3: External
D4: =VLOOKUP(D2,$A$8:$C$52,3,FALSE) -> k€
A8: TO SELECT | B8: Automatic data
A9: Diam France | B9: DFR | C9: k€ | G9: W1 | H9: January | J9: January | K9: 46023
A10: Diam Lurcy | B10: DLU | C10: k€ | G10: W2 | H10: January | I10: W1 | J10: February | K10: 46054
A11: Diam Yzeure | B11: DYZ | C11: k€ | G11: W3 | H11: January | I11: W2 | J11: March | K11: 46082
A12: Diam Tunisie | B12: DTN | C12: k€ | G12: W4 | H12: January | I12: W3 | J12: April | K12: 46113
A13: Diam Tunisie Prestige | B13: DTP | C13: k€ | G13: W5 | H13: January | I13: W4 | J13: May | K13: 46143
A14: Diam Turkey | B14: DTK | C14: k€ | G14: W6 | H14: February | I14: W5 | J14: June | K14: 46174
A15: Diam Italy | B15: DIT | C15: k€ | G15: W7 | H15: February | I15: W6 | J15: July | K15: 46204
A16: Diam Prestige Europe | B16: PEM | C16: k€ | G16: W8 | H16: February | I16: W7 | J16: August | K16: 46235
A17: Diam UK | B17: DUK | C17: k£ | G17: W9 | H17: February | I17: W8 | J17: September | K17: 46266
A18: Fieldflex UK | B18: FFUK | C18: k£ | G18: W10 | H18: March | I18: W9 | J18: October | K18: 46296
A19: Diam Germany | B19: DEU | C19: k€ | G19: W11 | H19: March | I19: W10 | J19: November | K19: 46327
A20: Diam Poland | B20: DPO | C20: k€ | G20: W12 | H20: March | I20: W11 | J20: December | K20: 46357
A21: Diam Premium North America | B21: DPN | C21: k$ | G21: W13 | H21: March | I21: W12
A22: D 3 LLC | B22: D3 | C22: k$ | G22: W14 | H22: April | I22: W13
A23: CONEX US | B23: CNX | C23: k$ | G23: W15 | H23: April | I23: W14
A24: CONEX EU | B24: CNE | C24: k€ | G24: W16 | H24: April | I24: W15
A25: CONEX APAC | B25: CNA | C25: k$ | G25: W17 | H25: April | I25: W16
A26: PRUGENT US | B26: PUS | C26: k$ | G26: W18 | H26: April | I26: W17
A27: Fieldflex US | B27: FFUS | C27: k$ | G27: W19 | H27: May | I27: W18
A28: Back to Diam | B28: B2D | C28: k$ | G28: W20 | H28: May | I28: W19
A29: Diam Mexico | B29: DMX | C29: k$ | G29: W21 | H29: May | I29: W20
A30: Diam Brazil | B30: DBR | C30: k€ | G30: W22 | H30: May | I30: W21
A31: Diam CHINA | B31: DDC | C31: k€ | G31: W23 | H31: June | I31: W22
A32: DE HONG KONG | B32: DEHK | C32: k€ | G32: W24 | H32: June | I32: W23
... A52: RETAIL 3D | B52: R3D | C52: k€ | G52: W44 | H52: October | I52: W43
G53: W45 | H53: November | I53: W44
G54: W46 | H54: November | I54: W45
G55: W47 | H55: November | I55: W46
G56: W48 | H56: November | I56: W47
G57: W49 | H57: December | I57: W48
G58: W50 | H58: December | I58: W49
G59: W51 | H59: December | I59: W50
G60: W52 | H60: December | I60: W51
G61: W53 | H61: December | I61: W52

Sheet analysis week
B2: Entity | C2: =+'W1'!G2 -> Diam CHINA | D2: =VLOOKUP(C2, parameters!A:B, 2,0) -> DDC
B4: Week | C4: W2 | D4: =VLOOKUP(C4, parameters!G:I,3,0) -> W1
B7: Var 2026 | H7: Var 2027
C9: External | D9: Group | E9: Total | I9: External | J9: Group | K9: Total
B10: ="Var in sales 2025 - "&D4&" to "&C4 -> Var in sales 2025 - W1 to W2 | C10: =+C16-C22 -> 0 | D10: =+D16-D22 -> 93.912 | E10: =+E16-E22 -> 93.912 | H10: =+"Orderbook "&$C$4 -> Orderbook W2 | I10: {=INDIRECT(ADDRESS(17,12,,,$C$4))} -> 0 | J10: {=INDIRECT(ADDRESS(18,12,,,$C$4))} -> 0 | K10: =SUM(I10:J10) -> 0
B11: ="Var in orderbook 2025 - "&D4&" to "&C4 -> Var in orderbook 2025 - W1 to W2 | C11: =+C17-C23 -> 369.921 | D11: =+D17-D23 -> 185 | E11: =+E17-E23 -> 554.921 | H11: =+"Orderbook "&$D$4 -> Orderbook W1 | I11: {=INDIRECT(ADDRESS(17,12,,,$D$4))} -> 0 | J11: {=INDIRECT(ADDRESS(18,12,,,$D$4))} -> 0 | K11: =SUM(I11:J11) -> 0
B12: ="Var in forecast 2025 - "&D4&" to "&C4 -> Var in forecast 2025 - W1 to W2 | C12: =+C18-C24 -> 369.921 | D12: =+D18-D24 -> 278.912 | E12: =+E18-E24 -> 648.833 | H12: ="Var in orderbook - "&D4&" to "&C4 -> Var in orderbook - W1 to W2 | I12: =+I10-I11 -> 0 | J12: =+J10-J11 -> 0 | K12: =+K10-K11 -> 0
C13: =+C12-SUM(C10:C11) -> 0 | D13: =+D12-SUM(D10:D11) -> 0 | E13: =+E12-SUM(E10:E11) -> 0
C15: External | D15: Group | E15: Total | H15: Somme de 2027 | I15: Étiquettes de colonnes
B16: =+"Sales "&$C$4 -> Sales W2 | C16: {=INDIRECT(ADDRESS(10,8,,,$C$4))} -> 0 | D16: {=INDIRECT(ADDRESS(11,8,,,$C$4))} -> 93.912 | E16: =SUM(C16:D16) -> 93.912 | H16: Étiquettes de lignes | I16: W2 | J16: W1 | K16: Var
B17: =+"Orderbook "&$C$4 -> Orderbook W2 | C17: {=INDIRECT(ADDRESS(17,11,,,$C$4))} -> 1560.5729 | D17: {=INDIRECT(ADDRESS(18,11,,,$C$4))} -> 8638.8 | E17: =SUM(C17:D17) -> 10199.373 | H17: 0 | I17: 0 | J17: 0 | K17: =+I17-J17 -> 0
B18: =+"Forecast "&$C$4 -> Forecast W2 | C18: =SUM(C16:C17) -> 1560.5729 | D18: =SUM(D16:D17) -> 8732.712 | E18: =SUM(E16:E17) -> 10293.285 | H18: Total général | I18: 0 | J18: 0 | K18: =+I18-J18 -> 0
K19: =+I19-J19 -> 0
K20: =+I20-J20 -> 0
C21: External | D21: Group | E21: Total | K21: =+I21-J21 -> 0
B22: =+"Sales "&$D$4 -> Sales W1 | C22: {=INDIRECT(ADDRESS(10,8,,,$D$4))} -> 0 | D22: {=INDIRECT(ADDRESS(11,8,,,$D$4))} -> 0 | E22: =SUM(C22:D22) -> 0 | K22: =+I22-J22 -> 0
B23: =+"Orderbook "&$D$4 -> Orderbook W1 | C23: {=INDIRECT(ADDRESS(17,11,,,$D$4))} -> 1190.6519 | D23: {=INDIRECT(ADDRESS(18,11,,,$D$4))} -> 8453.8 | E23: =SUM(C23:D23) -> 9644.4519 | K23: =+I23-J23 -> 0
B24: =+"Forecast "&$D$4 -> Forecast W1 | C24: =SUM(C22:C23) -> 1190.6519 | D24: =SUM(D22:D23) -> 8453.8 | E24: =SUM(E22:E23) -> 9644.4519 | K24: =+I24-J24 -> 0
K25: =+I25-J25 -> 0
K26: =+I26-J26 -> 0
B27: Somme de 2026 | C27: Étiquettes de colonnes | K27: =+I27-J27 -> 0
B28: Étiquettes de lignes | C28: W2 | D28: W1 | E28: Var | K28: =+I28-J28 -> 0
B29: 0 | C29: 0 | D29: 0 | E29: =+C29-D29 -> 0 | K29: =+I29-J29 -> 0
B30: Total général | C30: 0 | D30: 0 | E30: =+C30-D30 -> 0 | K30: =+I30-J30 -> 0
E31: =+C31-D31 -> 0 | K31: =+I31-J31 -> 0
E32: =+C32-D32 -> 0 | K32: =+I32-J32 -> 0
E33: =+C33-D33 -> 0 | K33: =+I33-J33 -> 0
E34: =+C34-D34 -> 0 | K34: =+I34-J34 -> 0
E35: =+C35-D35 -> 0 | K35: =+I35-J35 -> 0
E36: =+C36-D36 -> 0 | K36: =+I36-J36 -> 0
E37: =+C37-D37 -> 0 | K37: =+I37-J37 -> 0
E38: =+C38-D38 -> 0 | K38: =+I38-J38 -> 0
E39: =+C39-D39 -> 0 | K39: =+I39-J39 -> 0
E40: =+C40-D40 -> 0 | K40: =+I40-J40 -> 0
E41: =+C41-D41 -> 0 | K41: =+I41-J41 -> 0
E42: =+C42-D42 -> 0 | K42: =+I42-J42 -> 0
... E93: =+C93-D93 -> 0 | K93: =+I93-J93 -> 0
E94: =+C94-D94 -> 0
E95: =+C95-D95 -> 0
E96: =+C96-D96 -> 0
...

Sheet DB analysis orders
C2: Week | D2: =+'analysis week'!C4 -> W2 | E2: =+'analysis week'!D4 -> W1
C4: 5 | D4: =+C4+1 -> 6 | E4: =+D4+1 -> 7 | F4: =+E4+1 -> 8 | G4: =+F4+1 -> 9 | H4: =+G4+1 -> 10 | I4: =+H4+1 -> 11 | J4: =+I4+1 -> 12
B5: Week | C5: Order to be delivered | D5: External or Group | E5: Customers orders | F5: Quantity | G5: DGC | H5: TOTAL ORDERBOOK | I5: 2026 | J5: 2027
A6: =+INDEX(MATCH("X", 'W1'!D:D,0),,) -> 24 | B6: =+$D$2 -> W2 | C6: {=INDIRECT(ADDRESS($A6,C$4,,,$B6))} -> DEHK | D6: {=INDIRECT(ADDRESS($A6,D$4,,,$B6))} -> Group | E6: {=INDIRECT(ADDRESS($A6,E$4,,,$B6))} -> DEHK HK | F6: {=INDIRECT(ADDRESS($A6,F$4,,,$B6))} -> 0 | G6: {=INDIRECT(ADDRESS($A6,G$4,,,$B6))} -> G | H6: {=INDIRECT(ADDRESS($A6,H$4,,,$B6))} -> 8538.8 | I6: {=INDIRECT(ADDRESS($A6,I$4,,,$B6))} -> 8538.8 | J6: {=INDIRECT(ADDRESS($A6,J$4,,,$B6))} -> 0
A7: =+A6+1 -> 25 | B7: =+$D$2 -> W2 | C7: {=INDIRECT(ADDRESS($A7,C$4,,,$B7))} -> DIAM Singapore | D7: {=INDIRECT(ADDRESS($A7,D$4,,,$B7))} -> Group | E7: {=INDIRECT(ADDRESS($A7,E$4,,,$B7))} -> DIAM SINGAPORE | F7: {=INDIRECT(ADDRESS($A7,F$4,,,$B7))} -> 0 | G7: {=INDIRECT(ADDRESS($A7,G$4,,,$B7))} -> G | H7: {=INDIRECT(ADDRESS($A7,H$4,,,$B7))} -> 100 | I7: {=INDIRECT(ADDRESS($A7,I$4,,,$B7))} -> 100 | J7: {=INDIRECT(ADDRESS($A7,J$4,,,$B7))} -> 0
A8: =+A7+1 -> 26 | B8: =+$D$2 -> W2 | C8: {=INDIRECT(ADDRESS($A8,C$4,,,$B8))} -> Sephora | D8: {=INDIRECT(ADDRESS($A8,D$4,,,$B8))} -> External | E8: {=INDIRECT(ADDRESS($A8,E$4,,,$B8))} -> SEPHORA | F8: {=INDIRECT(ADDRESS($A8,F$4,,,$B8))} -> 0 | G8: {=INDIRECT(ADDRESS($A8,G$4,,,$B8))} -> E | H8: {=INDIRECT(ADDRESS($A8,H$4,,,$B8))} -> 309.454 | I8: {=INDIRECT(ADDRESS($A8,I$4,,,$B8))} -> 309.454 | J8: {=INDIRECT(ADDRESS($A8,J$4,,,$B8))} -> 0
A9: =+A8+1 -> 27 | B9: =+$D$2 -> W2 | C9: {=INDIRECT(ADDRESS($A9,C$4,,,$B9))} -> Burberry/Gucci/Lancaster | D9: {=INDIRECT(ADDRESS($A9,D$4,,,$B9))} -> External | E9: {=INDIRECT(ADDRESS($A9,E$4,,,$B9))} -> Coty | F9: {=INDIRECT(ADDRESS($A9,F$4,,,$B9))} -> 0 | G9: {=INDIRECT(ADDRESS($A9,G$4,,,$B9))} -> E | H9: {=INDIRECT(ADDRESS($A9,H$4,,,$B9))} -> 141.957 | I9: {=INDIRECT(ADDRESS($A9,I$4,,,$B9))} -> 141.957 | J9: {=INDIRECT(ADDRESS($A9,J$4,,,$B9))} -> 0
A10: =+A9+1 -> 28 | B10: =+$D$2 -> W2 | C10: {=INDIRECT(ADDRESS($A10,C$4,,,$B10))} -> Fenty | D10: {=INDIRECT(ADDRESS($A10,D$4,,,$B10))} -> External | E10: {=INDIRECT(ADDRESS($A10,E$4,,,$B10))} -> FENTY | F10: {=INDIRECT(ADDRESS($A10,F$4,,,$B10))} -> 0 | G10: {=INDIRECT(ADDRESS($A10,G$4,,,$B10))} -> E | H10: {=INDIRECT(ADDRESS($A10,H$4,,,$B10))} -> 6.708 | I10: {=INDIRECT(ADDRESS($A10,I$4,,,$B10))} -> 6.708 | J10: {=INDIRECT(ADDRESS($A10,J$4,,,$B10))} -> 0
A11: =+A10+1 -> 29 | B11: =+$D$2 -> W2 | C11: {=INDIRECT(ADDRESS($A11,C$4,,,$B11))} -> Herbeast/Komfymed/Chaling | D11: {=INDIRECT(ADDRESS($A11,D$4,,,$B11))} -> External | E11: {=INDIRECT(ADDRESS($A11,E$4,,,$B11))} -> SEPHORA-Exclusive brands | F11: {=INDIRECT(ADDRESS($A11,F$4,,,$B11))} -> 0 | G11: {=INDIRECT(ADDRESS($A11,G$4,,,$B11))} -> E | H11: {=INDIRECT(ADDRESS($A11,H$4,,,$B11))} -> 10.366 | I11: {=INDIRECT(ADDRESS($A11,I$4,,,$B11))} -> 10.366 | J11: {=INDIRECT(ADDRESS($A11,J$4,,,$B11))} -> 0
A12: =+A11+1 -> 30 | B12: =+$D$2 -> W2 | C12: {=INDIRECT(ADDRESS($A12,C$4,,,$B12))} -> Benefit/Fresh/Guerlain/Kenzo/Givenchy | D12: {=INDIRECT(ADDRESS($A12,D$4,,,$B12))} -> External | E12: {=INDIRECT(ADDRESS($A12,E$4,,,$B12))} -> LVMH | F12: {=INDIRECT(ADDRESS($A12,F$4,,,$B12))} -> 0 | G12: {=INDIRECT(ADDRESS($A12,G$4,,,$B12))} -> E | H12: {=INDIRECT(ADDRESS($A12,H$4,,,$B12))} -> 153.9259 | I12: {=INDIRECT(ADDRESS($A12,I$4,,,$B12))} -> 153.9259 | J12: {=INDIRECT(ADDRESS($A12,J$4,,,$B12))} -> 0
A13: =+A12+1 -> 31 | B13: =+$D$2 -> W2 | C13: {=INDIRECT(ADDRESS($A13,C$4,,,$B13))} -> ETERNAL( Laura Mercier) | D13: {=INDIRECT(ADDRESS($A13,D$4,,,$B13))} -> External | E13: {=INDIRECT(ADDRESS($A13,E$4,,,$B13))} -> ETERNAL | F13: {=INDIRECT(ADDRESS($A13,F$4,,,$B13))} -> 0 | G13: {=INDIRECT(ADDRESS($A13,G$4,,,$B13))} -> E | H13: {=INDIRECT(ADDRESS($A13,H$4,,,$B13))} -> 6.251 | I13: {=INDIRECT(ADDRESS($A13,I$4,,,$B13))} -> 6.251 | J13: {=INDIRECT(ADDRESS($A13,J$4,,,$B13))} -> 0
A14: =+A13+1 -> 32 | B14: =+$D$2 -> W2 | C14: {=INDIRECT(ADDRESS($A14,C$4,,,$B14))} -> Perfect Diary | D14: {=INDIRECT(ADDRESS($A14,D$4,,,$B14))} -> External | E14: {=INDIRECT(ADDRESS($A14,E$4,,,$B14))} -> Perfect Diary | F14: {=INDIRECT(ADDRESS($A14,F$4,,,$B14))} -> 0 | G14: {=INDIRECT(ADDRESS($A14,G$4,,,$B14))} -> E | H14: {=INDIRECT(ADDRESS($A14,H$4,,,$B14))} -> 14.456 | I14: {=INDIRECT(ADDRESS($A14,I$4,,,$B14))} -> 14.456 | J14: {=INDIRECT(ADDRESS($A14,J$4,,,$B14))} -> 0
A15: =+A14+1 -> 33 | B15: =+$D$2 -> W2 | C15: {=INDIRECT(ADDRESS($A15,C$4,,,$B15))} -> Clinique/BB/MAC/Estee Lauder | D15: {=INDIRECT(ADDRESS($A15,D$4,,,$B15))} -> External | E15: {=INDIRECT(ADDRESS($A15,E$4,,,$B15))} -> Estee Lauder | F15: {=INDIRECT(ADDRESS($A15,F$4,,,$B15))} -> 0 | G15: {=INDIRECT(ADDRESS($A15,G$4,,,$B15))} -> E | H15: {=INDIRECT(ADDRESS($A15,H$4,,,$B15))} -> 6.75 | I15: {=INDIRECT(ADDRESS($A15,I$4,,,$B15))} -> 6.75 | J15: {=INDIRECT(ADDRESS($A15,J$4,,,$B15))} -> 0
A16: =+A15+1 -> 34 | B16: =+$D$2 -> W2 | C16: {=INDIRECT(ADDRESS($A16,C$4,,,$B16))} -> Hourglass | D16: {=INDIRECT(ADDRESS($A16,D$4,,,$B16))} -> External | E16: {=INDIRECT(ADDRESS($A16,E$4,,,$B16))} -> Hourglass | F16: {=INDIRECT(ADDRESS($A16,F$4,,,$B16))} -> 0 | G16: {=INDIRECT(ADDRESS($A16,G$4,,,$B16))} -> E | H16: {=INDIRECT(ADDRESS($A16,H$4,,,$B16))} -> 360 | I16: {=INDIRECT(ADDRESS($A16,I$4,,,$B16))} -> 360 | J16: {=INDIRECT(ADDRESS($A16,J$4,,,$B16))} -> 0
A17: =+A16+1 -> 35 | B17: =+$D$2 -> W2 | C17: {=INDIRECT(ADDRESS($A17,C$4,,,$B17))} -> ARMANI | D17: {=INDIRECT(ADDRESS($A17,D$4,,,$B17))} -> External | E17: {=INDIRECT(ADDRESS($A17,E$4,,,$B17))} -> ARMANI | F17: {=INDIRECT(ADDRESS($A17,F$4,,,$B17))} -> 0 | G17: {=INDIRECT(ADDRESS($A17,G$4,,,$B17))} -> G | H17: {=INDIRECT(ADDRESS($A17,H$4,,,$B17))} -> 9.921 | I17: {=INDIRECT(ADDRESS($A17,I$4,,,$B17))} -> 9.921 | J17: {=INDIRECT(ADDRESS($A17,J$4,,,$B17))} -> 0
A18: =+A17+1 -> 36 | B18: =+$D$2 -> W2 | C18: {=INDIRECT(ADDRESS($A18,C$4,,,$B18))} -> Galenic | D18: {=INDIRECT(ADDRESS($A18,D$4,,,$B18))} -> External | E18: {=INDIRECT(ADDRESS($A18,E$4,,,$B18))} -> Galenic | F18: {=INDIRECT(ADDRESS($A18,F$4,,,$B18))} -> 0 | G18: {=INDIRECT(ADDRESS($A18,G$4,,,$B18))} -> E | H18: {=INDIRECT(ADDRESS($A18,H$4,,,$B18))} -> 23 | I18: {=INDIRECT(ADDRESS($A18,I$4,,,$B18))} -> 23 | J18: {=INDIRECT(ADDRESS($A18,J$4,,,$B18))} -> 0
... A233: =+A232+1 -> 251 | B233: =+$D$2 -> W2 | C233: {=INDIRECT(ADDRESS($A233,C$4,,,$B233))} -> 0 | D233: {=INDIRECT(ADDRESS($A233,D$4,,,$B233))} -> 0 | E233: {=INDIRECT(ADDRESS($A233,E$4,,,$B233))} -> 0 | F233: {=INDIRECT(ADDRESS($A233,F$4,,,$B233))} -> 0 | G233: {=INDIRECT(ADDRESS($A233,G$4,,,$B233))} -> 0 | H233: {=INDIRECT(ADDRESS($A233,H$4,,,$B233))} -> 0 | I233: {=INDIRECT(ADDRESS($A233,I$4,,,$B233))} -> 0 | J233: {=INDIRECT(ADDRESS($A233,J$4,,,$B233))} -> 0
A234: =+A6 -> 24 | B234: =+$E$2 -> W1 | C234: {=INDIRECT(ADDRESS($A234,C$4,,,$B234))} -> DEHK | D234: {=INDIRECT(ADDRESS($A234,D$4,,,$B234))} -> Group | E234: {=INDIRECT(ADDRESS($A234,E$4,,,$B234))} -> DEHK HK | F234: {=INDIRECT(ADDRESS($A234,F$4,,,$B234))} -> 0 | G234: {=INDIRECT(ADDRESS($A234,G$4,,,$B234))} -> G | H234: {=INDIRECT(ADDRESS($A234,H$4,,,$B234))} -> 8353.8 | I234: {=INDIRECT(ADDRESS($A234,I$4,,,$B234))} -> 8353.8 | J234: {=INDIRECT(ADDRESS($A234,J$4,,,$B234))} -> 0
A235: =+A7 -> 25 | B235: =+$E$2 -> W1 | C235: {=INDIRECT(ADDRESS($A235,C$4,,,$B235))} -> DIAM Singapore | D235: {=INDIRECT(ADDRESS($A235,D$4,,,$B235))} -> Group | E235: {=INDIRECT(ADDRESS($A235,E$4,,,$B235))} -> DIAM SINGAPORE | F235: {=INDIRECT(ADDRESS($A235,F$4,,,$B235))} -> 0 | G235: {=INDIRECT(ADDRESS($A235,G$4,,,$B235))} -> G | H235: {=INDIRECT(ADDRESS($A235,H$4,,,$B235))} -> 100 | I235: {=INDIRECT(ADDRESS($A235,I$4,,,$B235))} -> 100 | J235: {=INDIRECT(ADDRESS($A235,J$4,,,$B235))} -> 0
A236: =+A8 -> 26 | B236: =+$E$2 -> W1 | C236: {=INDIRECT(ADDRESS($A236,C$4,,,$B236))} -> Sephora | D236: {=INDIRECT(ADDRESS($A236,D$4,,,$B236))} -> External | E236: {=INDIRECT(ADDRESS($A236,E$4,,,$B236))} -> SEPHORA | F236: {=INDIRECT(ADDRESS($A236,F$4,,,$B236))} -> 0 | G236: {=INDIRECT(ADDRESS($A236,G$4,,,$B236))} -> E | H236: {=INDIRECT(ADDRESS($A236,H$4,,,$B236))} -> 292.454 | I236: {=INDIRECT(ADDRESS($A236,I$4,,,$B236))} -> 292.454 | J236: {=INDIRECT(ADDRESS($A236,J$4,,,$B236))} -> 0
A237: =+A9 -> 27 | B237: =+$E$2 -> W1 | C237: {=INDIRECT(ADDRESS($A237,C$4,,,$B237))} -> Burberry/Gucci/Lancaster | D237: {=INDIRECT(ADDRESS($A237,D$4,,,$B237))} -> External | E237: {=INDIRECT(ADDRESS($A237,E$4,,,$B237))} -> Coty | F237: {=INDIRECT(ADDRESS($A237,F$4,,,$B237))} -> 0 | G237: {=INDIRECT(ADDRESS($A237,G$4,,,$B237))} -> E | H237: {=INDIRECT(ADDRESS($A237,H$4,,,$B237))} -> 132.957 | I237: {=INDIRECT(ADDRESS($A237,I$4,,,$B237))} -> 132.957 | J237: {=INDIRECT(ADDRESS($A237,J$4,,,$B237))} -> 0
A238: =+A10 -> 28 | B238: =+$E$2 -> W1 | C238: {=INDIRECT(ADDRESS($A238,C$4,,,$B238))} -> Fenty | D238: {=INDIRECT(ADDRESS($A238,D$4,,,$B238))} -> External | E238: {=INDIRECT(ADDRESS($A238,E$4,,,$B238))} -> FENTY | F238: {=INDIRECT(ADDRESS($A238,F$4,,,$B238))} -> 0 | G238: {=INDIRECT(ADDRESS($A238,G$4,,,$B238))} -> E | H238: {=INDIRECT(ADDRESS($A238,H$4,,,$B238))} -> 3.708 | I238: {=INDIRECT(ADDRESS($A238,I$4,,,$B238))} -> 3.708 | J238: {=INDIRECT(ADDRESS($A238,J$4,,,$B238))} -> 0
A239: =+A11 -> 29 | B239: =+$E$2 -> W1 | C239: {=INDIRECT(ADDRESS($A239,C$4,,,$B239))} -> Herbeast/Komfymed/Chaling | D239: {=INDIRECT(ADDRESS($A239,D$4,,,$B239))} -> External | E239: {=INDIRECT(ADDRESS($A239,E$4,,,$B239))} -> SEPHORA-Exclusive brands | F239: {=INDIRECT(ADDRESS($A239,F$4,,,$B239))} -> 0 | G239: {=INDIRECT(ADDRESS($A239,G$4,,,$B239))} -> E | H239: {=INDIRECT(ADDRESS($A239,H$4,,,$B239))} -> 10.366 | I239: {=INDIRECT(ADDRESS($A239,I$4,,,$B239))} -> 10.366 | J239: {=INDIRECT(ADDRESS($A239,J$4,,,$B239))} -> 0
A240: =+A12 -> 30 | B240: =+$E$2 -> W1 | C240: {=INDIRECT(ADDRESS($A240,C$4,,,$B240))} -> Benefit/Fresh/Guerlain/Kenzo/Givenchy | D240: {=INDIRECT(ADDRESS($A240,D$4,,,$B240))} -> External | E240: {=INDIRECT(ADDRESS($A240,E$4,,,$B240))} -> LVMH | F240: {=INDIRECT(ADDRESS($A240,F$4,,,$B240))} -> 0 | G240: {=INDIRECT(ADDRESS($A240,G$4,,,$B240))} -> E | H240: {=INDIRECT(ADDRESS($A240,H$4,,,$B240))} -> 153.9259 | I240: {=INDIRECT(ADDRESS($A240,I$4,,,$B240))} -> 153.9259 | J240: {=INDIRECT(ADDRESS($A240,J$4,,,$B240))} -> 0
A241: =+A13 -> 31 | B241: =+$E$2 -> W1 | C241: {=INDIRECT(ADDRESS($A241,C$4,,,$B241))} -> ETERNAL( Laura Mercier) | D241: {=INDIRECT(ADDRESS($A241,D$4,,,$B241))} -> External | E241: {=INDIRECT(ADDRESS($A241,E$4,,,$B241))} -> ETERNAL | F241: {=INDIRECT(ADDRESS($A241,F$4,,,$B241))} -> 0 | G241: {=INDIRECT(ADDRESS($A241,G$4,,,$B241))} -> E | H241: {=INDIRECT(ADDRESS($A241,H$4,,,$B241))} -> 6.251 | I241: {=INDIRECT(ADDRESS($A241,I$4,,,$B241))} -> 6.251 | J241: {=INDIRECT(ADDRESS($A241,J$4,,,$B241))} -> 0
A242: =+A14 -> 32 | B242: =+$E$2 -> W1 | C242: {=INDIRECT(ADDRESS($A242,C$4,,,$B242))} -> Perfect Diary | D242: {=INDIRECT(ADDRESS($A242,D$4,,,$B242))} -> External | E242: {=INDIRECT(ADDRESS($A242,E$4,,,$B242))} -> Perfect Diary | F242: {=INDIRECT(ADDRESS($A242,F$4,,,$B242))} -> 0 | G242: {=INDIRECT(ADDRESS($A242,G$4,,,$B242))} -> E | H242: {=INDIRECT(ADDRESS($A242,H$4,,,$B242))} -> 14.456 | I242: {=INDIRECT(ADDRESS($A242,I$4,,,$B242))} -> 14.456 | J242: {=INDIRECT(ADDRESS($A242,J$4,,,$B242))} -> 0
A243: =+A15 -> 33 | B243: =+$E$2 -> W1 | C243: {=INDIRECT(ADDRESS($A243,C$4,,,$B243))} -> Clinique/BB/MAC/Estee Lauder | D243: {=INDIRECT(ADDRESS($A243,D$4,,,$B243))} -> External | E243: {=INDIRECT(ADDRESS($A243,E$4,,,$B243))} -> Estee Lauder | F243: {=INDIRECT(ADDRESS($A243,F$4,,,$B243))} -> 0 | G243: {=INDIRECT(ADDRESS($A243,G$4,,,$B243))} -> E | H243: {=INDIRECT(ADDRESS($A243,H$4,,,$B243))} -> 6.75 | I243: {=INDIRECT(ADDRESS($A243,I$4,,,$B243))} -> 6.75 | J243: {=INDIRECT(ADDRESS($A243,J$4,,,$B243))} -> 0
A244: =+A16 -> 34 | B244: =+$E$2 -> W1 | C244: {=INDIRECT(ADDRESS($A244,C$4,,,$B244))} -> Hourglass | D244: {=INDIRECT(ADDRESS($A244,D$4,,,$B244))} -> External | E244: {=INDIRECT(ADDRESS($A244,E$4,,,$B244))} -> Hourglass | F244: {=INDIRECT(ADDRESS($A244,F$4,,,$B244))} -> 0 | G244: {=INDIRECT(ADDRESS($A244,G$4,,,$B244))} -> E | H244: {=INDIRECT(ADDRESS($A244,H$4,,,$B244))} -> 360 | I244: {=INDIRECT(ADDRESS($A244,I$4,,,$B244))} -> 360 | J244: {=INDIRECT(ADDRESS($A244,J$4,,,$B244))} -> 0
A245: =+A17 -> 35 | B245: =+$E$2 -> W1 | C245: {=INDIRECT(ADDRESS($A245,C$4,,,$B245))} -> L‘oreal | D245: {=INDIRECT(ADDRESS($A245,D$4,,,$B245))} -> External | E245: {=INDIRECT(ADDRESS($A245,E$4,,,$B245))} -> L‘oreal(PACK) | F245: {=INDIRECT(ADDRESS($A245,F$4,,,$B245))} -> 0 | G245: {=INDIRECT(ADDRESS($A245,G$4,,,$B245))} -> E | H245: {=INDIRECT(ADDRESS($A245,H$4,,,$B245))} -> 209.784 | I245: {=INDIRECT(ADDRESS($A245,I$4,,,$B245))} -> 209.784 | J245: {=INDIRECT(ADDRESS($A245,J$4,,,$B245))} -> 0
... A461: =+A233 -> 251 | B461: =+$E$2 -> W1 | C461: {=INDIRECT(ADDRESS($A461,C$4,,,$B461))} -> 0 | D461: {=INDIRECT(ADDRESS($A461,D$4,,,$B461))} -> 0 | E461: {=INDIRECT(ADDRESS($A461,E$4,,,$B461))} -> 0 | F461: {=INDIRECT(ADDRESS($A461,F$4,,,$B461))} -> 0 | G461: {=INDIRECT(ADDRESS($A461,G$4,,,$B461))} -> 0 | H461: {=INDIRECT(ADDRESS($A461,H$4,,,$B461))} -> 0 | I461: {=INDIRECT(ADDRESS($A461,I$4,,,$B461))} -> 0 | J461: {=INDIRECT(ADDRESS($A461,J$4,,,$B461))} -> 0

Sheet Synth
A1: SYNTHESIS
A3: To be filled in (TURNOVER = BO)
A5: YTD : Year to date turnover. This means the cumulated turnover since the begining of the year.
A6: This turnover should the same as the turnover fill in Business Object (BO). See with your local accountant to know this turnover.
A8: TURNOVER | D8: ORDERBOOK 2026 | F8: FORECAST 2026 | H8: NEW ORDERS 2026 | J8: ORDERBOOK 2027
A10: W52 2025
A12: W1 | B12: =+'W1'!$J$12 -> 0 | D12: =+'W1'!$K$19 -> 9644.4519 | F12: =+B12+D12 -> 9644.4519 | H12: =D12+B12-D10 -> 9644.4519 | J12: =+'W1'!$L$19 -> 0
A13: W2 | B13: =+'W2'!$J$12 -> 93.912 | D13: =+'W2'!$K$19 -> 10199.373 | F13: =+B13+D13 -> 10293.285 | H13: =F13-F12 -> 648.833 | J13: =+'W2'!$L$19 -> 0
A14: W3 | B14: =+'W3'!$J$12 -> 319.115 | D14: =+'W3'!$K$19 -> 10132.398 | F14: =+B14+D14 -> 10451.513 | H14: =F14-F13 -> 158.228 | J14: =+'W3'!$L$19 -> 0
A15: W4 | B15: =+'W4'!$J$12 -> 2544.395 | D15: =+'W4'!$K$19 -> 8791.1139 | F15: =+B15+D15 -> 11335.509 | H15: =F15-F14 -> 883.996 | J15: =+'W4'!$L$19 -> 0
A16: W5 | B16: =+'W5'!$J$12 -> 5825.982 | D16: =+'W5'!$K$19 -> 5833.3499 | F16: =+B16+D16 -> 11659.332 | H16: =F16-F15 -> 323.823 | J16: =+'W5'!$L$19 -> 0
A17: January YTD
A18: W6 | B18: =+'W6'!$J$12 -> 171.096 | D18: =+'W6'!$K$19 -> 6587.1139 | F18: =+B17+B18+D18 -> 6758.2099 | H18: =F18-F16 -> -4901.122 | J18: =+'W6'!$L$19 -> 0
A19: W7 | B19: =+'W7'!$J$12 -> 328.897 | D19: =+'W7'!$K$19 -> 6449.4129 | F19: =+B17+B19+D19 -> 6778.3099 | H19: =F19-F18 -> 20.1 | J19: =+'W7'!$L$19 -> 0
A20: W8 | B20: =+'W8'!$J$12 -> 328.897 | D20: =+'W8'!$K$19 -> 6449.4129 | F20: =+B17+B20+D20 -> 6778.3099 | H20: =F20-F19 -> 0 | J20: =+'W8'!$L$19 -> 0
A21: W9 | B21: =+'W9'!$J$12 -> 1413.944 | D21: =+'W9'!$K$19 -> 5949.7629 | F21: =+B22+B21+D21 -> 7363.7069 | H21: =F21-F20 -> 585.397 | J21: =+'W9'!$L$19 -> 0
A22: February YTD
A23: W10 | B23: =+'W10'!$J$12 -> 90.95 | D23: =+'W10'!$K$19 -> 6520.8399 | F23: =+B22+B23+D23 -> 6611.7899 | H23: =F23-F21 -> -751.917 | J23: =+'W10'!$L$19 -> 0
A24: W11 | B24: =+'W11'!$J$12 -> 414.005 | D24: =+'W11'!$K$19 -> 6530.0279 | F24: =+B22+B24+D24 -> 6944.0329 | H24: =F24-F23 -> 332.243 | J24: =+'W11'!$L$19 -> 0
A25: W12 | B25: =+'W12'!$J$12 -> 673.918 | D25: =+'W12'!$K$19 -> 6360.7779 | F25: =+B22+B25+D25 -> 7034.6959 | H25: =F25-F24 -> 90.663 | J25: =+'W12'!$L$19 -> 0
A26: W13 | B26: =+'W13'!$J$12 -> 1083.376 | D26: =+'W13'!$K$19 -> 7230.6759 | F26: =+B22+B26+D26 -> 8314.0519 | H26: =F26-F25 -> 1279.356 | J26: =+'W13'!$L$19 -> 0
A27: March YTD
A28: W14 | B28: =+'W14'!$J$12 -> 0 | D28: =+'W14'!$K$19 -> 8258.6119 | F28: =+B27+B28+D28 -> 8258.6119 | H28: =F28-F26 -> -55.44 | J28: =+'W14'!$L$19 -> 0
A29: W15 | B29: =+'W15'!$J$12 -> 962.663 | D29: =+'W15'!$K$19 -> 7866.7289 | F29: =+B27+B29+D29 -> 8829.3919 | H29: =F29-F28 -> 570.78 | J29: =+'W15'!$L$19 -> 0
A30: W16 | B30: =+'W16'!$J$12 -> 1383.04 | D30: =+'W16'!$K$19 -> 8315.5249 | F30: =+B27+B30+D30 -> 9698.5649 | H30: =F30-F29 -> 869.173 | J30: =+'W16'!$L$19 -> 0
A31: W17 | B31: =+'W17'!$J$12 -> 2197.503 | D31: =+'W17'!$K$19 -> 8317.3289 | F31: =+B27+B31+D31 -> 10514.832 | H31: =F31-F30 -> 816.267 | J31: =+'W17'!$L$19 -> 0
A32: W18 | B32: =+'W18'!$J$12 -> 2525.698 | D32: =+'W18'!$K$19 -> 8191.8489 | F32: =+B33+B32+D32 -> 10717.547 | H32: =F32-F31 -> 202.715 | J32: =+'W18'!$L$19 -> 0
A33: April YTD
A34: W19 | B34: =+'W19'!$J$12 -> 0 | D34: =+'W19'!$K$19 -> 8385.0489 | F34: =+B33+B34+D34 -> 8385.0489 | H34: =F34-F32 -> -2332.498 | J34: =+'W19'!$L$19 -> 0
A35: W20 | B35: =+'W20'!$J$12 -> 261.312 | D35: =+'W20'!$K$19 -> 8379.9929 | F35: =+B33+B35+D35 -> 8641.3049 | H35: =F35-F34 -> 256.256 | J35: =+'W20'!$L$19 -> 0
A36: W21 | B36: =+'W21'!$J$12 -> 403.452 | D36: =+'W21'!$K$19 -> 11771.371 | F36: =+B33+B36+D36 -> 12174.823 | H36: =F36-F35 -> 3533.518 | J36: =+'W21'!$L$19 -> 0
A37: W22 | B37: =+'W22'!$J$12 -> 3229.064 | D37: =+'W22'!$K$19 -> 9063.9429 | F37: =+B38+B37+D37 -> 12293.007 | H37: =F37-F36 -> 118.184 | J37: =+'W22'!$L$19 -> 0
A38: May YTD
A39: W23 | B39: =+'W23'!$J$12 -> 0 | D39: =+'W23'!$K$19 -> 9112.5209 | F39: =+B38+B39+D39 -> 9112.5209 | H39: =F39-F37 -> -3180.486 | J39: =+'W23'!$L$19 -> 0
A40: W24 | B40: =+'W24'!$J$12 -> 207.691 | D40: =+'W24'!$K$19 -> 8908.9819 | F40: =+B38+B40+D40 -> 9116.6729 | H40: =F40-F39 -> 4.152 | J40: =+'W24'!$L$19 -> 0
A41: W25 | B41: =+'W25'!$J$12 -> 263.631 | D41: =+'W25'!$K$19 -> 8993.4509 | F41: =+B38+B41+D41 -> 9257.0819 | H41: =F41-F40 -> 140.409 | J41: =+'W25'!$L$19 -> 0
A42: W26 | B42: =+'W26'!$J$12 -> 571.826 | D42: =+'W26'!$K$19 -> 8841.2559 | F42: =+B38+B42+D42 -> 9413.0819 | H42: =F42-F41 -> 156 | J42: =+'W26'!$L$19 -> 0
A43: June YTD
A44: W27 | B44: =+'W27'!$J$12 -> 0 | D44: =+'W27'!$K$19 -> 7204.4989 | F44: =+B43+B44+D44 -> 7204.4989 | H44: =F44-F42 -> -2208.583 | J44: =+'W27'!$L$19 -> 0
A45: W28 | B45: =+'W28'!$J$12 -> 205.089 | D45: =+'W28'!$K$19 -> 7254.7209 | F45: =+B43+B45+D45 -> 7459.8099 | H45: =F45-F44 -> 255.311 | J45: =+'W28'!$L$19 -> 0
...

Sheet W1
E2: ENTITY NAME : | G2: =+parameters!D2 -> Diam CHINA | I2: ORDER BOOK SYNTHESIS in K€
E4: WEEK : | G4: W1 | I4: Cells to be filled in
E6: MONTH : | G6: =+VLOOKUP(G4, parameters!G:H, 2, 0) -> January
E8: TURNOVER | F8: =parameters!D4 -> k€ | H8: YTD Turnover | J8: =+G6&" Turnover" -> January Turnover | L8: Last estim. for the month: | O8: Forecast 2026
H9: =+"from January 1 until end of "&G4 -> from January 1 until end of W1 | J9: =+"from "&G6&" 1 until end of "&G4 -> from January 1 until end of W1 | L9: =+G6 -> January | O9: =+G4 -> W1
E10: EXTERNAL SALES INVOICED (=outside group) | H10: =J10 -> 0 | J10: =0 -> 0 | L10: =J10+N17 -> 263.6359 | O10: =+H10+K17 -> 1190.6519
E11: GROUP SALES INVOICED | H11: =J11 -> 0 | J11: =0 -> 0 | L11: =J11+N18 -> 4479.5 | O11: =+H11+K18 -> 8453.8 | S11: Definition orders : you consider the orders which are sure even if the order customers paper order is not yet received
E12: TOTAL | H12: =SUM(H10:H11) -> 0 | J12: =SUM(J10:J11) -> 0 | L12: =SUM(L10:L11) -> 4743.1359 | O12: =SUM(O10:O11) -> 9644.4519 | S12: The quantity, value, and delivery date can be changed before final delivery
E16: ORDERBOOK | F16: =+F8 -> k€ | J16: TOTAL ORDERBOOK | K16: Total amount 2026 | L16: Total amount 2027 | N16: 46023 | O16: 46054 | P16: 46082 | Q16: 46113 | R16: 46143 | S16: 46174 | T16: 46204 | U16: 46235 | V16: 46266 | W16: 46296 | X16: 46327 | Y16: 46357 | AA16: 46388 | AB16: 46419 | AC16: 46447 | AD16: 46478 | AE16: 46508 | AF16: 46539 | AG16: 46569 | AH16: 46600 | AI16: 46631 | AJ16: 46661 | AK16: 46692 | AL16: 46722
E17: External | J17: =+SUMIF($F$24:$F$243,"External",$J$24:$J$243) -> 1190.6519 | K17: =+SUMIF($F$24:$F$243,"External",$K$24:$K$243) -> 1190.6519 | L17: =+SUMIF($F$24:$F$243,"External",$L$24:$L$243) -> 0 | N17: =+SUMIF($F$24:$F$243,"External",N$24:N$243) -> 263.6359 | O17: =+SUMIF($F$24:$F$243,"External",O$24:O$243) -> 346 | P17: =+SUMIF($F$24:$F$243,"External",P$24:P$243) -> 107 | Q17: =+SUMIF($F$24:$F$243,"External",Q$24:Q$243) -> 398 | R17: =+SUMIF($F$24:$F$243,"External",R$24:R$243) -> 76.016 | S17: =+SUMIF($F$24:$F$243,"External",S$24:S$243) -> 0 | T17: =+SUMIF($F$24:$F$243,"External",T$24:T$243) -> 0 | U17: =+SUMIF($F$24:$F$243,"External",U$24:U$243) -> 0 | ... Y17: =+SUMIF($F$24:$F$243,"External",Y$24:Y$243) -> 0 | AA17: =+SUMIF($F$24:$F$243,"External",AA$24:AA$243) -> 0 | AB17: =+SUMIF($F$24:$F$243,"External",AB$24:AB$243) -> 0 | AC17: =+SUMIF($F$24:$F$243,"External",AC$24:AC$243) -> 0 | AD17: =+SUMIF($F$24:$F$243,"External",AD$24:AD$243) -> 0 | AE17: =+SUMIF($F$24:$F$243,"External",AE$24:AE$243) -> 0 | AF17: =+SUMIF($F$24:$F$243,"External",AF$24:AF$243) -> 0 | AG17: =+SUMIF($F$24:$F$243,"External",AG$24:AG$243) -> 0 | AH17: =+SUMIF($F$24:$F$243,"External",AH$24:AH$243) -> 0 | ... AL17: =+SUMIF($F$24:$F$243,"External",AL$24:AL$243) -> 0
E18: Group | J18: =+SUMIF($F$24:$F$243,"Group",$J$24:$J$243) -> 8453.8 | K18: =+SUMIF($F$24:$F$243,"Group",$K$24:$K$243) -> 8453.8 | L18: =SUMIF($F$24:$F$243,"Group",$L$24:$L$243) -> 0 | N18: =+SUMIF($F$24:$F$243,"Group",N$24:N$243) -> 4479.5 | O18: =+SUMIF($F$24:$F$243,"Group",O$24:O$243) -> 1592.1 | P18: =+SUMIF($F$24:$F$243,"Group",P$24:P$243) -> 507.5 | Q18: =+SUMIF($F$24:$F$243,"Group",Q$24:Q$243) -> 273.5 | R18: =+SUMIF($F$24:$F$243,"Group",R$24:R$243) -> 375.5 | S18: =+SUMIF($F$24:$F$243,"Group",S$24:S$243) -> 1218 | T18: =+SUMIF($F$24:$F$243,"Group",T$24:T$243) -> 7.7 | U18: =+SUMIF($F$24:$F$243,"Group",U$24:U$243) -> 0 | ... Y18: =+SUMIF($F$24:$F$243,"Group",Y$24:Y$243) -> 0 | AA18: =+SUMIF($F$24:$F$243,"Group",AA$24:AA$243) -> 0 | AB18: =+SUMIF($F$24:$F$243,"Group",AB$24:AB$243) -> 0 | AC18: =+SUMIF($F$24:$F$243,"Group",AC$24:AC$243) -> 0 | AD18: =+SUMIF($F$24:$F$243,"Group",AD$24:AD$243) -> 0 | AE18: =+SUMIF($F$24:$F$243,"Group",AE$24:AE$243) -> 0 | AF18: =+SUMIF($F$24:$F$243,"Group",AF$24:AF$243) -> 0 | AG18: =+SUMIF($F$24:$F$243,"Group",AG$24:AG$243) -> 0 | AH18: =+SUMIF($F$24:$F$243,"Group",AH$24:AH$243) -> 0 | ... AL18: =+SUMIF($F$24:$F$243,"Group",AL$24:AL$243) -> 0
E19: TOTAL | J19: =SUM(J17:J18) -> 9644.4519 | K19: =SUM(K17:K18) -> 9644.4519 | L19: =SUM(L17:L18) -> 0 | N19: =SUM(N17:N18) -> 4743.1359 | O19: =SUM(O17:O18) -> 1938.1 | P19: =SUM(P17:P18) -> 614.5 | Q19: =SUM(Q17:Q18) -> 671.5 | R19: =SUM(R17:R18) -> 451.516 | S19: =SUM(S17:S18) -> 1218 | T19: =SUM(T17:T18) -> 7.7 | U19: =SUM(U17:U18) -> 0 | ... Y19: =SUM(Y17:Y18) -> 0 | AA19: =SUM(AA17:AA18) -> 0 | AB19: =SUM(AB17:AB18) -> 0 | AC19: =SUM(AC17:AC18) -> 0 | AD19: =SUM(AD17:AD18) -> 0 | AE19: =SUM(AE17:AE18) -> 0 | AF19: =SUM(AF17:AF18) -> 0 | AG19: =SUM(AG17:AG18) -> 0 | AH19: =SUM(AH17:AH18) -> 0 | ... AL19: =SUM(AL17:AL18) -> 0
I21: check | J21: =IF(SUM(J24:J243)=J19, "OK", "Please correct: the sum of orders below is not equal to the total calculated above. Make sure to pick External or Group for each order and don't change the formulas in columns K and L") -> OK | N21: 2026 | AA21: 2027
E23: Order (Tooling including) to be delivered | F23: External or Group | G23: Customers orders | H23: Quantity | I23: DGC | J23: TOTAL ORDERBOOK | K23: Total amount 2026 | L23: Total amount 2027 | N23: 46023 | O23: 46054 | P23: 46082 | Q23: 46113 | R23: 46143 | S23: 46174 | T23: 46204 | U23: 46235 | V23: 46266 | W23: 46296 | X23: 46327 | Y23: 46357 | AA23: 46388 | AB23: 46419 | AC23: 46447 | AD23: 46478 | AE23: 46508 | AF23: 46539 | AG23: 46569 | AH23: 46600 | AI23: 46631 | AJ23: 46661 | AK23: 46692 | AL23: 46722
D24: X | E24: DEHK | F24: Group | G24: DEHK HK | I24: G | J24: =+K24+L24 -> 8353.8 | K24: =SUM(N24:Y24) -> 8353.8 | L24: =SUM(AA24:AL24) -> 0 | N24: 4429.5 | O24: 1542.1 | P24: 507.5 | Q24: 273.5 | R24: 375.5 | S24: 1218 | T24: 7.7
E25: DIAM Singapore | F25: Group | G25: DIAM SINGAPORE | I25: G | J25: =+K25+L25 -> 100 | K25: =SUM(N25:Y25) -> 100 | L25: =SUM(AA25:AL25) -> 0 | N25: 50 | O25: 50
E26: Sephora | F26: External | G26: SEPHORA | I26: E | J26: =+K26+L26 -> 292.454 | K26: =SUM(N26:Y26) -> 292.454 | L26: =SUM(AA26:AL26) -> 0 | N26: 17.438 | O26: 128 | P26: 94 | R26: 53.016
E27: Burberry/Gucci/Lancaster | F27: External | G27: Coty | I27: E | J27: =+K27+L27 -> 132.957 | K27: =SUM(N27:Y27) -> 132.957 | L27: =SUM(AA27:AL27) -> 0 | N27: 28.957 | O27: 104
E28: Fenty | F28: External | G28: FENTY | I28: E | J28: =+K28+L28 -> 3.708 | K28: =SUM(N28:Y28) -> 3.708 | L28: =SUM(AA28:AL28) -> 0 | N28: 3.708
E29: Herbeast/Komfymed/Chaling | F29: External | G29: SEPHORA-Exclusive brands | I29: E | J29: =+K29+L29 -> 10.366 | K29: =SUM(N29:Y29) -> 10.366 | L29: =SUM(AA29:AL29) -> 0 | N29: 8.366 | O29: 2
E30: Benefit/Fresh/Guerlain/Kenzo/Givenchy | F30: External | G30: LVMH | I30: E | J30: =+K30+L30 -> 153.9259 | K30: =SUM(N30:Y30) -> 153.9259 | L30: =SUM(AA30:AL30) -> 0 | N30: 59.9259 | P30: 13 | Q30: 58 | R30: 23
E31: ETERNAL( Laura Mercier) | F31: External | G31: ETERNAL | I31: E | J31: =+K31+L31 -> 6.251 | K31: =SUM(N31:Y31) -> 6.251 | L31: =SUM(AA31:AL31) -> 0 | N31: 2.251 | O31: 4
E32: Perfect Diary | F32: External | G32: Perfect Diary | I32: E | J32: =+K32+L32 -> 14.456 | K32: =SUM(N32:Y32) -> 14.456 | L32: =SUM(AA32:AL32) -> 0 | N32: 12.456 | O32: 2
E33: Clinique/BB/MAC/Estee Lauder | F33: External | G33: Estee Lauder | I33: E | J33: =+K33+L33 -> 6.75 | K33: =SUM(N33:Y33) -> 6.75 | L33: =SUM(AA33:AL33) -> 0 | N33: 5.75 | O33: 1
E34: Hourglass | F34: External | G34: Hourglass | I34: E | J34: =+K34+L34 -> 360 | K34: =SUM(N34:Y34) -> 360 | L34: =SUM(AA34:AL34) -> 0 | N34: 20 | Q34: 340
E35: L‘oreal | F35: External | G35: L‘oreal(PACK) | I35: E | J35: =+K35+L35 -> 209.784 | K35: =SUM(N35:Y35) -> 209.784 | L35: =SUM(AA35:AL35) -> 0 | N35: 104.784 | O35: 105
J36: =+K36+L36 -> 0 | K36: =SUM(N36:Y36) -> 0 | L36: =SUM(AA36:AL36) -> 0
J37: =+K37+L37 -> 0 | K37: =SUM(N37:Y37) -> 0 | L37: =SUM(AA37:AL37) -> 0
J38: =+K38+L38 -> 0 | K38: =SUM(N38:Y38) -> 0 | L38: =SUM(AA38:AL38) -> 0
J39: =+K39+L39 -> 0 | K39: =SUM(N39:Y39) -> 0 | L39: =SUM(AA39:AL39) -> 0
J40: =+K40+L40 -> 0 | K40: =SUM(N40:Y40) -> 0 | L40: =SUM(AA40:AL40) -> 0
J41: =+K41+L41 -> 0 | K41: =SUM(N41:Y41) -> 0 | L41: =SUM(AA41:AL41) -> 0
J42: =+K42+L42 -> 0 | K42: =SUM(N42:Y42) -> 0 | L42: =SUM(AA42:AL42) -> 0
J43: =+K43+L43 -> 0 | K43: =SUM(N43:Y43) -> 0 | L43: =SUM(AA43:AL43) -> 0
J44: =+K44+L44 -> 0 | K44: =SUM(N44:Y44) -> 0 | L44: =SUM(AA44:AL44) -> 0
J45: =+K45+L45 -> 0 | K45: =SUM(N45:Y45) -> 0 | L45: =SUM(AA45:AL45) -> 0
J46: =+K46+L46 -> 0 | K46: =SUM(N46:Y46) -> 0 | L46: =SUM(AA46:AL46) -> 0
J47: =+K47+L47 -> 0 | K47: =SUM(N47:Y47) -> 0 | L47: =SUM(AA47:AL47) -> 0
... J243: =+K243+L243 -> 0 | K243: =SUM(N243:Y243) -> 0 | L243: =SUM(AA243:AL243) -> 0

Sheet W2
E2: ENTITY NAME : | G2: =+parameters!D2 -> Diam CHINA | I2: ORDER BOOK SYNTHESIS in K€
E4: WEEK : | G4: W2 | I4: Cells to be filled in
E6: MONTH : | G6: =+VLOOKUP(G4, parameters!G:H, 2, 0) -> January
E8: TURNOVER | F8: =parameters!D4 -> k€ | H8: YTD Turnover | J8: =+G6&" Turnover" -> January Turnover | L8: Last estim. for the month: | O8: Forecast 2026
H9: =+"from January 1 until end of "&G4 -> from January 1 until end of W2 | J9: =+"from "&G6&" 1 until end of "&G4 -> from January 1 until end of W2 | L9: =+G6 -> January | O9: =+G4 -> W2 | P9: =+VLOOKUP(G4, parameters!$G$9:$I$61,3,0) -> W1 | Q9: Var
E10: EXTERNAL SALES INVOICED (=outside group) | H10: =J10 -> 0 | J10: =0 -> 0 | L10: =J10+N17 -> 518.6629 | O10: =+H10+K17 -> 1560.5729 | P10: {=INDIRECT(ADDRESS(10,15,,,VLOOKUP($G$4,parameters!$G:$I,3,0)))} -> 1190.6519 | Q10: =O10-P10 -> 369.921
E11: GROUP SALES INVOICED | H11: =J11 -> 93.912 | J11: =0+93.912 -> 93.912 | L11: =J11+N18 -> 4483.112 | O11: =+H11+K18 -> 8732.712 | P11: {=INDIRECT(ADDRESS(11,15,,,VLOOKUP($G$4,parameters!$G:$I,3,0)))} -> 8453.8 | Q11: =O11-P11 -> 278.912 | S11: Definition orders : you consider the orders which are sure even if the order customers paper order is not yet received
E12: TOTAL | H12: =SUM(H10:H11) -> 93.912 | J12: =SUM(J10:J11) -> 93.912 | L12: =SUM(L10:L11) -> 5001.7749 | O12: =SUM(O10:O11) -> 10293.285 | P12: =SUM(P10:P11) -> 9644.4519 | Q12: =O12-P12 -> 648.833 | S12: The quantity, value, and delivery date can be changed before final delivery
E16: ORDERBOOK | F16: =+F8 -> k€ | J16: TOTAL ORDERBOOK | K16: Total amount 2026 | L16: Total amount 2027 | N16: 46023 | O16: 46054 | P16: 46082 | Q16: 46113 | R16: 46143 | S16: 46174 | T16: 46204 | U16: 46235 | V16: 46266 | W16: 46296 | X16: 46327 | Y16: 46357 | AA16: 46388 | AB16: 46419 | AC16: 46447 | AD16: 46478 | AE16: 46508 | AF16: 46539 | AG16: 46569 | AH16: 46600 | AI16: 46631 | AJ16: 46661 | AK16: 46692 | AL16: 46722
E17: External | J17: =+SUMIF($F$24:$F$252,"External",$J$24:$J$252) -> 1560.5729 | K17: =+SUMIF($F$24:$F$252,"External",$K$24:$K$252) -> 1560.5729 | L17: =+SUMIF($F$24:$F$252,"External",$L$24:$L$252) -> 0 | N17: =+SUMIF($F$24:$F$252,"External",N$24:N$252) -> 518.6629 | O17: =+SUMIF($F$24:$F$252,"External",O$24:O$252) -> 340.438 | P17: =+SUMIF($F$24:$F$252,"External",P$24:P$252) -> 190 | Q17: =+SUMIF($F$24:$F$252,"External",Q$24:Q$252) -> 151.472 | R17: =+SUMIF($F$24:$F$252,"External",R$24:R$252) -> 0 | S17: =+SUMIF($F$24:$F$252,"External",S$24:S$252) -> 0 | T17: =+SUMIF($F$24:$F$252,"External",T$24:T$252) -> 0 | U17: =+SUMIF($F$24:$F$252,"External",U$24:U$252) -> 360 | ... Y17: =+SUMIF($F$24:$F$252,"External",Y$24:Y$252) -> 0 | AA17: =+SUMIF($F$24:$F$252,"External",AA$24:AA$252) -> 0 | AB17: =+SUMIF($F$24:$F$252,"External",AB$24:AB$252) -> 0 | AC17: =+SUMIF($F$24:$F$252,"External",AC$24:AC$252) -> 0 | AD17: =+SUMIF($F$24:$F$252,"External",AD$24:AD$252) -> 0 | AE17: =+SUMIF($F$24:$F$252,"External",AE$24:AE$252) -> 0 | AF17: =+SUMIF($F$24:$F$252,"External",AF$24:AF$252) -> 0 | AG17: =+SUMIF($F$24:$F$252,"External",AG$24:AG$252) -> 0 | AH17: =+SUMIF($F$24:$F$252,"External",AH$24:AH$252) -> 0 | ... AL17: =+SUMIF($F$24:$F$252,"External",AL$24:AL$252) -> 0
E18: Group | J18: =+SUMIF($F$24:$F$252,"Group",$J$24:$J$252) -> 8638.8 | K18: =+SUMIF($F$24:$F$252,"Group",$K$24:$K$252) -> 8638.8 | L18: =SUMIF($F$24:$F$252,"Group",$L$24:$L$252) -> 0 | N18: =+SUMIF($F$24:$F$252,"Group",N$24:N$252) -> 4389.2 | O18: =+SUMIF($F$24:$F$252,"Group",O$24:O$252) -> 1624.3 | P18: =+SUMIF($F$24:$F$252,"Group",P$24:P$252) -> 342.5 | Q18: =+SUMIF($F$24:$F$252,"Group",Q$24:Q$252) -> 302.2 | R18: =+SUMIF($F$24:$F$252,"Group",R$24:R$252) -> 73.5 | S18: =+SUMIF($F$24:$F$252,"Group",S$24:S$252) -> 200.5 | T18: =+SUMIF($F$24:$F$252,"Group",T$24:T$252) -> 322.7 | U18: =+SUMIF($F$24:$F$252,"Group",U$24:U$252) -> 1383.9 | ... Y18: =+SUMIF($F$24:$F$252,"Group",Y$24:Y$252) -> 0 | AA18: =+SUMIF($F$24:$F$252,"Group",AA$24:AA$252) -> 0 | AB18: =+SUMIF($F$24:$F$252,"Group",AB$24:AB$252) -> 0 | AC18: =+SUMIF($F$24:$F$252,"Group",AC$24:AC$252) -> 0 | AD18: =+SUMIF($F$24:$F$252,"Group",AD$24:AD$252) -> 0 | AE18: =+SUMIF($F$24:$F$252,"Group",AE$24:AE$252) -> 0 | AF18: =+SUMIF($F$24:$F$252,"Group",AF$24:AF$252) -> 0 | AG18: =+SUMIF($F$24:$F$252,"Group",AG$24:AG$252) -> 0 | AH18: =+SUMIF($F$24:$F$252,"Group",AH$24:AH$252) -> 0 | ... AL18: =+SUMIF($F$24:$F$252,"Group",AL$24:AL$252) -> 0
E19: TOTAL | J19: =SUM(J17:J18) -> 10199.373 | K19: =SUM(K17:K18) -> 10199.373 | L19: =SUM(L17:L18) -> 0 | N19: =SUM(N17:N18) -> 4907.8629 | O19: =SUM(O17:O18) -> 1964.738 | P19: =SUM(P17:P18) -> 532.5 | Q19: =SUM(Q17:Q18) -> 453.672 | R19: =SUM(R17:R18) -> 73.5 | S19: =SUM(S17:S18) -> 200.5 | T19: =SUM(T17:T18) -> 322.7 | U19: =SUM(U17:U18) -> 1743.9 | ... Y19: =SUM(Y17:Y18) -> 0 | AA19: =SUM(AA17:AA18) -> 0 | AB19: =SUM(AB17:AB18) -> 0 | AC19: =SUM(AC17:AC18) -> 0 | AD19: =SUM(AD17:AD18) -> 0 | AE19: =SUM(AE17:AE18) -> 0 | AF19: =SUM(AF17:AF18) -> 0 | AG19: =SUM(AG17:AG18) -> 0 | AH19: =SUM(AH17:AH18) -> 0 | ... AL19: =SUM(AL17:AL18) -> 0
I21: check | J21: =IF(SUM(J24:J252)=J19, "OK", "Please correct: the sum of orders below is not equal to the total calculated above. Make sure to pick External or Group for each order and don't change the formulas in columns K and L") -> OK | N21: 2026 | AA21: 2027
E23: Order (Tooling including) to be delivered | F23: External or Group | G23: Customers orders | H23: Quantity | I23: DGC | J23: TOTAL ORDERBOOK | K23: Total amount 2026 | L23: Total amount 2027 | N23: 46023 | O23: 46054 | P23: 46082 | Q23: 46113 | R23: 46143 | S23: 46174 | T23: 46204 | U23: 46235 | V23: 46266 | W23: 46296 | X23: 46327 | Y23: 46357 | AA23: 46388 | AB23: 46419 | AC23: 46447 | AD23: 46478 | AE23: 46508 | AF23: 46539 | AG23: 46569 | AH23: 46600 | AI23: 46631 | AJ23: 46661 | AK23: 46692 | AL23: 46722
D24: X | E24: DEHK | F24: Group | G24: DEHK HK | I24: G | J24: =+K24+L24 -> 8538.8 | K24: =SUM(N24:Y24) -> 8538.8 | L24: =SUM(AA24:AL24) -> 0 | N24: 4351.2 | O24: 1623.3 | P24: 336.5 | Q24: 302.2 | R24: 73.5 | S24: 145.5 | T24: 322.7 | U24: 1383.9
E25: DIAM Singapore | F25: Group | G25: DIAM SINGAPORE | I25: G | J25: =+K25+L25 -> 100 | K25: =SUM(N25:Y25) -> 100 | L25: =SUM(AA25:AL25) -> 0 | N25: =50-12 -> 38 | O25: 1 | P25: 6 | S25: =50-1-6+12 -> 55
E26: Sephora | F26: External | G26: SEPHORA | I26: E | J26: =+K26+L26 -> 309.454 | K26: =SUM(N26:Y26) -> 309.454 | L26: =SUM(AA26:AL26) -> 0 | O26: =128+17.438+94-9 -> 230.438 | Q26: =53.016+9+17 -> 79.016
E27: Burberry/Gucci/Lancaster | F27: External | G27: Coty | I27: E | J27: =+K27+L27 -> 141.957 | K27: =SUM(N27:Y27) -> 141.957 | L27: =SUM(AA27:AL27) -> 0 | N27: =28.957+8 -> 36.957 | O27: =104-8+9 -> 105
E28: Fenty | F28: External | G28: FENTY | I28: E | J28: =+K28+L28 -> 6.708 | K28: =SUM(N28:Y28) -> 6.708 | L28: =SUM(AA28:AL28) -> 0 | N28: =3.708+3 -> 6.708
E29: Herbeast/Komfymed/Chaling | F29: External | G29: SEPHORA-Exclusive brands | I29: E | J29: =+K29+L29 -> 10.366 | K29: =SUM(N29:Y29) -> 10.366 | L29: =SUM(AA29:AL29) -> 0 | N29: =8.366-3 -> 5.366 | P29: 5
E30: Benefit/Fresh/Guerlain/Kenzo/Givenchy | F30: External | G30: LVMH | I30: E | J30: =+K30+L30 -> 153.9259 | K30: =SUM(N30:Y30) -> 153.9259 | L30: =SUM(AA30:AL30) -> 0 | N30: =59.9259-2 -> 57.9259 | P30: =13+2+21 -> 36 | Q30: =58+2 -> 60
E31: ETERNAL( Laura Mercier) | F31: External | G31: ETERNAL | I31: E | J31: =+K31+L31 -> 6.251 | K31: =SUM(N31:Y31) -> 6.251 | L31: =SUM(AA31:AL31) -> 0 | N31: 2.251 | O31: 4
E32: Perfect Diary | F32: External | G32: Perfect Diary | I32: E | J32: =+K32+L32 -> 14.456 | K32: =SUM(N32:Y32) -> 14.456 | L32: =SUM(AA32:AL32) -> 0 | N32: 2 | Q32: 12.456
E33: Clinique/BB/MAC/Estee Lauder | F33: External | G33: Estee Lauder | I33: E | J33: =+K33+L33 -> 6.75 | K33: =SUM(N33:Y33) -> 6.75 | L33: =SUM(AA33:AL33) -> 0 | N33: 5.75 | O33: 1
E34: Hourglass | F34: External | G34: Hourglass | I34: E | J34: =+K34+L34 -> 360 | K34: =SUM(N34:Y34) -> 360 | L34: =SUM(AA34:AL34) -> 0 | U34: 360
E35: ARMANI | F35: External | G35: ARMANI | I35: G | J35: =+K35+L35 -> 9.921 | K35: =SUM(N35:Y35) -> 9.921 | L35: =SUM(AA35:AL35) -> 0 | N35: 9.921
E36: Galenic | F36: External | G36: Galenic | I36: E | J36: =+K36+L36 -> 23 | K36: =SUM(N36:Y36) -> 23 | L36: =SUM(AA36:AL36) -> 0 | P36: 23
E37: YAMEI(Trading) | F37: External | G37: YAMEI(Trading) | I37: E | J37: =+K37+L37 -> 170 | K37: =SUM(N37:Y37) -> 170 | L37: =SUM(AA37:AL37) -> 0 | N37: 170
E38: L‘oreal | F38: External | G38: L‘oreal(PACK) | I38: E | J38: =+K38+L38 -> 347.784 | K38: =SUM(N38:Y38) -> 347.784 | L38: =SUM(AA38:AL38) -> 0 | N38: =104.784+105+12 -> 221.784 | P38: 126
J39: =+K39+L39 -> 0 | K39: =SUM(N39:Y39) -> 0 | L39: =SUM(AA39:AL39) -> 0
J40: =+K40+L40 -> 0 | K40: =SUM(N40:Y40) -> 0 | L40: =SUM(AA40:AL40) -> 0
J41: =+K41+L41 -> 0 | K41: =SUM(N41:Y41) -> 0 | L41: =SUM(AA41:AL41) -> 0
J42: =+K42+L42 -> 0 | K42: =SUM(N42:Y42) -> 0 | L42: =SUM(AA42:AL42) -> 0
J43: =+K43+L43 -> 0 | K43: =SUM(N43:Y43) -> 0 | L43: =SUM(AA43:AL43) -> 0
J44: =+K44+L44 -> 0 | K44: =SUM(N44:Y44) -> 0 | L44: =SUM(AA44:AL44) -> 0
J45: =+K45+L45 -> 0 | K45: =SUM(N45:Y45) -> 0 | L45: =SUM(AA45:AL45) -> 0
J46: =+K46+L46 -> 0 | K46: =SUM(N46:Y46) -> 0 | L46: =SUM(AA46:AL46) -> 0
J47: =+K47+L47 -> 0 | K47: =SUM(N47:Y47) -> 0 | L47: =SUM(AA47:AL47) -> 0
J48: =+K48+L48 -> 0 | K48: =SUM(N48:Y48) -> 0 | L48: =SUM(AA48:AL48) -> 0
J49: =+K49+L49 -> 0 | K49: =SUM(N49:Y49) -> 0 | L49: =SUM(AA49:AL49) -> 0
...

Sheet W3
E2: ENTITY NAME : | G2: =+parameters!D2 -> Diam CHINA | I2: ORDER BOOK SYNTHESIS in K€
E4: WEEK : | G4: W3 | I4: Cells to be filled in
E6: MONTH : | G6: =+VLOOKUP(G4, parameters!G:H, 2, 0) -> January
E8: TURNOVER | F8: =parameters!D4 -> k€ | H8: YTD Turnover | J8: =+G6&" Turnover" -> January Turnover | L8: Last estim. for the month: | O8: Forecast 2026
H9: =+"from January 1 until end of "&G4 -> from January 1 until end of W3 | J9: =+"from "&G6&" 1 until end of "&G4 -> from January 1 until end of W3 | L9: =+G6 -> January | O9: =+G4 -> W3 | P9: =+VLOOKUP(G4, parameters!$G$9:$I$61,3,0) -> W2 | Q9: Var
E10: EXTERNAL SALES INVOICED (=outside group) | H10: =J10 -> 42.329 | J10: =0+42.329 -> 42.329 | L10: =J10+N17 -> 568.9129 | O10: =+H10+K17 -> 1585.3269 | P10: {=INDIRECT(ADDRESS(10,15,,,VLOOKUP($G$4,parameters!$G:$I,3,0)))} -> 1560.5729 | Q10: =O10-P10 -> 24.754
E11: GROUP SALES INVOICED | H11: =J11 -> 276.786 | J11: =0+93.912+182.874 -> 276.786 | L11: =J11+N18 -> 4309.286 | O11: =+H11+K18 -> 8866.186 | P11: {=INDIRECT(ADDRESS(11,15,,,VLOOKUP($G$4,parameters!$G:$I,3,0)))} -> 8732.712 | Q11: =O11-P11 -> 133.474 | S11: Definition orders : you consider the orders which are sure even if the order customers paper order is not yet received
E12: TOTAL | H12: =SUM(H10:H11) -> 319.115 | J12: =SUM(J10:J11) -> 319.115 | L12: =SUM(L10:L11) -> 4878.1989 | O12: =SUM(O10:O11) -> 10451.513 | P12: =SUM(P10:P11) -> 10293.285 | Q12: =O12-P12 -> 158.228 | S12: The quantity, value, and delivery date can be changed before final delivery
E16: ORDERBOOK | F16: =+F8 -> k€ | J16: TOTAL ORDERBOOK | K16: Total amount 2026 | L16: Total amount 2027 | N16: 46023 | O16: 46054 | P16: 46082 | Q16: 46113 | R16: 46143 | S16: 46174 | T16: 46204 | U16: 46235 | V16: 46266 | W16: 46296 | X16: 46327 | Y16: 46357 | AA16: 46388 | AB16: 46419 | AC16: 46447 | AD16: 46478 | AE16: 46508 | AF16: 46539 | AG16: 46569 | AH16: 46600 | AI16: 46631 | AJ16: 46661 | AK16: 46692 | AL16: 46722
E17: External | J17: =+SUMIF($F$24:$F$251,"External",$J$24:$J$251) -> 1542.9979 | K17: =+SUMIF($F$24:$F$251,"External",$K$24:$K$251) -> 1542.9979 | L17: =+SUMIF($F$24:$F$251,"External",$L$24:$L$251) -> 0 | N17: =+SUMIF($F$24:$F$251,"External",N$24:N$251) -> 526.5839 | O17: =+SUMIF($F$24:$F$251,"External",O$24:O$251) -> 281.674 | P17: =+SUMIF($F$24:$F$251,"External",P$24:P$251) -> 181.921 | Q17: =+SUMIF($F$24:$F$251,"External",Q$24:Q$251) -> 210.472 | R17: =+SUMIF($F$24:$F$251,"External",R$24:R$251) -> 0 | S17: =+SUMIF($F$24:$F$251,"External",S$24:S$251) -> 0 | T17: =+SUMIF($F$24:$F$251,"External",T$24:T$251) -> 0 | U17: =+SUMIF($F$24:$F$251,"External",U$24:U$251) -> 342.347 | ... Y17: =+SUMIF($F$24:$F$251,"External",Y$24:Y$251) -> 0 | AA17: =+SUMIF($F$24:$F$251,"External",AA$24:AA$251) -> 0 | AB17: =+SUMIF($F$24:$F$251,"External",AB$24:AB$251) -> 0 | AC17: =+SUMIF($F$24:$F$251,"External",AC$24:AC$251) -> 0 | AD17: =+SUMIF($F$24:$F$251,"External",AD$24:AD$251) -> 0 | AE17: =+SUMIF($F$24:$F$251,"External",AE$24:AE$251) -> 0 | AF17: =+SUMIF($F$24:$F$251,"External",AF$24:AF$251) -> 0 | AG17: =+SUMIF($F$24:$F$251,"External",AG$24:AG$251) -> 0 | AH17: =+SUMIF($F$24:$F$251,"External",AH$24:AH$251) -> 0 | ... AL17: =+SUMIF($F$24:$F$251,"External",AL$24:AL$251) -> 0
E18: Group | J18: =+SUMIF($F$24:$F$251,"Group",$J$24:$J$251) -> 8589.4 | K18: =+SUMIF($F$24:$F$251,"Group",$K$24:$K$251) -> 8589.4 | L18: =SUMIF($F$24:$F$251,"Group",$L$24:$L$251) -> 0 | N18: =+SUMIF($F$24:$F$251,"Group",N$24:N$251) -> 4032.5 | O18: =+SUMIF($F$24:$F$251,"Group",O$24:O$251) -> 1599.3 | P18: =+SUMIF($F$24:$F$251,"Group",P$24:P$251) -> 352.5 | Q18: =+SUMIF($F$24:$F$251,"Group",Q$24:Q$251) -> 373.1 | R18: =+SUMIF($F$24:$F$251,"Group",R$24:R$251) -> 73.5 | S18: =+SUMIF($F$24:$F$251,"Group",S$24:S$251) -> 393.5 | T18: =+SUMIF($F$24:$F$251,"Group",T$24:T$251) -> 322.5 | U18: =+SUMIF($F$24:$F$251,"Group",U$24:U$251) -> 1442.5 | ... Y18: =+SUMIF($F$24:$F$251,"Group",Y$24:Y$251) -> 0 | AA18: =+SUMIF($F$24:$F$251,"Group",AA$24:AA$251) -> 0 | AB18: =+SUMIF($F$24:$F$251,"Group",AB$24:AB$251) -> 0 | AC18: =+SUMIF($F$24:$F$251,"Group",AC$24:AC$251) -> 0 | AD18: =+SUMIF($F$24:$F$251,"Group",AD$24:AD$251) -> 0 | AE18: =+SUMIF($F$24:$F$251,"Group",AE$24:AE$251) -> 0 | AF18: =+SUMIF($F$24:$F$251,"Group",AF$24:AF$251) -> 0 | AG18: =+SUMIF($F$24:$F$251,"Group",AG$24:AG$251) -> 0 | AH18: =+SUMIF($F$24:$F$251,"Group",AH$24:AH$251) -> 0 | ... AL18: =+SUMIF($F$24:$F$251,"Group",AL$24:AL$251) -> 0
E19: TOTAL | J19: =SUM(J17:J18) -> 10132.398 | K19: =SUM(K17:K18) -> 10132.398 | L19: =SUM(L17:L18) -> 0 | N19: =SUM(N17:N18) -> 4559.0839 | O19: =SUM(O17:O18) -> 1880.974 | P19: =SUM(P17:P18) -> 534.421 | Q19: =SUM(Q17:Q18) -> 583.572 | R19: =SUM(R17:R18) -> 73.5 | S19: =SUM(S17:S18) -> 393.5 | T19: =SUM(T17:T18) -> 322.5 | U19: =SUM(U17:U18) -> 1784.847 | ... Y19: =SUM(Y17:Y18) -> 0 | AA19: =SUM(AA17:AA18) -> 0 | AB19: =SUM(AB17:AB18) -> 0 | AC19: =SUM(AC17:AC18) -> 0 | AD19: =SUM(AD17:AD18) -> 0 | AE19: =SUM(AE17:AE18) -> 0 | AF19: =SUM(AF17:AF18) -> 0 | AG19: =SUM(AG17:AG18) -> 0 | AH19: =SUM(AH17:AH18) -> 0 | ... AL19: =SUM(AL17:AL18) -> 0
I21: check | J21: =IF(SUM(J24:J251)=J19, "OK", "Please correct: the sum of orders below is not equal to the total calculated above. Make sure to pick External or Group for each order and don't change the formulas in columns K and L") -> OK | N21: 2026 | AA21: 2027
E23: Order (Tooling including) to be delivered | F23: External or Group | G23: Customers orders | H23: Quantity | I23: DGC | J23: TOTAL ORDERBOOK | K23: Total amount 2026 | L23: Total amount 2027 | N23: 46023 | O23: 46054 | P23: 46082 | Q23: 46113 | R23: 46143 | S23: 46174 | T23: 46204 | U23: 46235 | V23: 46266 | W23: 46296 | X23: 46327 | Y23: 46357 | AA23: 46388 | AB23: 46419 | AC23: 46447 | AD23: 46478 | AE23: 46508 | AF23: 46539 | AG23: 46569 | AH23: 46600 | AI23: 46631 | AJ23: 46661 | AK23: 46692 | AL23: 46722
D24: X | E24: DEHK | F24: Group | G24: DEHK HK | I24: G | J24: =+K24+L24 -> 8489.4 | K24: =SUM(N24:Y24) -> 8489.4 | L24: =SUM(AA24:AL24) -> 0 | N24: 3994.5 | O24: 1588.3 | P24: 346.5 | Q24: 373.1 | R24: 73.5 | S24: 348.5 | T24: 322.5 | U24: 1442.5
E25: DIAM Singapore | F25: Group | G25: DIAM SINGAPORE | I25: G | J25: =+K25+L25 -> 100 | K25: =SUM(N25:Y25) -> 100 | L25: =SUM(AA25:AL25) -> 0 | N25: 38 | O25: =1+10 -> 11 | P25: 6 | S25: =55-10 -> 45
E26: Sephora | F26: External | G26: SEPHORA | I26: E | J26: =+K26+L26 -> 306.69 | K26: =SUM(N26:Y26) -> 306.69 | L26: =SUM(AA26:AL26) -> 0 | O26: =230.438-2.764-58 -> 169.674 | Q26: =79.016+58 -> 137.016
E27: Burberry/Gucci/Lancaster | F27: External | G27: Coty | I27: E | J27: =+K27+L27 -> 141.957 | K27: =SUM(N27:Y27) -> 141.957 | L27: =SUM(AA27:AL27) -> 0 | N27: 36.957 | O27: 105
E28: Fenty | F28: External | G28: FENTY | I28: E | J28: =+K28+L28 -> 2.793 | K28: =SUM(N28:Y28) -> 2.793 | L28: =SUM(AA28:AL28) -> 0 | N28: =6.708-6.415+2.5 -> 2.793
E29: Herbeast/Komfymed/Chaling | F29: External | G29: SEPHORA-Exclusive brands | I29: E | J29: =+K29+L29 -> 8.123 | K29: =SUM(N29:Y29) -> 8.123 | L29: =SUM(AA29:AL29) -> 0 | N29: =5.366-0.513-0.24-1.49 -> 3.123 | P29: 5
E30: Benefit/Fresh/Guerlain/Kenzo/Givenchy | F30: External | G30: LVMH | I30: E | J30: =+K30+L30 -> 153.9259 | K30: =SUM(N30:Y30) -> 153.9259 | L30: =SUM(AA30:AL30) -> 0 | N30: =57.9259+22 -> 79.9259 | P30: =36-23 -> 13 | Q30: =60-22+23 -> 61
E31: ETERNAL( Laura Mercier) | F31: External | G31: ETERNAL | I31: E | J31: =+K31+L31 -> 6.251 | K31: =SUM(N31:Y31) -> 6.251 | L31: =SUM(AA31:AL31) -> 0 | N31: 2.251 | O31: 4
E32: Perfect Diary | F32: External | G32: Perfect Diary | I32: E | J32: =+K32+L32 -> 14.456 | K32: =SUM(N32:Y32) -> 14.456 | L32: =SUM(AA32:AL32) -> 0 | N32: 2 | Q32: 12.456
E33: Clinique/BB/MAC/Estee Lauder | F33: External | G33: Estee Lauder | I33: E | J33: =+K33+L33 -> 10.75 | K33: =SUM(N33:Y33) -> 10.75 | L33: =SUM(AA33:AL33) -> 0 | N33: =5.75+1+1 -> 7.75 | O33: 3
E34: Hourglass | F34: External | G34: Hourglass | I34: E | J34: =+K34+L34 -> 342.347 | K34: =SUM(N34:Y34) -> 342.347 | L34: =SUM(AA34:AL34) -> 0 | U34: =360-17.653 -> 342.347
E35: ARMANI | F35: External | G35: ARMANI | I35: G | J35: =+K35+L35 -> 9.921 | K35: =SUM(N35:Y35) -> 9.921 | L35: =SUM(AA35:AL35) -> 0 | P35: 9.921
E36: Galenic | F36: External | G36: Galenic | I36: E | J36: =+K36+L36 -> 28 | K36: =SUM(N36:Y36) -> 28 | L36: =SUM(AA36:AL36) -> 0 | P36: =23+5 -> 28
E37: YAMEI(Trading) | F37: External | G37: YAMEI(Trading) | I37: E | J37: =+K37+L37 -> 170 | K37: =SUM(N37:Y37) -> 170 | L37: =SUM(AA37:AL37) -> 0 | N37: 170
E38: L‘oreal | F38: External | G38: L‘oreal(PACK) | I38: E | J38: =+K38+L38 -> 347.784 | K38: =SUM(N38:Y38) -> 347.784 | L38: =SUM(AA38:AL38) -> 0 | N38: 221.784 | P38: 126
J39: =+K39+L39 -> 0 | K39: =SUM(N39:Y39) -> 0 | L39: =SUM(AA39:AL39) -> 0
J40: =+K40+L40 -> 0 | K40: =SUM(N40:Y40) -> 0 | L40: =SUM(AA40:AL40) -> 0
J41: =+K41+L41 -> 0 | K41: =SUM(N41:Y41) -> 0 | L41: =SUM(AA41:AL41) -> 0
J42: =+K42+L42 -> 0 | K42: =SUM(N42:Y42) -> 0 | L42: =SUM(AA42:AL42) -> 0
J43: =+K43+L43 -> 0 | K43: =SUM(N43:Y43) -> 0 | L43: =SUM(AA43:AL43) -> 0
J44: =+K44+L44 -> 0 | K44: =SUM(N44:Y44) -> 0 | L44: =SUM(AA44:AL44) -> 0
J45: =+K45+L45 -> 0 | K45: =SUM(N45:Y45) -> 0 | L45: =SUM(AA45:AL45) -> 0
J46: =+K46+L46 -> 0 | K46: =SUM(N46:Y46) -> 0 | L46: =SUM(AA46:AL46) -> 0
J47: =+K47+L47 -> 0 | K47: =SUM(N47:Y47) -> 0 | L47: =SUM(AA47:AL47) -> 0
J48: =+K48+L48 -> 0 | K48: =SUM(N48:Y48) -> 0 | L48: =SUM(AA48:AL48) -> 0
J49: =+K49+L49 -> 0 | K49: =SUM(N49:Y49) -> 0 | L49: =SUM(AA49:AL49) -> 0
...

Sheet W4
E2: ENTITY NAME : | G2: =+parameters!D2 -> Diam CHINA | I2: ORDER BOOK SYNTHESIS in K€
E4: WEEK : | G4: W4 | I4: Cells to be filled in
E6: MONTH : | G6: =+VLOOKUP(G4, parameters!G:H, 2, 0) -> January
E8: TURNOVER | F8: =parameters!D4 -> k€ | H8: YTD Turnover | J8: =+G6&" Turnover" -> January Turnover | L8: Last estim. for the month: | O8: Forecast 2026
H9: =+"from January 1 until end of "&G4 -> from January 1 until end of W4 | J9: =+"from "&G6&" 1 until end of "&G4 -> from January 1 until end of W4 | L9: =+G6 -> January | O9: =+G4 -> W4 | P9: =+VLOOKUP(G4, parameters!$G$9:$I$61,3,0) -> W3 | Q9: Var
E10: EXTERNAL SALES INVOICED (=outside group) | H10: =J10 -> 901.239 | J10: =0+42.329+858.91 -> 901.239 | L10: =J10+N17 -> 1169.9219 | O10: =+H10+K17 -> 2075.4579 | P10: {=INDIRECT(ADDRESS(10,15,,,VLOOKUP($G$4,parameters!$G:$I,3,0)))} -> 1585.3269 | Q10: =O10-P10 -> 490.131
E11: GROUP SALES INVOICED | H11: =J11 -> 1643.156 | J11: =0+93.912+182.874+1363.965+2.405 -> 1643.156 | L11: =J11+N18 -> 4657.656 | O11: =+H11+K18 -> 9260.051 | P11: {=INDIRECT(ADDRESS(11,15,,,VLOOKUP($G$4,parameters!$G:$I,3,0)))} -> 8866.186 | Q11: =O11-P11 -> 393.865 | S11: Definition orders : you consider the orders which are sure even if the order customers paper order is not yet received
E12: TOTAL | H12: =SUM(H10:H11) -> 2544.395 | J12: =SUM(J10:J11) -> 2544.395 | L12: =SUM(L10:L11) -> 5827.5779 | O12: =SUM(O10:O11) -> 11335.509 | P12: =SUM(P10:P11) -> 10451.513 | Q12: =O12-P12 -> 883.996 | S12: The quantity, value, and delivery date can be changed before final delivery
E16: ORDERBOOK | F16: =+F8 -> k€ | J16: TOTAL ORDERBOOK | K16: Total amount 2026 | L16: Total amount 2027 | N16: 46023 | O16: 46054 | P16: 46082 | Q16: 46113 | R16: 46143 | S16: 46174 | T16: 46204 | U16: 46235 | V16: 46266 | W16: 46296 | X16: 46327 | Y16: 46357 | AA16: 46388 | AB16: 46419 | AC16: 46447 | AD16: 46478 | AE16: 46508 | AF16: 46539 | AG16: 46569 | AH16: 46600 | AI16: 46631 | AJ16: 46661 | AK16: 46692 | AL16: 46722
E17: External | J17: =+SUMIF($F$24:$F$250,"External",$J$24:$J$250) -> 1174.2189 | K17: =+SUMIF($F$24:$F$250,"External",$K$24:$K$250) -> 1174.2189 | L17: =+SUMIF($F$24:$F$250,"External",$L$24:$L$250) -> 0 | N17: =+SUMIF($F$24:$F$250,"External",N$24:N$250) -> 268.6829 | O17: =+SUMIF($F$24:$F$250,"External",O$24:O$250) -> 157.294 | P17: =+SUMIF($F$24:$F$250,"External",P$24:P$250) -> 190.423 | Q17: =+SUMIF($F$24:$F$250,"External",Q$24:Q$250) -> 210.472 | R17: =+SUMIF($F$24:$F$250,"External",R$24:R$250) -> 339 | S17: =+SUMIF($F$24:$F$250,"External",S$24:S$250) -> 0 | T17: =+SUMIF($F$24:$F$250,"External",T$24:T$250) -> 0 | U17: =+SUMIF($F$24:$F$250,"External",U$24:U$250) -> 8.347 | ... Y17: =+SUMIF($F$24:$F$250,"External",Y$24:Y$250) -> 0 | AA17: =+SUMIF($F$24:$F$250,"External",AA$24:AA$250) -> 0 | AB17: =+SUMIF($F$24:$F$250,"External",AB$24:AB$250) -> 0 | AC17: =+SUMIF($F$24:$F$250,"External",AC$24:AC$250) -> 0 | AD17: =+SUMIF($F$24:$F$250,"External",AD$24:AD$250) -> 0 | AE17: =+SUMIF($F$24:$F$250,"External",AE$24:AE$250) -> 0 | AF17: =+SUMIF($F$24:$F$250,"External",AF$24:AF$250) -> 0 | AG17: =+SUMIF($F$24:$F$250,"External",AG$24:AG$250) -> 0 | AH17: =+SUMIF($F$24:$F$250,"External",AH$24:AH$250) -> 0 | ... AL17: =+SUMIF($F$24:$F$250,"External",AL$24:AL$250) -> 0
E18: Group | J18: =+SUMIF($F$24:$F$250,"Group",$J$24:$J$250) -> 7616.895 | K18: =+SUMIF($F$24:$F$250,"Group",$K$24:$K$250) -> 7616.895 | L18: =SUMIF($F$24:$F$250,"Group",$L$24:$L$250) -> 0 | N18: =+SUMIF($F$24:$F$250,"Group",N$24:N$250) -> 3014.5 | O18: =+SUMIF($F$24:$F$250,"Group",O$24:O$250) -> 1399.5 | P18: =+SUMIF($F$24:$F$250,"Group",P$24:P$250) -> 906.2 | Q18: =+SUMIF($F$24:$F$250,"Group",Q$24:Q$250) -> 330.4 | R18: =+SUMIF($F$24:$F$250,"Group",R$24:R$250) -> 564.2 | S18: =+SUMIF($F$24:$F$250,"Group",S$24:S$250) -> 343.695 | T18: =+SUMIF($F$24:$F$250,"Group",T$24:T$250) -> 0 | U18: =+SUMIF($F$24:$F$250,"Group",U$24:U$250) -> 1058.4 | ... Y18: =+SUMIF($F$24:$F$250,"Group",Y$24:Y$250) -> 0 | AA18: =+SUMIF($F$24:$F$250,"Group",AA$24:AA$250) -> 0 | AB18: =+SUMIF($F$24:$F$250,"Group",AB$24:AB$250) -> 0 | AC18: =+SUMIF($F$24:$F$250,"Group",AC$24:AC$250) -> 0 | AD18: =+SUMIF($F$24:$F$250,"Group",AD$24:AD$250) -> 0 | AE18: =+SUMIF($F$24:$F$250,"Group",AE$24:AE$250) -> 0 | AF18: =+SUMIF($F$24:$F$250,"Group",AF$24:AF$250) -> 0 | AG18: =+SUMIF($F$24:$F$250,"Group",AG$24:AG$250) -> 0 | AH18: =+SUMIF($F$24:$F$250,"Group",AH$24:AH$250) -> 0 | ... AL18: =+SUMIF($F$24:$F$250,"Group",AL$24:AL$250) -> 0
E19: TOTAL | J19: =SUM(J17:J18) -> 8791.1139 | K19: =SUM(K17:K18) -> 8791.1139 | L19: =SUM(L17:L18) -> 0 | N19: =SUM(N17:N18) -> 3283.1829 | O19: =SUM(O17:O18) -> 1556.794 | P19: =SUM(P17:P18) -> 1096.623 | Q19: =SUM(Q17:Q18) -> 540.872 | R19: =SUM(R17:R18) -> 903.2 | S19: =SUM(S17:S18) -> 343.695 | T19: =SUM(T17:T18) -> 0 | U19: =SUM(U17:U18) -> 1066.747 | ... Y19: =SUM(Y17:Y18) -> 0 | AA19: =SUM(AA17:AA18) -> 0 | AB19: =SUM(AB17:AB18) -> 0 | AC19: =SUM(AC17:AC18) -> 0 | AD19: =SUM(AD17:AD18) -> 0 | AE19: =SUM(AE17:AE18) -> 0 | AF19: =SUM(AF17:AF18) -> 0 | AG19: =SUM(AG17:AG18) -> 0 | AH19: =SUM(AH17:AH18) -> 0 | ... AL19: =SUM(AL17:AL18) -> 0
I21: check | J21: =IF(SUM(J24:J250)=J19, "OK", "Please correct: the sum of orders below is not equal to the total calculated above. Make sure to pick External or Group for each order and don't change the formulas in columns K and L") -> OK | N21: 2026 | AA21: 2027
E23: Order (Tooling including) to be delivered | F23: External or Group | G23: Customers orders | H23: Quantity | I23: DGC | J23: TOTAL ORDERBOOK | K23: Total amount 2026 | L23: Total amount 2027 | N23: 46023 | O23: 46054 | P23: 46082 | Q23: 46113 | R23: 46143 | S23: 46174 | T23: 46204 | U23: 46235 | V23: 46266 | W23: 46296 | X23: 46327 | Y23: 46357 | AA23: 46388 | AB23: 46419 | AC23: 46447 | AD23: 46478 | AE23: 46508 | AF23: 46539 | AG23: 46569 | AH23: 46600 | AI23: 46631 | AJ23: 46661 | AK23: 46692 | AL23: 46722
