Workbook
Name Liste: parameters!$A$2:$A$3
Name liste1: #REF!
Name liste2: #REF!
Name SOCIETE: parameters!$A$8:$A$55

Sheet read me
B1: INSTRUCTIONS FOR USE
B3: The aim of this document is to follow the orderbook per week.
B5: This document has to be sent each Friday afternoon to : | H5: dashboard@diaminter.com
B11: How to fill in the document :
C13: 1 | D13: Select the worksheet for the appropriate week
C15: 2 | D15: Fill in your company name in the cell G2
C17: 3 | D17: The current month corresponding to the week is automatically mentionned: please make sure to report data for this month (and not previous or next one when the week runs over two different months)
C19: 4 | D19: Column E : Fill in product name
C21: 5 | D21: Column F : Fill in customers statut (external or internal customers)
C23: 6 | D23: Column G : fill in the customers name
C25: 7 | D25: Please never correct the worksheet of a past week
C27: 8 | D27: You can update the pivot tables on the worksheet [analysis week] to see the detailed variations by customers in the orderbook from previous week to ongoing week
C29: 9 | D29: This is a synthesis of the orders taken and the sales invoiced during the year. Please update the YTD figures at the end of each months (yellow cells) to show the
B33: IMPORTANT : At the end of the month, orders not yet delivered, have to be automatically transferred to the next month.
D34: Once the orders have been invoiced (and so the amount is indicated as turnover), the orders should disappear of the table.

Sheet parameters
D1: Entity to select
A2: Group | D2: DE HONG KONG
A3: External
D4: =VLOOKUP(D2,$A$8:$C$52,3,FALSE) -> k€
A8: TO SELECT | B8: Automatic data
A9: Diam France | B9: DFR | C9: k€ | G9: W1 | H9: January | J9: January | K9: 46023
A10: Diam Lurcy | B10: DLU | C10: k€ | G10: W2 | H10: January | I10: W1 | J10: February | K10: 46054
A11: Diam Yzeure | B11: DYZ | C11: k€ | G11: W3 | H11: January | I11: W2 | J11: March | K11: 46082
A12: Diam Tunisie | B12: DTN | C12: k€ | G12: W4 | H12: January | I12: W3 | J12: April | K12: 46113
A13: Diam Tunisie Prestige | B13: DTP | C13: k€ | G13: W5 | H13: January | I13: W4 | J13: May | K13: 46143
A14: Diam Turkey | B14: DTK | C14: k€ | G14: W6 | H14: February | I14: W5 | J14: June | K14: 46174
A15: Diam Italy | B15: DIT | C15: k€ | G15: W7 | H15: February | I15: W6 | J15: July | K15: 46204
A16: Diam Prestige Europe | B16: PEM | C16: k€ | G16: W8 | H16: February | I16: W7 | J16: August | K16: 46235
A17: Diam UK | B17: DUK | C17: k£ | G17: W9 | H17: February | I17: W8 | J17: September | K17: 46266
A18: Fieldflex UK | B18: FFUK | C18: k£ | G18: W10 | H18: March | I18: W9 | J18: October | K18: 46296
A19: Diam Germany | B19: DEU | C19: k€ | G19: W11 | H19: March | I19: W10 | J19: November | K19: 46327
A20: Diam Poland | B20: DPO | C20: k€ | G20: W12 | H20: March | I20: W11 | J20: December | K20: 46357
A21: Diam Premium North America | B21: DPN | C21: k$ | G21: W13 | H21: March | I21: W12
A22: D 3 LLC | B22: D3 | C22: k$ | G22: W14 | H22: April | I22: W13
A23: CONEX US | B23: CNX | C23: k$ | G23: W15 | H23: April | I23: W14
A24: CONEX EU | B24: CNE | C24: k€ | G24: W16 | H24: April | I24: W15
A25: CONEX APAC | B25: CNA | C25: k$ | G25: W17 | H25: April | I25: W16
A26: PRUGENT US | B26: PUS | C26: k$ | G26: W18 | H26: April | I26: W17
A27: Fieldflex US | B27: FFUS | C27: k$ | G27: W19 | H27: May | I27: W18
A28: Back to Diam | B28: B2D | C28: k$ | G28: W20 | H28: May | I28: W19
A29: Diam Mexico | B29: DMX | C29: k$ | G29: W21 | H29: May | I29: W20
A30: Diam Brazil | B30: DBR | C30: k€ | G30: W22 | H30: May | I30: W21
A31: Diam CHINA | B31: DDC | C31: k€ | G31: W23 | H31: June | I31: W22
A32: DE HONG KONG | B32: DEHK | C32: k€ | G32: W24 | H32: June | I32: W23
... A52: RETAIL 3D | B52: R3D | C52: k€ | G52: W44 | H52: October | I52: W43
G53: W45 | H53: November | I53: W44
G54: W46 | H54: November | I54: W45
G55: W47 | H55: November | I55: W46
G56: W48 | H56: November | I56: W47
G57: W49 | H57: December | I57: W48
G58: W50 | H58: December | I58: W49
G59: W51 | H59: December | I59: W50
G60: W52 | H60: December | I60: W51
G61: W53 | H61: December | I61: W52

Sheet analysis week
B2: Entity | C2: =+'W1'!G2 -> DE HONG KONG | D2: =VLOOKUP(C2, parameters!A:B, 2,0) -> DEHK
B4: Week | C4: W2 | D4: =VLOOKUP(C4, parameters!G:I,3,0) -> W1
B7: Var 2026 | H7: Var 2027
C9: External | D9: Group | E9: Total | I9: External | J9: Group | K9: Total
B10: ="Var in sales 2025 - "&D4&" to "&C4 -> Var in sales 2025 - W1 to W2 | C10: =+C16-C22 -> 65.798 | D10: =+D16-D22 -> 68.362 | E10: =+E16-E22 -> 134.16 | H10: =+"Orderbook "&$C$4 -> Orderbook W2 | I10: {=INDIRECT(ADDRESS(17,12,,,$C$4))} -> 0 | J10: {=INDIRECT(ADDRESS(18,12,,,$C$4))} -> 0 | K10: =SUM(I10:J10) -> 0
B11: ="Var in orderbook 2025 - "&D4&" to "&C4 -> Var in orderbook 2025 - W1 to W2 | C11: =+C17-C23 -> 131.202 | D11: =+D17-D23 -> 133.301 | E11: =+E17-E23 -> 264.503 | H11: =+"Orderbook "&$D$4 -> Orderbook W1 | I11: {=INDIRECT(ADDRESS(17,12,,,$D$4))} -> 0 | J11: {=INDIRECT(ADDRESS(18,12,,,$D$4))} -> 0 | K11: =SUM(I11:J11) -> 0
B12: ="Var in forecast 2025 - "&D4&" to "&C4 -> Var in forecast 2025 - W1 to W2 | C12: =+C18-C24 -> 197 | D12: =+D18-D24 -> 201.663 | E12: =+E18-E24 -> 398.663 | H12: ="Var in orderbook - "&D4&" to "&C4 -> Var in orderbook - W1 to W2 | I12: =+I10-I11 -> 0 | J12: =+J10-J11 -> 0 | K12: =+K10-K11 -> 0
C13: =+C12-SUM(C10:C11) -> -2.2737368e-13 | D13: =+D12-SUM(D10:D11) -> 0 | E13: =+E12-SUM(E10:E11) -> 0
C15: External | D15: Group | E15: Total | H15: Somme de 2027 | I15: Étiquettes de colonnes
B16: =+"Sales "&$C$4 -> Sales W2 | C16: {=INDIRECT(ADDRESS(10,8,,,$C$4))} -> 65.798 | D16: {=INDIRECT(ADDRESS(11,8,,,$C$4))} -> 68.362 | E16: =SUM(C16:D16) -> 134.16 | H16: Étiquettes de lignes | I16: W2 | J16: W1 | K16: Var
B17: =+"Orderbook "&$C$4 -> Orderbook W2 | C17: {=INDIRECT(ADDRESS(17,11,,,$C$4))} -> 7404.08 | D17: {=INDIRECT(ADDRESS(18,11,,,$C$4))} -> 4795.099 | E17: =SUM(C17:D17) -> 12199.179 | H17: 0 | I17: 0 | J17: 0 | K17: =+I17-J17 -> 0
B18: =+"Forecast "&$C$4 -> Forecast W2 | C18: =SUM(C16:C17) -> 7469.878 | D18: =SUM(D16:D17) -> 4863.461 | E18: =SUM(E16:E17) -> 12333.339 | H18: Total général | I18: 0 | J18: 0 | K18: =+I18-J18 -> 0
K19: =+I19-J19 -> 0
K20: =+I20-J20 -> 0
C21: External | D21: Group | E21: Total | K21: =+I21-J21 -> 0
B22: =+"Sales "&$D$4 -> Sales W1 | C22: {=INDIRECT(ADDRESS(10,8,,,$D$4))} -> 0 | D22: {=INDIRECT(ADDRESS(11,8,,,$D$4))} -> 0 | E22: =SUM(C22:D22) -> 0 | K22: =+I22-J22 -> 0
B23: =+"Orderbook "&$D$4 -> Orderbook W1 | C23: {=INDIRECT(ADDRESS(17,11,,,$D$4))} -> 7272.878 | D23: {=INDIRECT(ADDRESS(18,11,,,$D$4))} -> 4661.798 | E23: =SUM(C23:D23) -> 11934.676 | K23: =+I23-J23 -> 0
B24: =+"Forecast "&$D$4 -> Forecast W1 | C24: =SUM(C22:C23) -> 7272.878 | D24: =SUM(D22:D23) -> 4661.798 | E24: =SUM(E22:E23) -> 11934.676 | K24: =+I24-J24 -> 0
K25: =+I25-J25 -> 0
K26: =+I26-J26 -> 0
B27: Somme de 2026 | C27: Étiquettes de colonnes | K27: =+I27-J27 -> 0
B28: Étiquettes de lignes | C28: W2 | D28: W1 | E28: Var | K28: =+I28-J28 -> 0
B29: 0 | C29: 0 | D29: 0 | E29: =+C29-D29 -> 0 | K29: =+I29-J29 -> 0
B30: Total général | C30: 0 | D30: 0 | E30: =+C30-D30 -> 0 | K30: =+I30-J30 -> 0
E31: =+C31-D31 -> 0 | K31: =+I31-J31 -> 0
E32: =+C32-D32 -> 0 | K32: =+I32-J32 -> 0
E33: =+C33-D33 -> 0 | K33: =+I33-J33 -> 0
E34: =+C34-D34 -> 0 | K34: =+I34-J34 -> 0
E35: =+C35-D35 -> 0 | K35: =+I35-J35 -> 0
E36: =+C36-D36 -> 0 | K36: =+I36-J36 -> 0
E37: =+C37-D37 -> 0 | K37: =+I37-J37 -> 0
E38: =+C38-D38 -> 0 | K38: =+I38-J38 -> 0
E39: =+C39-D39 -> 0 | K39: =+I39-J39 -> 0
E40: =+C40-D40 -> 0 | K40: =+I40-J40 -> 0
E41: =+C41-D41 -> 0 | K41: =+I41-J41 -> 0
E42: =+C42-D42 -> 0 | K42: =+I42-J42 -> 0
... E93: =+C93-D93 -> 0 | K93: =+I93-J93 -> 0
E94: =+C94-D94 -> 0
E95: =+C95-D95 -> 0
E96: =+C96-D96 -> 0
...

Sheet DB analysis orders
C2: Week | D2: =+'analysis week'!C4 -> W2 | E2: =+'analysis week'!D4 -> W1
C4: 5 | D4: =+C4+1 -> 6 | E4: =+D4+1 -> 7 | F4: =+E4+1 -> 8 | G4: =+F4+1 -> 9 | H4: =+G4+1 -> 10 | I4: =+H4+1 -> 11 | J4: =+I4+1 -> 12
B5: Week | C5: Order to be delivered | D5: External or Group | E5: Customers orders | F5: Quantity | G5: DGC | H5: TOTAL ORDERBOOK | I5: 2026 | J5: 2027
A6: =+INDEX(MATCH("X", 'W1'!D:D,0),,) -> 24 | B6: =+$D$2 -> W2 | C6: {=INDIRECT(ADDRESS($A6,C$4,,,$B6))} -> D3 | D6: {=INDIRECT(ADDRESS($A6,D$4,,,$B6))} -> Group | E6: {=INDIRECT(ADDRESS($A6,E$4,,,$B6))} -> D3 | F6: {=INDIRECT(ADDRESS($A6,F$4,,,$B6))} -> 0 | G6: {=INDIRECT(ADDRESS($A6,G$4,,,$B6))} -> G | H6: {=INDIRECT(ADDRESS($A6,H$4,,,$B6))} -> 3331.75 | I6: {=INDIRECT(ADDRESS($A6,I$4,,,$B6))} -> 3331.75 | J6: {=INDIRECT(ADDRESS($A6,J$4,,,$B6))} -> 0
A7: =+A6+1 -> 25 | B7: =+$D$2 -> W2 | C7: {=INDIRECT(ADDRESS($A7,C$4,,,$B7))} -> Diam France | D7: {=INDIRECT(ADDRESS($A7,D$4,,,$B7))} -> Group | E7: {=INDIRECT(ADDRESS($A7,E$4,,,$B7))} -> Diam France | F7: {=INDIRECT(ADDRESS($A7,F$4,,,$B7))} -> 0 | G7: {=INDIRECT(ADDRESS($A7,G$4,,,$B7))} -> G | H7: {=INDIRECT(ADDRESS($A7,H$4,,,$B7))} -> 16.781 | I7: {=INDIRECT(ADDRESS($A7,I$4,,,$B7))} -> 16.781 | J7: {=INDIRECT(ADDRESS($A7,J$4,,,$B7))} -> 0
A8: =+A7+1 -> 26 | B8: =+$D$2 -> W2 | C8: {=INDIRECT(ADDRESS($A8,C$4,,,$B8))} -> DIAM Turkey | D8: {=INDIRECT(ADDRESS($A8,D$4,,,$B8))} -> Group | E8: {=INDIRECT(ADDRESS($A8,E$4,,,$B8))} -> DIAM Turkey | F8: {=INDIRECT(ADDRESS($A8,F$4,,,$B8))} -> 0 | G8: {=INDIRECT(ADDRESS($A8,G$4,,,$B8))} -> G | H8: {=INDIRECT(ADDRESS($A8,H$4,,,$B8))} -> 166.23 | I8: {=INDIRECT(ADDRESS($A8,I$4,,,$B8))} -> 166.23 | J8: {=INDIRECT(ADDRESS($A8,J$4,,,$B8))} -> 0
A9: =+A8+1 -> 27 | B9: =+$D$2 -> W2 | C9: {=INDIRECT(ADDRESS($A9,C$4,,,$B9))} -> Nevacril | D9: {=INDIRECT(ADDRESS($A9,D$4,,,$B9))} -> Group | E9: {=INDIRECT(ADDRESS($A9,E$4,,,$B9))} -> Nevacril | F9: {=INDIRECT(ADDRESS($A9,F$4,,,$B9))} -> 0 | G9: {=INDIRECT(ADDRESS($A9,G$4,,,$B9))} -> G | H9: {=INDIRECT(ADDRESS($A9,H$4,,,$B9))} -> 3.259 | I9: {=INDIRECT(ADDRESS($A9,I$4,,,$B9))} -> 3.259 | J9: {=INDIRECT(ADDRESS($A9,J$4,,,$B9))} -> 0
A10: =+A9+1 -> 28 | B10: =+$D$2 -> W2 | C10: {=INDIRECT(ADDRESS($A10,C$4,,,$B10))} -> Diam UK | D10: {=INDIRECT(ADDRESS($A10,D$4,,,$B10))} -> Group | E10: {=INDIRECT(ADDRESS($A10,E$4,,,$B10))} -> Diam UK | F10: {=INDIRECT(ADDRESS($A10,F$4,,,$B10))} -> 0 | G10: {=INDIRECT(ADDRESS($A10,G$4,,,$B10))} -> G | H10: {=INDIRECT(ADDRESS($A10,H$4,,,$B10))} -> 191 | I10: {=INDIRECT(ADDRESS($A10,I$4,,,$B10))} -> 191 | J10: {=INDIRECT(ADDRESS($A10,J$4,,,$B10))} -> 0
A11: =+A10+1 -> 29 | B11: =+$D$2 -> W2 | C11: {=INDIRECT(ADDRESS($A11,C$4,,,$B11))} -> DIAM PORTUGAL | D11: {=INDIRECT(ADDRESS($A11,D$4,,,$B11))} -> Group | E11: {=INDIRECT(ADDRESS($A11,E$4,,,$B11))} -> DIAM PORTUGAL | F11: {=INDIRECT(ADDRESS($A11,F$4,,,$B11))} -> 0 | G11: {=INDIRECT(ADDRESS($A11,G$4,,,$B11))} -> G | H11: {=INDIRECT(ADDRESS($A11,H$4,,,$B11))} -> 3.5 | I11: {=INDIRECT(ADDRESS($A11,I$4,,,$B11))} -> 3.5 | J11: {=INDIRECT(ADDRESS($A11,J$4,,,$B11))} -> 0
A12: =+A11+1 -> 30 | B12: =+$D$2 -> W2 | C12: {=INDIRECT(ADDRESS($A12,C$4,,,$B12))} -> DIAM PRESTIGE EUROPE | D12: {=INDIRECT(ADDRESS($A12,D$4,,,$B12))} -> Group | E12: {=INDIRECT(ADDRESS($A12,E$4,,,$B12))} -> DIAM PRESTIGE EUROPE | F12: {=INDIRECT(ADDRESS($A12,F$4,,,$B12))} -> 0 | G12: {=INDIRECT(ADDRESS($A12,G$4,,,$B12))} -> G | H12: {=INDIRECT(ADDRESS($A12,H$4,,,$B12))} -> 153.294 | I12: {=INDIRECT(ADDRESS($A12,I$4,,,$B12))} -> 153.294 | J12: {=INDIRECT(ADDRESS($A12,J$4,,,$B12))} -> 0
A13: =+A12+1 -> 31 | B13: =+$D$2 -> W2 | C13: {=INDIRECT(ADDRESS($A13,C$4,,,$B13))} -> PRUGENT DIAM EUROPE | D13: {=INDIRECT(ADDRESS($A13,D$4,,,$B13))} -> Group | E13: {=INDIRECT(ADDRESS($A13,E$4,,,$B13))} -> PRUGENT DIAM EUROPE | F13: {=INDIRECT(ADDRESS($A13,F$4,,,$B13))} -> 0 | G13: {=INDIRECT(ADDRESS($A13,G$4,,,$B13))} -> G | H13: {=INDIRECT(ADDRESS($A13,H$4,,,$B13))} -> 1.443 | I13: {=INDIRECT(ADDRESS($A13,I$4,,,$B13))} -> 1.443 | J13: {=INDIRECT(ADDRESS($A13,J$4,,,$B13))} -> 0
A14: =+A13+1 -> 32 | B14: =+$D$2 -> W2 | C14: {=INDIRECT(ADDRESS($A14,C$4,,,$B14))} -> Diam Japan | D14: {=INDIRECT(ADDRESS($A14,D$4,,,$B14))} -> Group | E14: {=INDIRECT(ADDRESS($A14,E$4,,,$B14))} -> Diam Japan(L) | F14: {=INDIRECT(ADDRESS($A14,F$4,,,$B14))} -> 0 | G14: {=INDIRECT(ADDRESS($A14,G$4,,,$B14))} -> G | H14: {=INDIRECT(ADDRESS($A14,H$4,,,$B14))} -> 412.895 | I14: {=INDIRECT(ADDRESS($A14,I$4,,,$B14))} -> 412.895 | J14: {=INDIRECT(ADDRESS($A14,J$4,,,$B14))} -> 0
A15: =+A14+1 -> 33 | B15: =+$D$2 -> W2 | C15: {=INDIRECT(ADDRESS($A15,C$4,,,$B15))} -> Diam Japan | D15: {=INDIRECT(ADDRESS($A15,D$4,,,$B15))} -> Group | E15: {=INDIRECT(ADDRESS($A15,E$4,,,$B15))} -> Diam Japan(PACK) | F15: {=INDIRECT(ADDRESS($A15,F$4,,,$B15))} -> 0 | G15: {=INDIRECT(ADDRESS($A15,G$4,,,$B15))} -> G | H15: {=INDIRECT(ADDRESS($A15,H$4,,,$B15))} -> 254.566 | I15: {=INDIRECT(ADDRESS($A15,I$4,,,$B15))} -> 254.566 | J15: {=INDIRECT(ADDRESS($A15,J$4,,,$B15))} -> 0
A16: =+A15+1 -> 34 | B16: =+$D$2 -> W2 | C16: {=INDIRECT(ADDRESS($A16,C$4,,,$B16))} -> DDA | D16: {=INDIRECT(ADDRESS($A16,D$4,,,$B16))} -> Group | E16: {=INDIRECT(ADDRESS($A16,E$4,,,$B16))} -> DDA(PACK) | F16: {=INDIRECT(ADDRESS($A16,F$4,,,$B16))} -> 0 | G16: {=INDIRECT(ADDRESS($A16,G$4,,,$B16))} -> G | H16: {=INDIRECT(ADDRESS($A16,H$4,,,$B16))} -> 10 | I16: {=INDIRECT(ADDRESS($A16,I$4,,,$B16))} -> 10 | J16: {=INDIRECT(ADDRESS($A16,J$4,,,$B16))} -> 0
A17: =+A16+1 -> 35 | B17: =+$D$2 -> W2 | C17: {=INDIRECT(ADDRESS($A17,C$4,,,$B17))} -> D3 | D17: {=INDIRECT(ADDRESS($A17,D$4,,,$B17))} -> Group | E17: {=INDIRECT(ADDRESS($A17,E$4,,,$B17))} -> D3(PACK) | F17: {=INDIRECT(ADDRESS($A17,F$4,,,$B17))} -> 0 | G17: {=INDIRECT(ADDRESS($A17,G$4,,,$B17))} -> G | H17: {=INDIRECT(ADDRESS($A17,H$4,,,$B17))} -> 34.496 | I17: {=INDIRECT(ADDRESS($A17,I$4,,,$B17))} -> 34.496 | J17: {=INDIRECT(ADDRESS($A17,J$4,,,$B17))} -> 0
A18: =+A17+1 -> 36 | B18: =+$D$2 -> W2 | C18: {=INDIRECT(ADDRESS($A18,C$4,,,$B18))} -> Diam Poland | D18: {=INDIRECT(ADDRESS($A18,D$4,,,$B18))} -> Group | E18: {=INDIRECT(ADDRESS($A18,E$4,,,$B18))} -> Diam Poland（PACK) | F18: {=INDIRECT(ADDRESS($A18,F$4,,,$B18))} -> 0 | G18: {=INDIRECT(ADDRESS($A18,G$4,,,$B18))} -> G | H18: {=INDIRECT(ADDRESS($A18,H$4,,,$B18))} -> 128.231 | I18: {=INDIRECT(ADDRESS($A18,I$4,,,$B18))} -> 128.231 | J18: {=INDIRECT(ADDRESS($A18,J$4,,,$B18))} -> 0
... A233: =+A232+1 -> 251 | B233: =+$D$2 -> W2 | C233: {=INDIRECT(ADDRESS($A233,C$4,,,$B233))} -> 0 | D233: {=INDIRECT(ADDRESS($A233,D$4,,,$B233))} -> 0 | E233: {=INDIRECT(ADDRESS($A233,E$4,,,$B233))} -> 0 | F233: {=INDIRECT(ADDRESS($A233,F$4,,,$B233))} -> 0 | G233: {=INDIRECT(ADDRESS($A233,G$4,,,$B233))} -> 0 | H233: {=INDIRECT(ADDRESS($A233,H$4,,,$B233))} -> 0 | I233: {=INDIRECT(ADDRESS($A233,I$4,,,$B233))} -> 0 | J233: {=INDIRECT(ADDRESS($A233,J$4,,,$B233))} -> 0
A234: =+A6 -> 24 | B234: =+$E$2 -> W1 | C234: {=INDIRECT(ADDRESS($A234,C$4,,,$B234))} -> D3 | D234: {=INDIRECT(ADDRESS($A234,D$4,,,$B234))} -> Group | E234: {=INDIRECT(ADDRESS($A234,E$4,,,$B234))} -> D3 | F234: {=INDIRECT(ADDRESS($A234,F$4,,,$B234))} -> 0 | G234: {=INDIRECT(ADDRESS($A234,G$4,,,$B234))} -> G | H234: {=INDIRECT(ADDRESS($A234,H$4,,,$B234))} -> 3385.283 | I234: {=INDIRECT(ADDRESS($A234,I$4,,,$B234))} -> 3385.283 | J234: {=INDIRECT(ADDRESS($A234,J$4,,,$B234))} -> 0
A235: =+A7 -> 25 | B235: =+$E$2 -> W1 | C235: {=INDIRECT(ADDRESS($A235,C$4,,,$B235))} -> Diam France | D235: {=INDIRECT(ADDRESS($A235,D$4,,,$B235))} -> Group | E235: {=INDIRECT(ADDRESS($A235,E$4,,,$B235))} -> Diam France | F235: {=INDIRECT(ADDRESS($A235,F$4,,,$B235))} -> 0 | G235: {=INDIRECT(ADDRESS($A235,G$4,,,$B235))} -> G | H235: {=INDIRECT(ADDRESS($A235,H$4,,,$B235))} -> 16.781 | I235: {=INDIRECT(ADDRESS($A235,I$4,,,$B235))} -> 16.781 | J235: {=INDIRECT(ADDRESS($A235,J$4,,,$B235))} -> 0
A236: =+A8 -> 26 | B236: =+$E$2 -> W1 | C236: {=INDIRECT(ADDRESS($A236,C$4,,,$B236))} -> DIAM Turkey | D236: {=INDIRECT(ADDRESS($A236,D$4,,,$B236))} -> Group | E236: {=INDIRECT(ADDRESS($A236,E$4,,,$B236))} -> DIAM Turkey | F236: {=INDIRECT(ADDRESS($A236,F$4,,,$B236))} -> 0 | G236: {=INDIRECT(ADDRESS($A236,G$4,,,$B236))} -> G | H236: {=INDIRECT(ADDRESS($A236,H$4,,,$B236))} -> 177.711 | I236: {=INDIRECT(ADDRESS($A236,I$4,,,$B236))} -> 177.711 | J236: {=INDIRECT(ADDRESS($A236,J$4,,,$B236))} -> 0
A237: =+A9 -> 27 | B237: =+$E$2 -> W1 | C237: {=INDIRECT(ADDRESS($A237,C$4,,,$B237))} -> Nevacril | D237: {=INDIRECT(ADDRESS($A237,D$4,,,$B237))} -> Group | E237: {=INDIRECT(ADDRESS($A237,E$4,,,$B237))} -> Nevacril | F237: {=INDIRECT(ADDRESS($A237,F$4,,,$B237))} -> 0 | G237: {=INDIRECT(ADDRESS($A237,G$4,,,$B237))} -> G | H237: {=INDIRECT(ADDRESS($A237,H$4,,,$B237))} -> 3.259 | I237: {=INDIRECT(ADDRESS($A237,I$4,,,$B237))} -> 3.259 | J237: {=INDIRECT(ADDRESS($A237,J$4,,,$B237))} -> 0
A238: =+A10 -> 28 | B238: =+$E$2 -> W1 | C238: {=INDIRECT(ADDRESS($A238,C$4,,,$B238))} -> Diam UK | D238: {=INDIRECT(ADDRESS($A238,D$4,,,$B238))} -> Group | E238: {=INDIRECT(ADDRESS($A238,E$4,,,$B238))} -> Diam UK | F238: {=INDIRECT(ADDRESS($A238,F$4,,,$B238))} -> 0 | G238: {=INDIRECT(ADDRESS($A238,G$4,,,$B238))} -> G | H238: {=INDIRECT(ADDRESS($A238,H$4,,,$B238))} -> 134 | I238: {=INDIRECT(ADDRESS($A238,I$4,,,$B238))} -> 134 | J238: {=INDIRECT(ADDRESS($A238,J$4,,,$B238))} -> 0
A239: =+A11 -> 29 | B239: =+$E$2 -> W1 | C239: {=INDIRECT(ADDRESS($A239,C$4,,,$B239))} -> DIAM PORTUGAL | D239: {=INDIRECT(ADDRESS($A239,D$4,,,$B239))} -> Group | E239: {=INDIRECT(ADDRESS($A239,E$4,,,$B239))} -> DIAM PORTUGAL | F239: {=INDIRECT(ADDRESS($A239,F$4,,,$B239))} -> 0 | G239: {=INDIRECT(ADDRESS($A239,G$4,,,$B239))} -> G | H239: {=INDIRECT(ADDRESS($A239,H$4,,,$B239))} -> 3.5 | I239: {=INDIRECT(ADDRESS($A239,I$4,,,$B239))} -> 3.5 | J239: {=INDIRECT(ADDRESS($A239,J$4,,,$B239))} -> 0
A240: =+A12 -> 30 | B240: =+$E$2 -> W1 | C240: {=INDIRECT(ADDRESS($A240,C$4,,,$B240))} -> DIAM PRESTIGE EUROPE | D240: {=INDIRECT(ADDRESS($A240,D$4,,,$B240))} -> Group | E240: {=INDIRECT(ADDRESS($A240,E$4,,,$B240))} -> DIAM PRESTIGE EUROPE | F240: {=INDIRECT(ADDRESS($A240,F$4,,,$B240))} -> 0 | G240: {=INDIRECT(ADDRESS($A240,G$4,,,$B240))} -> G | H240: {=INDIRECT(ADDRESS($A240,H$4,,,$B240))} -> 153.294 | I240: {=INDIRECT(ADDRESS($A240,I$4,,,$B240))} -> 153.294 | J240: {=INDIRECT(ADDRESS($A240,J$4,,,$B240))} -> 0
A241: =+A13 -> 31 | B241: =+$E$2 -> W1 | C241: {=INDIRECT(ADDRESS($A241,C$4,,,$B241))} -> PRUGENT DIAM EUROPE | D241: {=INDIRECT(ADDRESS($A241,D$4,,,$B241))} -> Group | E241: {=INDIRECT(ADDRESS($A241,E$4,,,$B241))} -> PRUGENT DIAM EUROPE | F241: {=INDIRECT(ADDRESS($A241,F$4,,,$B241))} -> 0 | G241: {=INDIRECT(ADDRESS($A241,G$4,,,$B241))} -> G | H241: {=INDIRECT(ADDRESS($A241,H$4,,,$B241))} -> 1.75 | I241: {=INDIRECT(ADDRESS($A241,I$4,,,$B241))} -> 1.75 | J241: {=INDIRECT(ADDRESS($A241,J$4,,,$B241))} -> 0
A242: =+A14 -> 32 | B242: =+$E$2 -> W1 | C242: {=INDIRECT(ADDRESS($A242,C$4,,,$B242))} -> Diam Japan | D242: {=INDIRECT(ADDRESS($A242,D$4,,,$B242))} -> Group | E242: {=INDIRECT(ADDRESS($A242,E$4,,,$B242))} -> Diam Japan(L) | F242: {=INDIRECT(ADDRESS($A242,F$4,,,$B242))} -> 0 | G242: {=INDIRECT(ADDRESS($A242,G$4,,,$B242))} -> G | H242: {=INDIRECT(ADDRESS($A242,H$4,,,$B242))} -> 385.936 | I242: {=INDIRECT(ADDRESS($A242,I$4,,,$B242))} -> 385.936 | J242: {=INDIRECT(ADDRESS($A242,J$4,,,$B242))} -> 0
A243: =+A15 -> 33 | B243: =+$E$2 -> W1 | C243: {=INDIRECT(ADDRESS($A243,C$4,,,$B243))} -> Diam Japan | D243: {=INDIRECT(ADDRESS($A243,D$4,,,$B243))} -> Group | E243: {=INDIRECT(ADDRESS($A243,E$4,,,$B243))} -> Diam Japan(PACK) | F243: {=INDIRECT(ADDRESS($A243,F$4,,,$B243))} -> 0 | G243: {=INDIRECT(ADDRESS($A243,G$4,,,$B243))} -> G | H243: {=INDIRECT(ADDRESS($A243,H$4,,,$B243))} -> 139.566 | I243: {=INDIRECT(ADDRESS($A243,I$4,,,$B243))} -> 139.566 | J243: {=INDIRECT(ADDRESS($A243,J$4,,,$B243))} -> 0
A244: =+A16 -> 34 | B244: =+$E$2 -> W1 | C244: {=INDIRECT(ADDRESS($A244,C$4,,,$B244))} -> DDA | D244: {=INDIRECT(ADDRESS($A244,D$4,,,$B244))} -> Group | E244: {=INDIRECT(ADDRESS($A244,E$4,,,$B244))} -> DDA(PACK) | F244: {=INDIRECT(ADDRESS($A244,F$4,,,$B244))} -> 0 | G244: {=INDIRECT(ADDRESS($A244,G$4,,,$B244))} -> G | H244: {=INDIRECT(ADDRESS($A244,H$4,,,$B244))} -> 10.337 | I244: {=INDIRECT(ADDRESS($A244,I$4,,,$B244))} -> 10.337 | J244: {=INDIRECT(ADDRESS($A244,J$4,,,$B244))} -> 0
A245: =+A17 -> 35 | B245: =+$E$2 -> W1 | C245: {=INDIRECT(ADDRESS($A245,C$4,,,$B245))} -> D3 | D245: {=INDIRECT(ADDRESS($A245,D$4,,,$B245))} -> Group | E245: {=INDIRECT(ADDRESS($A245,E$4,,,$B245))} -> D3(PACK) | F245: {=INDIRECT(ADDRESS($A245,F$4,,,$B245))} -> 0 | G245: {=INDIRECT(ADDRESS($A245,G$4,,,$B245))} -> G | H245: {=INDIRECT(ADDRESS($A245,H$4,,,$B245))} -> 34.496 | I245: {=INDIRECT(ADDRESS($A245,I$4,,,$B245))} -> 34.496 | J245: {=INDIRECT(ADDRESS($A245,J$4,,,$B245))} -> 0
... A461: =+A233 -> 251 | B461: =+$E$2 -> W1 | C461: {=INDIRECT(ADDRESS($A461,C$4,,,$B461))} -> 0 | D461: {=INDIRECT(ADDRESS($A461,D$4,,,$B461))} -> 0 | E461: {=INDIRECT(ADDRESS($A461,E$4,,,$B461))} -> 0 | F461: {=INDIRECT(ADDRESS($A461,F$4,,,$B461))} -> 0 | G461: {=INDIRECT(ADDRESS($A461,G$4,,,$B461))} -> 0 | H461: {=INDIRECT(ADDRESS($A461,H$4,,,$B461))} -> 0 | I461: {=INDIRECT(ADDRESS($A461,I$4,,,$B461))} -> 0 | J461: {=INDIRECT(ADDRESS($A461,J$4,,,$B461))} -> 0

Sheet Synth
A1: SYNTHESIS
A3: To be filled in (TURNOVER = BO)
A5: YTD : Year to date turnover. This means the cumulated turnover since the begining of the year.
A6: This turnover should the same as the turnover fill in Business Object (BO). See with your local accountant to know this turnover.
A8: TURNOVER | D8: ORDERBOOK 2026 | F8: FORECAST 2026 | H8: NEW ORDERS 2026 | J8: ORDERBOOK 2027
A10: W52 2025
A12: W1 | B12: =+'W1'!$J$12 -> 0 | D12: =+'W1'!$K$19 -> 11934.676 | F12: =+B12+D12 -> 11934.676 | H12: =D12+B12-D10 -> 11934.676 | J12: =+'W1'!$L$19 -> 0
A13: W2 | B13: =+'W2'!$J$12 -> 134.16 | D13: =+'W2'!$K$19 -> 12199.179 | F13: =+B13+D13 -> 12333.339 | H13: =F13-F12 -> 398.663 | J13: =+'W2'!$L$19 -> 0
A14: W3 | B14: =+'W3'!$J$12 -> 395.409 | D14: =+'W3'!$K$19 -> 12129.126 | F14: =+B14+D14 -> 12524.535 | H14: =F14-F13 -> 191.196 | J14: =+'W3'!$L$19 -> 0
A15: W4 | B15: =+'W4'!$J$12 -> 2343.93 | D15: =+'W4'!$K$19 -> 10743.055 | F15: =+B15+D15 -> 13086.985 | H15: =F15-F14 -> 562.45 | J15: =+'W4'!$L$19 -> 0
A16: W5 | B16: =+'W5'!$J$12 -> 6896.105 | D16: =+'W5'!$K$19 -> 6609.79 | F16: =+B16+D16 -> 13505.895 | H16: =F16-F15 -> 418.91 | J16: =+'W5'!$L$19 -> 0
A17: January YTD
A18: W6 | B18: =+'W6'!$J$12 -> 244.423 | D18: =+'W6'!$K$19 -> 7450.117 | F18: =+B17+B18+D18 -> 7694.54 | H18: =F18-F16 -> -5811.355 | J18: =+'W6'!$L$19 -> 0
A19: W7 | B19: =+'W7'!$J$12 -> 244.423 | D19: =+'W7'!$K$19 -> 7479.117 | F19: =+B17+B19+D19 -> 7723.54 | H19: =F19-F18 -> 29 | J19: =+'W7'!$L$19 -> 0
A20: W8 | B20: =+'W8'!$J$12 -> 244.423 | D20: =+'W8'!$K$19 -> 7479.117 | F20: =+B17+B20+D20 -> 7723.54 | H20: =F20-F19 -> 0 | J20: =+'W8'!$L$19 -> 0
A21: W9 | B21: =+'W9'!$J$12 -> 1477.552 | D21: =+'W9'!$K$19 -> 6437.674 | F21: =+B22+B21+D21 -> 7915.226 | H21: =F21-F20 -> 191.686 | J21: =+'W9'!$L$19 -> 0
A22: February YTD
A23: W10 | B23: =+'W10'!$J$12 -> 129.928 | D23: =+'W10'!$K$19 -> 6731.4 | F23: =+B22+B23+D23 -> 6861.328 | H23: =F23-F21 -> -1053.898 | J23: =+'W10'!$L$19 -> 0
A24: W11 | B24: =+'W11'!$J$12 -> 559.704 | D24: =+'W11'!$K$19 -> 6747.139 | F24: =+B22+B24+D24 -> 7306.843 | H24: =F24-F23 -> 445.515 | J24: =+'W11'!$L$19 -> 0
A25: W12 | B25: =+'W12'!$J$12 -> 776.651 | D25: =+'W12'!$K$19 -> 6566.65 | F25: =+B22+B25+D25 -> 7343.301 | H25: =F25-F24 -> 36.458 | J25: =+'W12'!$L$19 -> 0
A26: W13 | B26: =+'W13'!$J$12 -> 1302.566 | D26: =+'W13'!$K$19 -> 7502.635 | F26: =+B22+B26+D26 -> 8805.201 | H26: =F26-F25 -> 1461.9 | J26: =+'W13'!$L$19 -> 0
A27: March YTD
A28: W14 | B28: =+'W14'!$J$12 -> 0 | D28: =+'W14'!$K$19 -> 8474.303 | F28: =+B27+B28+D28 -> 8474.303 | H28: =F28-F26 -> -330.898 | J28: =+'W14'!$L$19 -> 0
A29: W15 | B29: =+'W15'!$J$12 -> 1254.829 | D29: =+'W15'!$K$19 -> 7647.474 | F29: =+B27+B29+D29 -> 8902.303 | H29: =F29-F28 -> 428 | J29: =+'W15'!$L$19 -> 0
A30: W16 | B30: =+'W16'!$J$12 -> 1796.085 | D30: =+'W16'!$K$19 -> 7677.303 | F30: =+B27+B30+D30 -> 9473.388 | H30: =F30-F29 -> 571.085 | J30: =+'W16'!$L$19 -> 0
A31: W17 | B31: =+'W17'!$J$12 -> 2828.752 | D31: =+'W17'!$K$19 -> 7692.468 | F31: =+B27+B31+D31 -> 10521.22 | H31: =F31-F30 -> 1047.832 | J31: =+'W17'!$L$19 -> 0
A32: W18 | B32: =+'W18'!$J$12 -> 2688.627 | D32: =+'W18'!$K$19 -> 8235.346 | F32: =+B33+B32+D32 -> 10923.973 | H32: =F32-F31 -> 402.753 | J32: =+'W18'!$L$19 -> 0
A33: April YTD
A34: W19 | B34: =+'W19'!$J$12 -> 0 | D34: =+'W19'!$K$19 -> 8392.347 | F34: =+B33+B34+D34 -> 8392.347 | H34: =F34-F32 -> -2531.626 | J34: =+'W19'!$L$19 -> 0
A35: W20 | B35: =+'W20'!$J$12 -> 338.931 | D35: =+'W20'!$K$19 -> 8389.723 | F35: =+B33+B35+D35 -> 8728.654 | H35: =F35-F34 -> 336.307 | J35: =+'W20'!$L$19 -> 0
A36: W21 | B36: =+'W21'!$J$12 -> 531.478 | D36: =+'W21'!$K$19 -> 8718.724 | F36: =+B33+B36+D36 -> 9250.202 | H36: =F36-F35 -> 521.548 | J36: =+'W21'!$L$19 -> 0
A37: W22 | B37: =+'W22'!$J$12 -> 2446.645 | D37: =+'W22'!$K$19 -> 7432.158 | F37: =+B38+B37+D37 -> 9878.803 | H37: =F37-F36 -> 628.601 | J37: =+'W22'!$L$19 -> 0
A38: May YTD
A39: W23 | B39: =+'W23'!$J$12 -> 0 | D39: =+'W23'!$K$19 -> 7718.502 | F39: =+B38+B39+D39 -> 7718.502 | H39: =F39-F37 -> -2160.301 | J39: =+'W23'!$L$19 -> 0
A40: W24 | B40: =+'W24'!$J$12 -> 295.789 | D40: =+'W24'!$K$19 -> 8068.568 | F40: =+B38+B40+D40 -> 8364.357 | H40: =F40-F39 -> 645.855 | J40: =+'W24'!$L$19 -> 0
A41: W25 | B41: =+'W25'!$J$12 -> 500.275 | D41: =+'W25'!$K$19 -> 8738.082 | F41: =+B38+B41+D41 -> 9238.357 | H41: =F41-F40 -> 874 | J41: =+'W25'!$L$19 -> 0
A42: W26 | B42: =+'W26'!$J$12 -> 2845.332 | D42: =+'W26'!$K$19 -> 7088.738 | F42: =+B38+B42+D42 -> 9934.07 | H42: =F42-F41 -> 695.713 | J42: =+'W26'!$L$19 -> 0
A43: June YTD
A44: W27 | B44: =+'W27'!$J$12 -> 0 | D44: =+'W27'!$K$19 -> 7548.578 | F44: =+B43+B44+D44 -> 7548.578 | H44: =F44-F42 -> -2385.492 | J44: =+'W27'!$L$19 -> 0
A45: W28 | B45: =+'W28'!$J$12 -> 442.332 | D45: =+'W28'!$K$19 -> 8415.325 | F45: =+B43+B45+D45 -> 8857.657 | H45: =F45-F44 -> 1309.079 | J45: =+'W28'!$L$19 -> 0
...

Sheet W1
E2: ENTITY NAME : | G2: =+parameters!D2 -> DE HONG KONG | I2: ORDER BOOK SYNTHESIS in K€
E4: WEEK : | G4: W1 | I4: Cells to be filled in
E6: MONTH : | G6: =+VLOOKUP(G4, parameters!G:H, 2, 0) -> January
E8: TURNOVER | F8: =parameters!D4 -> k€ | H8: YTD Turnover | J8: =+G6&" Turnover" -> January Turnover | L8: Last estim. for the month: | O8: Forecast 2026
H9: =+"from January 1 until end of "&G4 -> from January 1 until end of W1 | J9: =+"from "&G6&" 1 until end of "&G4 -> from January 1 until end of W1 | L9: =+G6 -> January | O9: =+G4 -> W1
E10: EXTERNAL SALES INVOICED (=outside group) | H10: =J10 -> 0 | J10: =0 -> 0 | L10: =J10+N17 -> 4734.722 | O10: =+H10+K17 -> 7272.878
E11: GROUP SALES INVOICED | H11: =J11 -> 0 | J11: =0 -> 0 | L11: =J11+N18 -> 1592.873 | O11: =+H11+K18 -> 4661.798 | S11: Definition orders : you consider the orders which are sure even if the order customers paper order is not yet received
E12: TOTAL | H12: =SUM(H10:H11) -> 0 | J12: =SUM(J10:J11) -> 0 | L12: =SUM(L10:L11) -> 6327.595 | O12: =SUM(O10:O11) -> 11934.676 | S12: The quantity, value, and delivery date can be changed before final delivery
E16: ORDERBOOK | F16: =+F8 -> k€ | J16: TOTAL ORDERBOOK | K16: Total amount 2026 | L16: Total amount 2027 | N16: 46023 | O16: 46054 | P16: 46082 | Q16: 46113 | R16: 46143 | S16: 46174 | T16: 46204 | U16: 46235 | V16: 46266 | W16: 46296 | X16: 46327 | Y16: 46357 | AA16: 46388 | AB16: 46419 | AC16: 46447 | AD16: 46478 | AE16: 46508 | AF16: 46539 | AG16: 46569 | AH16: 46600 | AI16: 46631 | AJ16: 46661 | AK16: 46692 | AL16: 46722
E17: External | J17: =+SUMIF($F$24:$F$247,"External",$J$24:$J$247) -> 7272.878 | K17: =+SUMIF($F$24:$F$247,"External",$K$24:$K$247) -> 7272.878 | L17: =+SUMIF($F$24:$F$247,"External",$L$24:$L$247) -> 0 | N17: =+SUMIF($F$24:$F$247,"External",N$24:N$247) -> 4734.722 | O17: =+SUMIF($F$24:$F$247,"External",O$24:O$247) -> 1618.757 | P17: =+SUMIF($F$24:$F$247,"External",P$24:P$247) -> 96 | Q17: =+SUMIF($F$24:$F$247,"External",Q$24:Q$247) -> 135.041 | R17: =+SUMIF($F$24:$F$247,"External",R$24:R$247) -> 537.358 | S17: =+SUMIF($F$24:$F$247,"External",S$24:S$247) -> 140 | T17: =+SUMIF($F$24:$F$247,"External",T$24:T$247) -> 11 | U17: =+SUMIF($F$24:$F$247,"External",U$24:U$247) -> 0 | ... Y17: =+SUMIF($F$24:$F$247,"External",Y$24:Y$247) -> 0 | AA17: =+SUMIF($F$24:$F$247,"External",AA$24:AA$247) -> 0 | AB17: =+SUMIF($F$24:$F$247,"External",AB$24:AB$247) -> 0 | AC17: =+SUMIF($F$24:$F$247,"External",AC$24:AC$247) -> 0 | AD17: =+SUMIF($F$24:$F$247,"External",AD$24:AD$247) -> 0 | AE17: =+SUMIF($F$24:$F$247,"External",AE$24:AE$247) -> 0 | AF17: =+SUMIF($F$24:$F$247,"External",AF$24:AF$247) -> 0 | AG17: =+SUMIF($F$24:$F$247,"External",AG$24:AG$247) -> 0 | AH17: =+SUMIF($F$24:$F$247,"External",AH$24:AH$247) -> 0 | ... AL17: =+SUMIF($F$24:$F$247,"External",AL$24:AL$247) -> 0
E18: Group | J18: =+SUMIF($F$24:$F$247,"Group",$J$24:$J$247) -> 4661.798 | K18: =+SUMIF($F$24:$F$247,"Group",$K$24:$K$247) -> 4661.798 | L18: =SUMIF($F$24:$F$247,"Group",$L$24:$L$247) -> 0 | N18: =+SUMIF($F$24:$F$247,"Group",N$24:N$247) -> 1592.873 | O18: =+SUMIF($F$24:$F$247,"Group",O$24:O$247) -> 584.294 | P18: =+SUMIF($F$24:$F$247,"Group",P$24:P$247) -> 629 | Q18: =+SUMIF($F$24:$F$247,"Group",Q$24:Q$247) -> 255.631 | R18: =+SUMIF($F$24:$F$247,"Group",R$24:R$247) -> 0 | S18: =+SUMIF($F$24:$F$247,"Group",S$24:S$247) -> 1600 | T18: =+SUMIF($F$24:$F$247,"Group",T$24:T$247) -> 0 | U18: =+SUMIF($F$24:$F$247,"Group",U$24:U$247) -> 0 | ... Y18: =+SUMIF($F$24:$F$247,"Group",Y$24:Y$247) -> 0 | AA18: =+SUMIF($F$24:$F$247,"Group",AA$24:AA$247) -> 0 | AB18: =+SUMIF($F$24:$F$247,"Group",AB$24:AB$247) -> 0 | AC18: =+SUMIF($F$24:$F$247,"Group",AC$24:AC$247) -> 0 | AD18: =+SUMIF($F$24:$F$247,"Group",AD$24:AD$247) -> 0 | AE18: =+SUMIF($F$24:$F$247,"Group",AE$24:AE$247) -> 0 | AF18: =+SUMIF($F$24:$F$247,"Group",AF$24:AF$247) -> 0 | AG18: =+SUMIF($F$24:$F$247,"Group",AG$24:AG$247) -> 0 | AH18: =+SUMIF($F$24:$F$247,"Group",AH$24:AH$247) -> 0 | ... AL18: =+SUMIF($F$24:$F$247,"Group",AL$24:AL$247) -> 0
E19: TOTAL | J19: =SUM(J17:J18) -> 11934.676 | K19: =SUM(K17:K18) -> 11934.676 | L19: =SUM(L17:L18) -> 0 | N19: =SUM(N17:N18) -> 6327.595 | O19: =SUM(O17:O18) -> 2203.051 | P19: =SUM(P17:P18) -> 725 | Q19: =SUM(Q17:Q18) -> 390.672 | R19: =SUM(R17:R18) -> 537.358 | S19: =SUM(S17:S18) -> 1740 | T19: =SUM(T17:T18) -> 11 | U19: =SUM(U17:U18) -> 0 | ... Y19: =SUM(Y17:Y18) -> 0 | AA19: =SUM(AA17:AA18) -> 0 | AB19: =SUM(AB17:AB18) -> 0 | AC19: =SUM(AC17:AC18) -> 0 | AD19: =SUM(AD17:AD18) -> 0 | AE19: =SUM(AE17:AE18) -> 0 | AF19: =SUM(AF17:AF18) -> 0 | AG19: =SUM(AG17:AG18) -> 0 | AH19: =SUM(AH17:AH18) -> 0 | ... AL19: =SUM(AL17:AL18) -> 0
I21: check | J21: =IF(SUM(J24:J247)=J19, "OK", "Please correct: the sum of orders below is not equal to the total calculated above. Make sure to pick External or Group for each order and don't change the formulas in columns K and L") -> OK | N21: 2026 | AA21: 2027
E23: Order (Tooling including) to be delivered | F23: External or Group | G23: Customers orders | H23: Quantity | I23: DGC | J23: TOTAL ORDERBOOK | K23: Total amount 2026 | L23: Total amount 2027 | N23: 46023 | O23: 46054 | P23: 46082 | Q23: 46113 | R23: 46143 | S23: 46174 | T23: 46204 | U23: 46235 | V23: 46266 | W23: 46296 | X23: 46327 | Y23: 46357 | AA23: 46388 | AB23: 46419 | AC23: 46447 | AD23: 46478 | AE23: 46508 | AF23: 46539 | AG23: 46569 | AH23: 46600 | AI23: 46631 | AJ23: 46661 | AK23: 46692 | AL23: 46722
D24: X | E24: D3 | F24: Group | G24: D3 | I24: G | J24: =+K24+L24 -> 3385.283 | K24: =SUM(N24:Y24) -> 3385.283 | L24: =SUM(AA24:AL24) -> 0 | N24: 1235.283 | O24: 50 | P24: 500 | S24: 1600
E25: Diam France | F25: Group | G25: Diam France | I25: G | J25: =+K25+L25 -> 16.781 | K25: =SUM(N25:Y25) -> 16.781 | L25: =SUM(AA25:AL25) -> 0 | N25: 7.781 | P25: 9
E26: DIAM Turkey | F26: Group | G26: DIAM Turkey | I26: G | J26: =+K26+L26 -> 177.711 | K26: =SUM(N26:Y26) -> 177.711 | L26: =SUM(AA26:AL26) -> 0 | N26: 33 | Q26: 144.711
E27: Nevacril | F27: Group | G27: Nevacril | I27: G | J27: =+K27+L27 -> 3.259 | K27: =SUM(N27:Y27) -> 3.259 | L27: =SUM(AA27:AL27) -> 0 | N27: 3.259
E28: Diam UK | F28: Group | G28: Diam UK | I28: G | J28: =+K28+L28 -> 134 | K28: =SUM(N28:Y28) -> 134 | L28: =SUM(AA28:AL28) -> 0 | N28: 14 | P28: 120
E29: DIAM PORTUGAL | F29: Group | G29: DIAM PORTUGAL | I29: G | J29: =+K29+L29 -> 3.5 | K29: =SUM(N29:Y29) -> 3.5 | L29: =SUM(AA29:AL29) -> 0 | N29: 3.5
E30: DIAM PRESTIGE EUROPE | F30: Group | G30: DIAM PRESTIGE EUROPE | I30: G | J30: =+K30+L30 -> 153.294 | K30: =SUM(N30:Y30) -> 153.294 | L30: =SUM(AA30:AL30) -> 0 | N30: 3 | O30: 150.294
E31: PRUGENT DIAM EUROPE | F31: Group | G31: PRUGENT DIAM EUROPE | I31: G | J31: =+K31+L31 -> 1.75 | K31: =SUM(N31:Y31) -> 1.75 | L31: =SUM(AA31:AL31) -> 0 | N31: 1.75
E32: Diam Japan | F32: Group | G32: Diam Japan(L) | I32: G | J32: =+K32+L32 -> 385.936 | K32: =SUM(N32:Y32) -> 385.936 | L32: =SUM(AA32:AL32) -> 0 | N32: 121.936 | O32: 264
E33: Diam Japan | F33: Group | G33: Diam Japan(PACK) | I33: G | J33: =+K33+L33 -> 139.566 | K33: =SUM(N33:Y33) -> 139.566 | L33: =SUM(AA33:AL33) -> 0 | N33: 79.566 | O33: 60
E34: DDA | F34: Group | G34: DDA(PACK) | I34: G | J34: =+K34+L34 -> 10.337 | K34: =SUM(N34:Y34) -> 10.337 | L34: =SUM(AA34:AL34) -> 0 | N34: 10.337
E35: D3 | F35: Group | G35: D3(PACK) | I35: G | J35: =+K35+L35 -> 34.496 | K35: =SUM(N35:Y35) -> 34.496 | L35: =SUM(AA35:AL35) -> 0 | N35: 24.496 | O35: 10
E36: Diam Poland | F36: Group | G36: Diam Poland（PACK) | I36: G | J36: =+K36+L36 -> 128.231 | K36: =SUM(N36:Y36) -> 128.231 | L36: =SUM(AA36:AL36) -> 0 | N36: 54.965 | O36: 50 | Q36: 23.266
E37: Diam Tunisia | F37: Group | G37: Diam Tunisia(PACK) | I37: G | J37: =+K37+L37 -> 87.654 | K37: =SUM(N37:Y37) -> 87.654 | L37: =SUM(AA37:AL37) -> 0 | Q37: 87.654
E38: Chanel | F38: External | G38: Chanel(FR team) | I38: G | J38: =+K38+L38 -> 319.223 | K38: =SUM(N38:Y38) -> 319.223 | L38: =SUM(AA38:AL38) -> 0 | N38: 103.223 | O38: 216
E39: Lancome/BIOTHERM | F39: External | G39: Loreal(FR team) | I39: G | J39: =+K39+L39 -> 1654.374 | K39: =SUM(N39:Y39) -> 1654.374 | L39: =SUM(AA39:AL39) -> 0 | N39: 1621.796 | O39: 32.578
E40: MUGLER | F40: External | G40: MUGLER(FR team) | I40: G | J40: =+K40+L40 -> 186.463 | K40: =SUM(N40:Y40) -> 186.463 | L40: =SUM(AA40:AL40) -> 0 | N40: 186.463
E41: LOUIS VUITTON | F41: External | G41: LOUIS VUITTON(FR team) | I41: G | J41: =+K41+L41 -> 113 | K41: =SUM(N41:Y41) -> 113 | L41: =SUM(AA41:AL41) -> 0 | N41: 113
E42: NARS/Shiseido | F42: External | G42: Shiseido(D3 team) | I42: G | J42: =+K42+L42 -> 636 | K42: =SUM(N42:Y42) -> 636 | L42: =SUM(AA42:AL42) -> 0 | N42: 321 | O42: 138 | Q42: 100 | R42: 77
E43: Hourglass | F43: External | G43: Hourglass(D3 team) | I43: G | J43: =+K43+L43 -> 185.814 | K43: =SUM(N43:Y43) -> 185.814 | L43: =SUM(AA43:AL43) -> 0 | N43: 35.814 | O43: 10 | S43: 140
E44: Luxottica | F44: External | G44: Luxottica(D3 team) | I44: G | J44: =+K44+L44 -> 321.58 | K44: =SUM(N44:Y44) -> 321.58 | L44: =SUM(AA44:AL44) -> 0 | N44: 255.58 | O44: 66
E45: LM/Bibbi Brown /MAC/Estee Lauder | F45: External | G45: ESTEE LAUDER(RDDC) | I45: E | J45: =+K45+L45 -> 1815.478 | K45: =SUM(N45:Y45) -> 1815.478 | L45: =SUM(AA45:AL45) -> 0 | N45: 775.12 | O45: 491 | P45: 89 | R45: 460.358
E46: SEPHORA | F46: External | G46: Sephora | I46: E | J46: =+K46+L46 -> 491.919 | K46: =SUM(N46:Y46) -> 491.919 | L46: =SUM(AA46:AL46) -> 0 | N46: 133.919 | O46: 351 | P46: 7
E47: Burberry/GUCCI | F47: External | G47: COTY | I47: E | J47: =+K47+L47 -> 15.049 | K47: =SUM(N47:Y47) -> 15.049 | L47: =SUM(AA47:AL47) -> 0 | N47: 15.049
E48: Tarte | F48: External | G48: Tarte | I48: E | J48: =+K48+L48 -> 257.072 | K48: =SUM(N48:Y48) -> 257.072 | L48: =SUM(AA48:AL48) -> 0 | N48: 7.893 | O48: 249.179
E49: KVD/FENTY | F49: External | G49: KENDO | I49: E | J49: =+K49+L49 -> 590.413 | K49: =SUM(N49:Y49) -> 590.413 | L49: =SUM(AA49:AL49) -> 0 | N49: 558.413 | Q49: 21 | T49: 11
...

Sheet W2
E2: ENTITY NAME : | G2: =+parameters!D2 -> DE HONG KONG | I2: ORDER BOOK SYNTHESIS in K€
E4: WEEK : | G4: W2 | I4: Cells to be filled in
E6: MONTH : | G6: =+VLOOKUP(G4, parameters!G:H, 2, 0) -> January
E8: TURNOVER | F8: =parameters!D4 -> k€ | H8: YTD Turnover | J8: =+G6&" Turnover" -> January Turnover | L8: Last estim. for the month: | O8: Forecast 2026
H9: =+"from January 1 until end of "&G4 -> from January 1 until end of W2 | J9: =+"from "&G6&" 1 until end of "&G4 -> from January 1 until end of W2 | L9: =+G6 -> January | O9: =+G4 -> W2 | P9: =+VLOOKUP(G4, parameters!$G$9:$I$61,3,0) -> W1 | Q9: Var
E10: EXTERNAL SALES INVOICED (=outside group) | H10: =J10 -> 65.798 | J10: =0+65.798 -> 65.798 | L10: =J10+N17 -> 4534.479 | O10: =+H10+K17 -> 7469.878 | P10: {=INDIRECT(ADDRESS(10,15,,,VLOOKUP($G$4,parameters!$G:$I,3,0)))} -> 7272.878 | Q10: =O10-P10 -> 197
E11: GROUP SALES INVOICED | H11: =J11 -> 68.362 | J11: =0+68.362 -> 68.362 | L11: =J11+N18 -> 1815.541 | O11: =+H11+K18 -> 4863.461 | P11: {=INDIRECT(ADDRESS(11,15,,,VLOOKUP($G$4,parameters!$G:$I,3,0)))} -> 4661.798 | Q11: =O11-P11 -> 201.663 | S11: Definition orders : you consider the orders which are sure even if the order customers paper order is not yet received
E12: TOTAL | H12: =SUM(H10:H11) -> 134.16 | J12: =SUM(J10:J11) -> 134.16 | L12: =SUM(L10:L11) -> 6350.02 | O12: =SUM(O10:O11) -> 12333.339 | P12: =SUM(P10:P11) -> 11934.676 | Q12: =O12-P12 -> 398.663 | S12: The quantity, value, and delivery date can be changed before final delivery
E16: ORDERBOOK | F16: =+F8 -> k€ | J16: TOTAL ORDERBOOK | K16: Total amount 2026 | L16: Total amount 2027 | N16: 46023 | O16: 46054 | P16: 46082 | Q16: 46113 | R16: 46143 | S16: 46174 | T16: 46204 | U16: 46235 | V16: 46266 | W16: 46296 | X16: 46327 | Y16: 46357 | AA16: 46388 | AB16: 46419 | AC16: 46447 | AD16: 46478 | AE16: 46508 | AF16: 46539 | AG16: 46569 | AH16: 46600 | AI16: 46631 | AJ16: 46661 | AK16: 46692 | AL16: 46722
E17: External | J17: =+SUMIF($F$24:$F$251,"External",$J$24:$J$251) -> 7404.08 | K17: =+SUMIF($F$24:$F$251,"External",$K$24:$K$251) -> 7404.08 | L17: =+SUMIF($F$24:$F$251,"External",$L$24:$L$251) -> 0 | N17: =+SUMIF($F$24:$F$251,"External",N$24:N$251) -> 4468.681 | O17: =+SUMIF($F$24:$F$251,"External",O$24:O$251) -> 1678.798 | P17: =+SUMIF($F$24:$F$251,"External",P$24:P$251) -> 360 | Q17: =+SUMIF($F$24:$F$251,"External",Q$24:Q$251) -> 21 | R17: =+SUMIF($F$24:$F$251,"External",R$24:R$251) -> 105.358 | S17: =+SUMIF($F$24:$F$251,"External",S$24:S$251) -> 84.243 | T17: =+SUMIF($F$24:$F$251,"External",T$24:T$251) -> 11 | U17: =+SUMIF($F$24:$F$251,"External",U$24:U$251) -> 675 | ... Y17: =+SUMIF($F$24:$F$251,"External",Y$24:Y$251) -> 0 | AA17: =+SUMIF($F$24:$F$251,"External",AA$24:AA$251) -> 0 | AB17: =+SUMIF($F$24:$F$251,"External",AB$24:AB$251) -> 0 | AC17: =+SUMIF($F$24:$F$251,"External",AC$24:AC$251) -> 0 | AD17: =+SUMIF($F$24:$F$251,"External",AD$24:AD$251) -> 0 | AE17: =+SUMIF($F$24:$F$251,"External",AE$24:AE$251) -> 0 | AF17: =+SUMIF($F$24:$F$251,"External",AF$24:AF$251) -> 0 | AG17: =+SUMIF($F$24:$F$251,"External",AG$24:AG$251) -> 0 | AH17: =+SUMIF($F$24:$F$251,"External",AH$24:AH$251) -> 0 | ... AL17: =+SUMIF($F$24:$F$251,"External",AL$24:AL$251) -> 0
E18: Group | J18: =+SUMIF($F$24:$F$251,"Group",$J$24:$J$251) -> 4795.099 | K18: =+SUMIF($F$24:$F$251,"Group",$K$24:$K$251) -> 4795.099 | L18: =SUMIF($F$24:$F$251,"Group",$L$24:$L$251) -> 0 | N18: =+SUMIF($F$24:$F$251,"Group",N$24:N$251) -> 1747.179 | O18: =+SUMIF($F$24:$F$251,"Group",O$24:O$251) -> 640.237 | P18: =+SUMIF($F$24:$F$251,"Group",P$24:P$251) -> 121 | Q18: =+SUMIF($F$24:$F$251,"Group",Q$24:Q$251) -> 410.683 | R18: =+SUMIF($F$24:$F$251,"Group",R$24:R$251) -> 0 | S18: =+SUMIF($F$24:$F$251,"Group",S$24:S$251) -> 124 | T18: =+SUMIF($F$24:$F$251,"Group",T$24:T$251) -> 450 | U18: =+SUMIF($F$24:$F$251,"Group",U$24:U$251) -> 1302 | ... Y18: =+SUMIF($F$24:$F$251,"Group",Y$24:Y$251) -> 0 | AA18: =+SUMIF($F$24:$F$251,"Group",AA$24:AA$251) -> 0 | AB18: =+SUMIF($F$24:$F$251,"Group",AB$24:AB$251) -> 0 | AC18: =+SUMIF($F$24:$F$251,"Group",AC$24:AC$251) -> 0 | AD18: =+SUMIF($F$24:$F$251,"Group",AD$24:AD$251) -> 0 | AE18: =+SUMIF($F$24:$F$251,"Group",AE$24:AE$251) -> 0 | AF18: =+SUMIF($F$24:$F$251,"Group",AF$24:AF$251) -> 0 | AG18: =+SUMIF($F$24:$F$251,"Group",AG$24:AG$251) -> 0 | AH18: =+SUMIF($F$24:$F$251,"Group",AH$24:AH$251) -> 0 | ... AL18: =+SUMIF($F$24:$F$251,"Group",AL$24:AL$251) -> 0
E19: TOTAL | J19: =SUM(J17:J18) -> 12199.179 | K19: =SUM(K17:K18) -> 12199.179 | L19: =SUM(L17:L18) -> 0 | N19: =SUM(N17:N18) -> 6215.86 | O19: =SUM(O17:O18) -> 2319.035 | P19: =SUM(P17:P18) -> 481 | Q19: =SUM(Q17:Q18) -> 431.683 | R19: =SUM(R17:R18) -> 105.358 | S19: =SUM(S17:S18) -> 208.243 | T19: =SUM(T17:T18) -> 461 | U19: =SUM(U17:U18) -> 1977 | ... Y19: =SUM(Y17:Y18) -> 0 | AA19: =SUM(AA17:AA18) -> 0 | AB19: =SUM(AB17:AB18) -> 0 | AC19: =SUM(AC17:AC18) -> 0 | AD19: =SUM(AD17:AD18) -> 0 | AE19: =SUM(AE17:AE18) -> 0 | AF19: =SUM(AF17:AF18) -> 0 | AG19: =SUM(AG17:AG18) -> 0 | AH19: =SUM(AH17:AH18) -> 0 | ... AL19: =SUM(AL17:AL18) -> 0
I21: check | J21: =IF(SUM(J24:J251)=J19, "OK", "Please correct: the sum of orders below is not equal to the total calculated above. Make sure to pick External or Group for each order and don't change the formulas in columns K and L") -> OK | N21: 2026 | AA21: 2027
E23: Order (Tooling including) to be delivered | F23: External or Group | G23: Customers orders | H23: Quantity | I23: DGC | J23: TOTAL ORDERBOOK | K23: Total amount 2026 | L23: Total amount 2027 | N23: 46023 | O23: 46054 | P23: 46082 | Q23: 46113 | R23: 46143 | S23: 46174 | T23: 46204 | U23: 46235 | V23: 46266 | W23: 46296 | X23: 46327 | Y23: 46357 | AA23: 46388 | AB23: 46419 | AC23: 46447 | AD23: 46478 | AE23: 46508 | AF23: 46539 | AG23: 46569 | AH23: 46600 | AI23: 46631 | AJ23: 46661 | AK23: 46692 | AL23: 46722
D24: X | E24: D3 | F24: Group | G24: D3 | I24: G | J24: =+K24+L24 -> 3331.75 | K24: =SUM(N24:Y24) -> 3331.75 | L24: =SUM(AA24:AL24) -> 0 | N24: =1235.283-53.533+141 -> 1322.75 | O24: =50+56 -> 106 | P24: 1 | Q24: 26 | S24: 124 | T24: =500-1-26-23 -> 450 | U24: =1600-141-56+23-124 -> 1302
E25: Diam France | F25: Group | G25: Diam France | I25: G | J25: =+K25+L25 -> 16.781 | K25: =SUM(N25:Y25) -> 16.781 | L25: =SUM(AA25:AL25) -> 0 | N25: =7.781-3 -> 4.781 | P25: =9+3 -> 12
E26: DIAM Turkey | F26: Group | G26: DIAM Turkey | I26: G | J26: =+K26+L26 -> 166.23 | K26: =SUM(N26:Y26) -> 166.23 | L26: =SUM(AA26:AL26) -> 0 | N26: =33-1.568-10 -> 21.432 | Q26: =144.711+10-8.265-0.531-1.117 -> 144.798
E27: Nevacril | F27: Group | G27: Nevacril | I27: G | J27: =+K27+L27 -> 3.259 | K27: =SUM(N27:Y27) -> 3.259 | L27: =SUM(AA27:AL27) -> 0 | N27: 3.259
E28: Diam UK | F28: Group | G28: Diam UK | I28: G | J28: =+K28+L28 -> 191 | K28: =SUM(N28:Y28) -> 191 | L28: =SUM(AA28:AL28) -> 0 | O28: =120+14+57 -> 191
E29: DIAM PORTUGAL | F29: Group | G29: DIAM PORTUGAL | I29: G | J29: =+K29+L29 -> 3.5 | K29: =SUM(N29:Y29) -> 3.5 | L29: =SUM(AA29:AL29) -> 0 | O29: 3.5
E30: DIAM PRESTIGE EUROPE | F30: Group | G30: DIAM PRESTIGE EUROPE | I30: G | J30: =+K30+L30 -> 153.294 | K30: =SUM(N30:Y30) -> 153.294 | L30: =SUM(AA30:AL30) -> 0 | O30: =150.294+3 -> 153.294
E31: PRUGENT DIAM EUROPE | F31: Group | G31: PRUGENT DIAM EUROPE | I31: G | J31: =+K31+L31 -> 1.443 | K31: =SUM(N31:Y31) -> 1.443 | L31: =SUM(AA31:AL31) -> 0 | O31: =1.75-0.307 -> 1.443
E32: Diam Japan | F32: Group | G32: Diam Japan(L) | I32: G | J32: =+K32+L32 -> 412.895 | K32: =SUM(N32:Y32) -> 412.895 | L32: =SUM(AA32:AL32) -> 0 | N32: =121.936-3.041+13 -> 131.895 | O32: =264-13-68 -> 183 | P32: =68+30 -> 98
E33: Diam Japan | F33: Group | G33: Diam Japan(PACK) | I33: G | J33: =+K33+L33 -> 254.566 | K33: =SUM(N33:Y33) -> 254.566 | L33: =SUM(AA33:AL33) -> 0 | N33: =79.566+60+115 -> 254.566
E34: DDA | F34: Group | G34: DDA(PACK) | I34: G | J34: =+K34+L34 -> 10 | K34: =SUM(N34:Y34) -> 10 | L34: =SUM(AA34:AL34) -> 0 | Q34: 10
E35: D3 | F35: Group | G35: D3(PACK) | I35: G | J35: =+K35+L35 -> 34.496 | K35: =SUM(N35:Y35) -> 34.496 | L35: =SUM(AA35:AL35) -> 0 | N35: =24.496-16 -> 8.496 | O35: =10-8 -> 2 | P35: =16+8-14 -> 10 | Q35: 14
E36: Diam Poland | F36: Group | G36: Diam Poland（PACK) | I36: G | J36: =+K36+L36 -> 128.231 | K36: =SUM(N36:Y36) -> 128.231 | L36: =SUM(AA36:AL36) -> 0 | Q36: =54.965+50+23.266 -> 128.231
E37: Diam Tunisia | F37: Group | G37: Diam Tunisia(PACK) | I37: G | J37: =+K37+L37 -> 87.654 | K37: =SUM(N37:Y37) -> 87.654 | L37: =SUM(AA37:AL37) -> 0 | Q37: 87.654
E38: Chanel | F38: External | G38: Chanel(FR team) | I38: G | J38: =+K38+L38 -> 349.223 | K38: =SUM(N38:Y38) -> 349.223 | L38: =SUM(AA38:AL38) -> 0 | N38: =103.223+30 -> 133.223 | O38: 216
E39: Lancome/BIOTHERM | F39: External | G39: Loreal(FR team) | I39: G | J39: =+K39+L39 -> 1654.374 | K39: =SUM(N39:Y39) -> 1654.374 | L39: =SUM(AA39:AL39) -> 0 | N39: 1621.796 | O39: 32.578
E40: MUGLER | F40: External | G40: MUGLER(FR team) | I40: G | J40: =+K40+L40 -> 186.463 | K40: =SUM(N40:Y40) -> 186.463 | L40: =SUM(AA40:AL40) -> 0 | N40: 186.463
E41: LOUIS VUITTON | F41: External | G41: LOUIS VUITTON(FR team) | I41: G | J41: =+K41+L41 -> 113 | K41: =SUM(N41:Y41) -> 113 | L41: =SUM(AA41:AL41) -> 0 | N41: =113 -> 113
E42: NARS/Shiseido | F42: External | G42: Shiseido(D3 team) | I42: G | J42: =+K42+L42 -> 622.201 | K42: =SUM(N42:Y42) -> 622.201 | L42: =SUM(AA42:AL42) -> 0 | N42: =321-13.799-305+8 -> 10.201 | O42: =138+62 -> 200 | P42: =100+77+15 -> 192 | S42: 28 | U42: =305-62-15-28-8 -> 192
E43: Hourglass | F43: External | G43: Hourglass(D3 team) | I43: G | J43: =+K43+L43 -> 163.243 | K43: =SUM(N43:Y43) -> 163.243 | L43: =SUM(AA43:AL43) -> 0 | S43: =35.814-22.571+10+33 -> 56.243 | U43: =140-33 -> 107
E44: Luxottica | F44: External | G44: Luxottica(D3 team) | I44: G | J44: =+K44+L44 -> 321.58 | K44: =SUM(N44:Y44) -> 321.58 | L44: =SUM(AA44:AL44) -> 0 | N44: 255.58 | O44: 66
E45: LM/Bibbi Brown /MAC/Estee Lauder | F45: External | G45: ESTEE LAUDER(RDDC) | I45: E | J45: =+K45+L45 -> 1815.478 | K45: =SUM(N45:Y45) -> 1815.478 | L45: =SUM(AA45:AL45) -> 0 | N45: =775.12-54 -> 721.12 | O45: =491-16 -> 475 | P45: =89+49 -> 138 | R45: =460.358-355 -> 105.358 | U45: =54+16-49+355 -> 376
E46: SEPHORA | F46: External | G46: Sephora | I46: E | J46: =+K46+L46 -> 505.919 | K46: =SUM(N46:Y46) -> 505.919 | L46: =SUM(AA46:AL46) -> 0 | N46: =133.919+87 -> 220.919 | O46: =351-87-2 -> 262 | P46: =7+2+14 -> 23
E47: Burberry/GUCCI | F47: External | G47: COTY | I47: E | J47: =+K47+L47 -> 15.049 | K47: =SUM(N47:Y47) -> 15.049 | L47: =SUM(AA47:AL47) -> 0 | N47: =15.049-7 -> 8.049 | P47: =7 -> 7
E48: Tarte | F48: External | G48: Tarte | I48: E | J48: =+K48+L48 -> 309.072 | K48: =SUM(N48:Y48) -> 309.072 | L48: =SUM(AA48:AL48) -> 0 | N48: =7.89300000000001-6 -> 1.893 | O48: =249.179+6+52 -> 307.179
E49: KVD/FENTY | F49: External | G49: KENDO | I49: E | J49: =+K49+L49 -> 590.413 | K49: =SUM(N49:Y49) -> 590.413 | L49: =SUM(AA49:AL49) -> 0 | N49: 558.413 | Q49: 21 | T49: 11
...

Sheet W3
E2: ENTITY NAME : | G2: =+parameters!D2 -> DE HONG KONG | I2: ORDER BOOK SYNTHESIS in K€
E4: WEEK : | G4: W3 | I4: Cells to be filled in
E6: MONTH : | G6: =+VLOOKUP(G4, parameters!G:H, 2, 0) -> January
E8: TURNOVER | F8: =parameters!D4 -> k€ | H8: YTD Turnover | J8: =+G6&" Turnover" -> January Turnover | L8: Last estim. for the month: | O8: Forecast 2026
H9: =+"from January 1 until end of "&G4 -> from January 1 until end of W3 | J9: =+"from "&G6&" 1 until end of "&G4 -> from January 1 until end of W3 | L9: =+G6 -> January | O9: =+G4 -> W3 | P9: =+VLOOKUP(G4, parameters!$G$9:$I$61,3,0) -> W2 | Q9: Var
E10: EXTERNAL SALES INVOICED (=outside group) | H10: =J10 -> 253.444 | J10: =0+65.798+187.646 -> 253.444 | L10: =J10+N17 -> 4208.689 | O10: =+H10+K17 -> 7633.399 | P10: {=INDIRECT(ADDRESS(10,15,,,VLOOKUP($G$4,parameters!$G:$I,3,0)))} -> 7469.878 | Q10: =O10-P10 -> 163.521
E11: GROUP SALES INVOICED | H11: =J11 -> 141.965 | J11: =0+68.362+73.603 -> 141.965 | L11: =J11+N18 -> 1894.105 | O11: =+H11+K18 -> 4891.136 | P11: {=INDIRECT(ADDRESS(11,15,,,VLOOKUP($G$4,parameters!$G:$I,3,0)))} -> 4863.461 | Q11: =O11-P11 -> 27.675 | S11: Definition orders : you consider the orders which are sure even if the order customers paper order is not yet received
E12: TOTAL | H12: =SUM(H10:H11) -> 395.409 | J12: =SUM(J10:J11) -> 395.409 | L12: =SUM(L10:L11) -> 6102.794 | O12: =SUM(O10:O11) -> 12524.535 | P12: =SUM(P10:P11) -> 12333.339 | Q12: =O12-P12 -> 191.196 | S12: The quantity, value, and delivery date can be changed before final delivery
E16: ORDERBOOK | F16: =+F8 -> k€ | J16: TOTAL ORDERBOOK | K16: Total amount 2026 | L16: Total amount 2027 | N16: 46023 | O16: 46054 | P16: 46082 | Q16: 46113 | R16: 46143 | S16: 46174 | T16: 46204 | U16: 46235 | V16: 46266 | W16: 46296 | X16: 46327 | Y16: 46357 | AA16: 46388 | AB16: 46419 | AC16: 46447 | AD16: 46478 | AE16: 46508 | AF16: 46539 | AG16: 46569 | AH16: 46600 | AI16: 46631 | AJ16: 46661 | AK16: 46692 | AL16: 46722
E17: External | J17: =+SUMIF($F$24:$F$253,"External",$J$24:$J$253) -> 7379.955 | K17: =+SUMIF($F$24:$F$253,"External",$K$24:$K$253) -> 7379.955 | L17: =+SUMIF($F$24:$F$253,"External",$L$24:$L$253) -> 0 | N17: =+SUMIF($F$24:$F$253,"External",N$24:N$253) -> 3955.245 | O17: =+SUMIF($F$24:$F$253,"External",O$24:O$253) -> 1772.079 | P17: =+SUMIF($F$24:$F$253,"External",P$24:P$253) -> 375.45 | Q17: =+SUMIF($F$24:$F$253,"External",Q$24:Q$253) -> 21 | R17: =+SUMIF($F$24:$F$253,"External",R$24:R$253) -> 105.358 | S17: =+SUMIF($F$24:$F$253,"External",S$24:S$253) -> 374.243 | T17: =+SUMIF($F$24:$F$253,"External",T$24:T$253) -> 11 | U17: =+SUMIF($F$24:$F$253,"External",U$24:U$253) -> 765.58 | ... Y17: =+SUMIF($F$24:$F$253,"External",Y$24:Y$253) -> 0 | AA17: =+SUMIF($F$24:$F$253,"External",AA$24:AA$253) -> 0 | AB17: =+SUMIF($F$24:$F$253,"External",AB$24:AB$253) -> 0 | AC17: =+SUMIF($F$24:$F$253,"External",AC$24:AC$253) -> 0 | AD17: =+SUMIF($F$24:$F$253,"External",AD$24:AD$253) -> 0 | AE17: =+SUMIF($F$24:$F$253,"External",AE$24:AE$253) -> 0 | AF17: =+SUMIF($F$24:$F$253,"External",AF$24:AF$253) -> 0 | AG17: =+SUMIF($F$24:$F$253,"External",AG$24:AG$253) -> 0 | AH17: =+SUMIF($F$24:$F$253,"External",AH$24:AH$253) -> 0 | ... AL17: =+SUMIF($F$24:$F$253,"External",AL$24:AL$253) -> 0
E18: Group | J18: =+SUMIF($F$24:$F$253,"Group",$J$24:$J$253) -> 4749.171 | K18: =+SUMIF($F$24:$F$253,"Group",$K$24:$K$253) -> 4749.171 | L18: =SUMIF($F$24:$F$253,"Group",$L$24:$L$253) -> 0 | N18: =+SUMIF($F$24:$F$253,"Group",N$24:N$253) -> 1752.14 | O18: =+SUMIF($F$24:$F$253,"Group",O$24:O$253) -> 496.743 | P18: =+SUMIF($F$24:$F$253,"Group",P$24:P$253) -> 119.329 | Q18: =+SUMIF($F$24:$F$253,"Group",Q$24:Q$253) -> 511.959 | R18: =+SUMIF($F$24:$F$253,"Group",R$24:R$253) -> 0 | S18: =+SUMIF($F$24:$F$253,"Group",S$24:S$253) -> 124 | T18: =+SUMIF($F$24:$F$253,"Group",T$24:T$253) -> 450 | U18: =+SUMIF($F$24:$F$253,"Group",U$24:U$253) -> 1295 | ... Y18: =+SUMIF($F$24:$F$253,"Group",Y$24:Y$253) -> 0 | AA18: =+SUMIF($F$24:$F$253,"Group",AA$24:AA$253) -> 0 | AB18: =+SUMIF($F$24:$F$253,"Group",AB$24:AB$253) -> 0 | AC18: =+SUMIF($F$24:$F$253,"Group",AC$24:AC$253) -> 0 | AD18: =+SUMIF($F$24:$F$253,"Group",AD$24:AD$253) -> 0 | AE18: =+SUMIF($F$24:$F$253,"Group",AE$24:AE$253) -> 0 | AF18: =+SUMIF($F$24:$F$253,"Group",AF$24:AF$253) -> 0 | AG18: =+SUMIF($F$24:$F$253,"Group",AG$24:AG$253) -> 0 | AH18: =+SUMIF($F$24:$F$253,"Group",AH$24:AH$253) -> 0 | ... AL18: =+SUMIF($F$24:$F$253,"Group",AL$24:AL$253) -> 0
E19: TOTAL | J19: =SUM(J17:J18) -> 12129.126 | K19: =SUM(K17:K18) -> 12129.126 | L19: =SUM(L17:L18) -> 0 | N19: =SUM(N17:N18) -> 5707.385 | O19: =SUM(O17:O18) -> 2268.822 | P19: =SUM(P17:P18) -> 494.779 | Q19: =SUM(Q17:Q18) -> 532.959 | R19: =SUM(R17:R18) -> 105.358 | S19: =SUM(S17:S18) -> 498.243 | T19: =SUM(T17:T18) -> 461 | U19: =SUM(U17:U18) -> 2060.58 | ... Y19: =SUM(Y17:Y18) -> 0 | AA19: =SUM(AA17:AA18) -> 0 | AB19: =SUM(AB17:AB18) -> 0 | AC19: =SUM(AC17:AC18) -> 0 | AD19: =SUM(AD17:AD18) -> 0 | AE19: =SUM(AE17:AE18) -> 0 | AF19: =SUM(AF17:AF18) -> 0 | AG19: =SUM(AG17:AG18) -> 0 | AH19: =SUM(AH17:AH18) -> 0 | ... AL19: =SUM(AL17:AL18) -> 0
I21: check | J21: =IF(SUM(J24:J253)=J19, "OK", "Please correct: the sum of orders below is not equal to the total calculated above. Make sure to pick External or Group for each order and don't change the formulas in columns K and L") -> OK | N21: 2026 | AA21: 2027
E23: Order (Tooling including) to be delivered | F23: External or Group | G23: Customers orders | H23: Quantity | I23: DGC | J23: TOTAL ORDERBOOK | K23: Total amount 2026 | L23: Total amount 2027 | N23: 46023 | O23: 46054 | P23: 46082 | Q23: 46113 | R23: 46143 | S23: 46174 | T23: 46204 | U23: 46235 | V23: 46266 | W23: 46296 | X23: 46327 | Y23: 46357 | AA23: 46388 | AB23: 46419 | AC23: 46447 | AD23: 46478 | AE23: 46508 | AF23: 46539 | AG23: 46569 | AH23: 46600 | AI23: 46631 | AJ23: 46661 | AK23: 46692 | AL23: 46722
D24: X | E24: D3 | F24: Group | G24: D3 | I24: G | J24: =+K24+L24 -> 3325.649 | K24: =SUM(N24:Y24) -> 3325.649 | L24: =SUM(AA24:AL24) -> 0 | N24: =1322.75-6.101+7 -> 1323.649 | O24: 106 | P24: 1 | Q24: 26 | S24: 124 | T24: 450 | U24: =1302-7 -> 1295
E25: Diam France | F25: Group | G25: Diam France | I25: G | J25: =+K25+L25 -> 12.329 | K25: =SUM(N25:Y25) -> 12.329 | L25: =SUM(AA25:AL25) -> 0 | N25: 5 | P25: =4.781-4.295-0.157+12-5 -> 7.329
E26: DIAM Turkey | F26: Group | G26: DIAM Turkey | I26: G | J26: =+K26+L26 -> 148.398 | K26: =SUM(N26:Y26) -> 148.398 | L26: =SUM(AA26:AL26) -> 0 | N26: =21.432-17.832 -> 3.6 | Q26: 144.798
E27: NOR LINE | F27: Group | G27: NOR LINE | I27: G | J27: =+K27+L27 -> 4 | K27: =SUM(N27:Y27) -> 4 | L27: =SUM(AA27:AL27) -> 0 | N27: 4
E28: Nevacril | F28: Group | G28: Nevacril | I28: G | J28: =+K28+L28 -> 15.259 | K28: =SUM(N28:Y28) -> 15.259 | L28: =SUM(AA28:AL28) -> 0 | N28: =3.259+12 -> 15.259
E29: Diam UK | F29: Group | G29: Diam UK | I29: G | J29: =+K29+L29 -> 197 | K29: =SUM(N29:Y29) -> 197 | L29: =SUM(AA29:AL29) -> 0 | N29: 3 | O29: 191 | P29: 3
E30: DIAM PORTUGAL | F30: Group | G30: DIAM PORTUGAL | I30: G | J30: =+K30+L30 -> 3.5 | K30: =SUM(N30:Y30) -> 3.5 | L30: =SUM(AA30:AL30) -> 0 | Q30: 3.5
E31: DIAM PRESTIGE EUROPE | F31: Group | G31: DIAM PRESTIGE EUROPE | I31: G | J31: =+K31+L31 -> 109.776 | K31: =SUM(N31:Y31) -> 109.776 | L31: =SUM(AA31:AL31) -> 0 | O31: 12 | Q31: =153.294-43.518-12 -> 97.776
E32: PRUGENT DIAM EUROPE | F32: Group | G32: PRUGENT DIAM EUROPE | I32: G | J32: =+K32+L32 -> 2.743 | K32: =SUM(N32:Y32) -> 2.743 | L32: =SUM(AA32:AL32) -> 0 | O32: =1.443-1.7+3 -> 2.743
E33: Diam Japan | F33: Group | G33: Diam Japan(L) | I33: G | J33: =+K33+L33 -> 412.895 | K33: =SUM(N33:Y33) -> 412.895 | L33: =SUM(AA33:AL33) -> 0 | N33: 131.895 | O33: 183 | P33: 98
E34: DIAM ITALY | F34: Group | G34: DIAM ITALY | I34: G | J34: =+K34+L34 -> 2.675 | K34: =SUM(N34:Y34) -> 2.675 | L34: =SUM(AA34:AL34) -> 0 | N34: 2.675
E35: Diam Japan | F35: Group | G35: Diam Japan(PACK) | I35: G | J35: =+K35+L35 -> 254.566 | K35: =SUM(N35:Y35) -> 254.566 | L35: =SUM(AA35:AL35) -> 0 | N35: 254.566
E36: DDA | F36: Group | G36: DDA(PACK) | I36: G | J36: =+K36+L36 -> 10 | K36: =SUM(N36:Y36) -> 10 | L36: =SUM(AA36:AL36) -> 0 | Q36: 10
E37: D3 | F37: Group | G37: D3(PACK) | I37: G | J37: =+K37+L37 -> 34.496 | K37: =SUM(N37:Y37) -> 34.496 | L37: =SUM(AA37:AL37) -> 0 | N37: 8.496 | O37: 2 | P37: 10 | Q37: 14
E38: Diam Poland | F38: Group | G38: Diam Poland（PACK) | I38: G | J38: =+K38+L38 -> 128.231 | K38: =SUM(N38:Y38) -> 128.231 | L38: =SUM(AA38:AL38) -> 0 | Q38: 128.231
E39: Diam Tunisia | F39: Group | G39: Diam Tunisia(PACK) | I39: G | J39: =+K39+L39 -> 87.654 | K39: =SUM(N39:Y39) -> 87.654 | L39: =SUM(AA39:AL39) -> 0 | Q39: 87.654
E40: Chanel | F40: External | G40: Chanel(FR team) | I40: G | J40: =+K40+L40 -> 349.223 | K40: =SUM(N40:Y40) -> 349.223 | L40: =SUM(AA40:AL40) -> 0 | N40: 133.223 | O40: 216
E41: Lancome/BIOTHERM | F41: External | G41: Loreal(FR team) | I41: G | J41: =+K41+L41 -> 1644.974 | K41: =SUM(N41:Y41) -> 1644.974 | L41: =SUM(AA41:AL41) -> 0 | N41: =1621.796-15-9.4 -> 1597.396 | O41: =32.578+15-38 -> 9.578 | P41: 38
E42: MUGLER | F42: External | G42: MUGLER(FR team) | I42: G | J42: =+K42+L42 -> 186.463 | K42: =SUM(N42:Y42) -> 186.463 | L42: =SUM(AA42:AL42) -> 0 | N42: 186.463
E43: LOUIS VUITTON | F43: External | G43: LOUIS VUITTON(FR team) | I43: G | J43: =+K43+L43 -> 36.892 | K43: =SUM(N43:Y43) -> 36.892 | L43: =SUM(AA43:AL43) -> 0 | N43: =113-76.108 -> 36.892
E44: NARS/Shiseido | F44: External | G44: Shiseido(D3 team) | I44: G | J44: =+K44+L44 -> 528.43 | K44: =SUM(N44:Y44) -> 528.43 | L44: =SUM(AA44:AL44) -> 0 | N44: =10.201-93.771+168 -> 84.43 | O44: =200-5 -> 195 | P44: =192-168-9 -> 15 | S44: 28 | U44: =192+5+9 -> 206
E45: Hourglass | F45: External | G45: Hourglass(D3 team) | I45: G | J45: =+K45+L45 -> 163.243 | K45: =SUM(N45:Y45) -> 163.243 | L45: =SUM(AA45:AL45) -> 0 | O45: 5 | S45: 56.243 | U45: =107-5 -> 102
E46: Luxottica | F46: External | G46: Luxottica(D3 team) | I46: G | J46: =+K46+L46 -> 321.58 | K46: =SUM(N46:Y46) -> 321.58 | L46: =SUM(AA46:AL46) -> 0 | S46: 290 | U46: =255.58+66-290 -> 31.58
E47: LM/Bibbi Brown /MAC/Estee Lauder | F47: External | G47: ESTEE LAUDER(RDDC) | I47: E | J47: =+K47+L47 -> 1815.478 | K47: =SUM(N47:Y47) -> 1815.478 | L47: =SUM(AA47:AL47) -> 0 | N47: =721.12-4 -> 717.12 | O47: =475-19 -> 456 | P47: =138-17 -> 121 | R47: 105.358 | U47: =376+40 -> 416
E48: SEPHORA | F48: External | G48: Sephora | I48: E | J48: =+K48+L48 -> 505.919 | K48: =SUM(N48:Y48) -> 505.919 | L48: =SUM(AA48:AL48) -> 0 | N48: 220.919 | O48: 262 | P48: 23
E49: Burberry/GUCCI | F49: External | G49: COTY | I49: E | J49: =+K49+L49 -> 15.049 | K49: =SUM(N49:Y49) -> 15.049 | L49: =SUM(AA49:AL49) -> 0 | N49: 8.049 | P49: 7
...

Sheet W4
E2: ENTITY NAME : | G2: =+parameters!D2 -> DE HONG KONG | I2: ORDER BOOK SYNTHESIS in K€
E4: WEEK : | G4: W4 | I4: Cells to be filled in
E6: MONTH : | G6: =+VLOOKUP(G4, parameters!G:H, 2, 0) -> January
E8: TURNOVER | F8: =parameters!D4 -> k€ | H8: YTD Turnover | J8: =+G6&" Turnover" -> January Turnover | L8: Last estim. for the month: | O8: Forecast 2026
H9: =+"from January 1 until end of "&G4 -> from January 1 until end of W4 | J9: =+"from "&G6&" 1 until end of "&G4 -> from January 1 until end of W4 | L9: =+G6 -> January | O9: =+G4 -> W4 | P9: =+VLOOKUP(G4, parameters!$G$9:$I$61,3,0) -> W3 | Q9: Var
E10: EXTERNAL SALES INVOICED (=outside group) | H10: =J10 -> 1899.463 | J10: =0+65.798+187.646+1646.019 -> 1899.463 | L10: =J10+N17 -> 4637.144 | O10: =+H10+K17 -> 8132.399 | P10: {=INDIRECT(ADDRESS(10,15,,,VLOOKUP($G$4,parameters!$G:$I,3,0)))} -> 7633.399 | Q10: =O10-P10 -> 499
E11: GROUP SALES INVOICED | H11: =J11 -> 444.467 | J11: =0+68.362+73.603+302.502 -> 444.467 | L11: =J11+N18 -> 1947.652 | O11: =+H11+K18 -> 4954.586 | P11: {=INDIRECT(ADDRESS(11,15,,,VLOOKUP($G$4,parameters!$G:$I,3,0)))} -> 4891.136 | Q11: =O11-P11 -> 63.45 | S11: Definition orders : you consider the orders which are sure even if the order customers paper order is not yet received
E12: TOTAL | H12: =SUM(H10:H11) -> 2343.93 | J12: =SUM(J10:J11) -> 2343.93 | L12: =SUM(L10:L11) -> 6584.796 | O12: =SUM(O10:O11) -> 13086.985 | P12: =SUM(P10:P11) -> 12524.535 | Q12: =O12-P12 -> 562.45 | S12: The quantity, value, and delivery date can be changed before final delivery
E16: ORDERBOOK | F16: =+F8 -> k€ | J16: TOTAL ORDERBOOK | K16: Total amount 2026 | L16: Total amount 2027 | N16: 46023 | O16: 46054 | P16: 46082 | Q16: 46113 | R16: 46143 | S16: 46174 | T16: 46204 | U16: 46235 | V16: 46266 | W16: 46296 | X16: 46327 | Y16: 46357 | AA16: 46388 | AB16: 46419 | AC16: 46447 | AD16: 46478 | AE16: 46508 | AF16: 46539 | AG16: 46569 | AH16: 46600 | AI16: 46631 | AJ16: 46661 | AK16: 46692 | AL16: 46722
