Workbook

Sheet Executive Summary
A1: DIAM · GLOBAL FOLLOW UP
A3: W35 · 30 Aug 2026 · Global view · All sales · Sales + P1 · Reporting unit EUR K · FX 1 EUR = 1.18 USD
A6: Annual budget | C6: Sales to date | E6: Dashboard | G6: P1 | I6: Sales + P1 | K6: Residual gap
A7: 87010.199 | C7: 44569.868 | E7: 25546.452 | G7: 1846 | I7: 71962.32 | K7: -15047.879
A9: Complete published snapshot.
A10: BUSINESS UNIT POSITION · EUR K
A11: Region | B11: Business Unit | C11: Budget | D11: Sales to date | E11: Dashboard | F11: P1 | G11: Sales + P1 | H11: Coverage | I11: Gap
A12: Asia | B12: PDA · Asia (PDA + PDN + PGC) | C12: 10627.065 | D12: 1963.9134 | E12: 998 | F12: 271 | G12: 3232.9134 | H12: 0.30421507 | I12: -7394.1517
A13: Europe | B13: PDE · Prugent Diam Europe | C13: 24915 | D13: 15141 | E13: 4925 | F13: 793 | G13: 20859 | H13: 0.8372065 | I13: -4056
A14: Europe | B14: PDP · Prugent Diam Portugal | C14: 14500 | D14: 6733.3975 | E14: 3920 | F14: 486 | G14: 11139.398 | H14: 0.76823431 | I14: -3360.6025
A15: Europe | B15: PSG · Prugent Services GmbH | C15: 1500 | D15: 1224 | E15: 459 | F15: 0 | G15: 1683 | H15: 1.122 | I15: 183
A16: Americas | B16: PUS · Prugent America | C16: 6325.2306 | D16: 3438.4339 | E16: 2993.9548 | F16: 0 | G16: 6432.3887 | H16: 1.0169414 | I16: 107.15813
A17: Americas | B17: DMX · Diam Mexico | C17: 11319.024 | D17: 4321.1864 | E17: 6878.4579 | F17: 120 | G17: 11319.644 | H17: 1.0000548 | I17: 0.6203067
A18: Americas | B18: DBR · Diam Brazil | C18: 15423.88 | D18: 11747.937 | E18: 3307.0426 | F18: 176 | G18: 15230.979 | H18: 0.9874934 | I18: -192.90036
A19: Americas | B19: FFLEX · Fieldflex USA | C19: 2400 | D19: 0 | E19: 2064.997 | F19: 0 | G19: 2064.997 | H19: 0.86041541 | I19: -335.00301
A22: CUMULATIVE POSITION · EUR K
A23: Month | B23: Budget | C23: Sales | D23: Sales + P1
A24: Jan | B24: 6574.4881 | C24: 4507.5724 | D24: 4507.5724
A25: Feb | B25: 13376.982 | C25: 8232.8566 | D25: 8232.8566
A26: Mar | B26: 21241.629 | C26: 15248.016 | D26: 15249.016
A27: Apr | B27: 32614.521 | C27: 26565.519 | D27: 26566.519
A28: May | B28: 40184.907 | C28: 31985.072 | D28: 31986.072
A29: Jun | B29: 47699.885 | C29: 38708.084 | D29: 38709.084
A30: Jul | B30: 54202.648 | C30: 44106.548 | D30: 44107.548
A31: Aug | B31: 59327.15 | C31: 48265.208 | D31: 48271.208
A32: Sep | B32: 67592.802 | C32: 57042.265 | D32: 57119.265
A33: Oct | B33: 74636.103 | C33: 62850.698 | D33: 63297.698
A34: Nov | B34: 81571.311 | C34: 67368.559 | D34: 68403.559
A35: Dec | B35: 87010.199 | C35: 70116.32 | D35: 71962.32

Sheet Weekly Review
A1: DIAM · WEEKLY REVIEW
A3: W35 · 30 Aug 2026 · Global view · All sales · Sales + P1 · Reporting unit EUR K · FX 1 EUR = 1.18 USD
A5: Business Unit | B5: PDA | D5: =IFERROR(INDEX('Data Weekly'!$B$2:$B$273,MATCH($B$5,'Data Weekly'!$A$2:$A$273,0)),"") -> Asia (PDA + PDN + PGC) | J5: Change the selector to update the full matrix.
A6: W05–W26 use the frozen Global Follow Up history. From W27, Jan–Jun remains frozen and Jul–Dec follows the entity-dashboard snapshot.
A7: WEEKLY MONTHLY PROFILE · EUR K
A8: Snapshot | B8: Jan | C8: Feb | D8: Mar | E8: Apr | F8: May | G8: Jun | H8: Jul | I8: Aug | J8: Sep | K8: Oct | L8: Nov | M8: Dec | N8: FY Total | O8: Coverage | P8: WoW | Q8: Source
A9: Budget | B9: =SUMIFS('Data Weekly'!$F$2:$F$273,'Data Weekly'!$A$2:$A$273,$B$5,'Data Weekly'!$D$2:$D$273,$A9) -> 842.1969 | C9: =SUMIFS('Data Weekly'!$G$2:$G$273,'Data Weekly'!$A$2:$A$273,$B$5,'Data Weekly'!$D$2:$D$273,$A9) -> 889.09173 | D9: =SUMIFS('Data Weekly'!$H$2:$H$273,'Data Weekly'!$A$2:$A$273,$B$5,'Data Weekly'!$D$2:$D$273,$A9) -> 920.68852 | E9: =SUMIFS('Data Weekly'!$I$2:$I$273,'Data Weekly'!$A$2:$A$273,$B$5,'Data Weekly'!$D$2:$D$273,$A9) -> 912.37542 | F9: =SUMIFS('Data Weekly'!$J$2:$J$273,'Data Weekly'!$A$2:$A$273,$B$5,'Data Weekly'!$D$2:$D$273,$A9) -> 873.5492 | G9: =SUMIFS('Data Weekly'!$K$2:$K$273,'Data Weekly'!$A$2:$A$273,$B$5,'Data Weekly'!$D$2:$D$273,$A9) -> 937.03791 | H9: =SUMIFS('Data Weekly'!$L$2:$L$273,'Data Weekly'!$A$2:$A$273,$B$5,'Data Weekly'!$D$2:$D$273,$A9) -> 877.69877 | I9: =SUMIFS('Data Weekly'!$M$2:$M$273,'Data Weekly'!$A$2:$A$273,$B$5,'Data Weekly'!$D$2:$D$273,$A9) -> 889.68641 | J9: =SUMIFS('Data Weekly'!$N$2:$N$273,'Data Weekly'!$A$2:$A$273,$B$5,'Data Weekly'!$D$2:$D$273,$A9) -> 867.79987 | K9: =SUMIFS('Data Weekly'!$O$2:$O$273,'Data Weekly'!$A$2:$A$273,$B$5,'Data Weekly'!$D$2:$D$273,$A9) -> 845.67323 | L9: =SUMIFS('Data Weekly'!$P$2:$P$273,'Data Weekly'!$A$2:$A$273,$B$5,'Data Weekly'!$D$2:$D$273,$A9) -> 853.76019 | M9: =SUMIFS('Data Weekly'!$Q$2:$Q$273,'Data Weekly'!$A$2:$A$273,$B$5,'Data Weekly'!$D$2:$D$273,$A9) -> 917.50696 | N9: =SUMIFS('Data Weekly'!$R$2:$R$273,'Data Weekly'!$A$2:$A$273,$B$5,'Data Weekly'!$D$2:$D$273,$A9) -> 10627.065 | O9: =IF(OR(LEFT($A9,1)="W",LEFT($A9,10)="Sales + P1"),SUMIFS('Data Weekly'!$S$2:$S$273,'Data Weekly'!$A$2:$A$273,$B$5,'Data Weekly'!$D$2:$D$273,$A9),"") | P9: =SUMIFS('Data Weekly'!$T$2:$T$273,'Data Weekly'!$A$2:$A$273,$B$5,'Data Weekly'!$D$2:$D$273,$A9) -> 0 | Q9: =IFERROR(LOOKUP(2,1/(('Data Weekly'!$A$2:$A$273=$B$5)*('Data Weekly'!$D$2:$D$273=$A9)),'Data Weekly'!$U$2:$U$273),"") -> Approved Budget 2026
A10: W05 | B10: =SUMIFS('Data Weekly'!$F$2:$F$273,'Data Weekly'!$A$2:$A$273,$B$5,'Data Weekly'!$D$2:$D$273,$A10) -> 281 | C10: =SUMIFS('Data Weekly'!$G$2:$G$273,'Data Weekly'!$A$2:$A$273,$B$5,'Data Weekly'!$D$2:$D$273,$A10) -> 20.45 | D10: =SUMIFS('Data Weekly'!$H$2:$H$273,'Data Weekly'!$A$2:$A$273,$B$5,'Data Weekly'!$D$2:$D$273,$A10) -> 295.02 | E10: =SUMIFS('Data Weekly'!$I$2:$I$273,'Data Weekly'!$A$2:$A$273,$B$5,'Data Weekly'!$D$2:$D$273,$A10) -> 9.14 | F10: =SUMIFS('Data Weekly'!$J$2:$J$273,'Data Weekly'!$A$2:$A$273,$B$5,'Data Weekly'!$D$2:$D$273,$A10) -> 0 | G10: =SUMIFS('Data Weekly'!$K$2:$K$273,'Data Weekly'!$A$2:$A$273,$B$5,'Data Weekly'!$D$2:$D$273,$A10) -> 0 | H10: =SUMIFS('Data Weekly'!$L$2:$L$273,'Data Weekly'!$A$2:$A$273,$B$5,'Data Weekly'!$D$2:$D$273,$A10) -> 434 | I10: =SUMIFS('Data Weekly'!$M$2:$M$273,'Data Weekly'!$A$2:$A$273,$B$5,'Data Weekly'!$D$2:$D$273,$A10) -> 239.09 | J10: =SUMIFS('Data Weekly'!$N$2:$N$273,'Data Weekly'!$A$2:$A$273,$B$5,'Data Weekly'!$D$2:$D$273,$A10) -> 0 | K10: =SUMIFS('Data Weekly'!$O$2:$O$273,'Data Weekly'!$A$2:$A$273,$B$5,'Data Weekly'!$D$2:$D$273,$A10) -> 0 | L10: =SUMIFS('Data Weekly'!$P$2:$P$273,'Data Weekly'!$A$2:$A$273,$B$5,'Data Weekly'!$D$2:$D$273,$A10) -> 0 | M10: =SUMIFS('Data Weekly'!$Q$2:$Q$273,'Data Weekly'!$A$2:$A$273,$B$5,'Data Weekly'!$D$2:$D$273,$A10) -> 13.87 | N10: =SUMIFS('Data Weekly'!$R$2:$R$273,'Data Weekly'!$A$2:$A$273,$B$5,'Data Weekly'!$D$2:$D$273,$A10) -> 1292.57 | O10: =IF(OR(LEFT($A10,1)="W",LEFT($A10,10)="Sales + P1"),SUMIFS('Data Weekly'!$S$2:$S$273,'Data Weekly'!$A$2:$A$273,$B$5,'Data Weekly'!$D$2:$D$273,$A10),"") -> 0.12163001 | P10: =SUMIFS('Data Weekly'!$T$2:$T$273,'Data Weekly'!$A$2:$A$273,$B$5,'Data Weekly'!$D$2:$D$273,$A10) -> 0 | Q10: =IFERROR(LOOKUP(2,1/(('Data Weekly'!$A$2:$A$273=$B$5)*('Data Weekly'!$D$2:$D$273=$A10)),'Data Weekly'!$U$2:$U$273),"") -> Global Follow Up · frozen weekly history
A11: W06 | B11: =SUMIFS('Data Weekly'!$F$2:$F$273,'Data Weekly'!$A$2:$A$273,$B$5,'Data Weekly'!$D$2:$D$273,$A11) -> 310 | C11: =SUMIFS('Data Weekly'!$G$2:$G$273,'Data Weekly'!$A$2:$A$273,$B$5,'Data Weekly'!$D$2:$D$273,$A11) -> 214 | D11: =SUMIFS('Data Weekly'!$H$2:$H$273,'Data Weekly'!$A$2:$A$273,$B$5,'Data Weekly'!$D$2:$D$273,$A11) -> 165 | E11: =SUMIFS('Data Weekly'!$I$2:$I$273,'Data Weekly'!$A$2:$A$273,$B$5,'Data Weekly'!$D$2:$D$273,$A11) -> 9 | F11: =SUMIFS('Data Weekly'!$J$2:$J$273,'Data Weekly'!$A$2:$A$273,$B$5,'Data Weekly'!$D$2:$D$273,$A11) -> 0 | G11: =SUMIFS('Data Weekly'!$K$2:$K$273,'Data Weekly'!$A$2:$A$273,$B$5,'Data Weekly'!$D$2:$D$273,$A11) -> 439 | H11: =SUMIFS('Data Weekly'!$L$2:$L$273,'Data Weekly'!$A$2:$A$273,$B$5,'Data Weekly'!$D$2:$D$273,$A11) -> 0 | I11: =SUMIFS('Data Weekly'!$M$2:$M$273,'Data Weekly'!$A$2:$A$273,$B$5,'Data Weekly'!$D$2:$D$273,$A11) -> 236 | J11: =SUMIFS('Data Weekly'!$N$2:$N$273,'Data Weekly'!$A$2:$A$273,$B$5,'Data Weekly'!$D$2:$D$273,$A11) -> 0 | K11: =SUMIFS('Data Weekly'!$O$2:$O$273,'Data Weekly'!$A$2:$A$273,$B$5,'Data Weekly'!$D$2:$D$273,$A11) -> 0 | L11: =SUMIFS('Data Weekly'!$P$2:$P$273,'Data Weekly'!$A$2:$A$273,$B$5,'Data Weekly'!$D$2:$D$273,$A11) -> 0 | M11: =SUMIFS('Data Weekly'!$Q$2:$Q$273,'Data Weekly'!$A$2:$A$273,$B$5,'Data Weekly'!$D$2:$D$273,$A11) -> 14 | N11: =SUMIFS('Data Weekly'!$R$2:$R$273,'Data Weekly'!$A$2:$A$273,$B$5,'Data Weekly'!$D$2:$D$273,$A11) -> 1387 | O11: =IF(OR(LEFT($A11,1)="W",LEFT($A11,10)="Sales + P1"),SUMIFS('Data Weekly'!$S$2:$S$273,'Data Weekly'!$A$2:$A$273,$B$5,'Data Weekly'!$D$2:$D$273,$A11),"") -> 0.13051581 | P11: =SUMIFS('Data Weekly'!$T$2:$T$273,'Data Weekly'!$A$2:$A$273,$B$5,'Data Weekly'!$D$2:$D$273,$A11) -> 94.43 | Q11: =IFERROR(LOOKUP(2,1/(('Data Weekly'!$A$2:$A$273=$B$5)*('Data Weekly'!$D$2:$D$273=$A11)),'Data Weekly'!$U$2:$U$273),"") -> Global Follow Up · frozen weekly history
A12: W07 | B12: =SUMIFS('Data Weekly'!$F$2:$F$273,'Data Weekly'!$A$2:$A$273,$B$5,'Data Weekly'!$D$2:$D$273,$A12) -> 310 | C12: =SUMIFS('Data Weekly'!$G$2:$G$273,'Data Weekly'!$A$2:$A$273,$B$5,'Data Weekly'!$D$2:$D$273,$A12) -> 214 | D12: =SUMIFS('Data Weekly'!$H$2:$H$273,'Data Weekly'!$A$2:$A$273,$B$5,'Data Weekly'!$D$2:$D$273,$A12) -> 165 | E12: =SUMIFS('Data Weekly'!$I$2:$I$273,'Data Weekly'!$A$2:$A$273,$B$5,'Data Weekly'!$D$2:$D$273,$A12) -> 9 | F12: =SUMIFS('Data Weekly'!$J$2:$J$273,'Data Weekly'!$A$2:$A$273,$B$5,'Data Weekly'!$D$2:$D$273,$A12) -> 0 | G12: =SUMIFS('Data Weekly'!$K$2:$K$273,'Data Weekly'!$A$2:$A$273,$B$5,'Data Weekly'!$D$2:$D$273,$A12) -> 439 | H12: =SUMIFS('Data Weekly'!$L$2:$L$273,'Data Weekly'!$A$2:$A$273,$B$5,'Data Weekly'!$D$2:$D$273,$A12) -> 0 | I12: =SUMIFS('Data Weekly'!$M$2:$M$273,'Data Weekly'!$A$2:$A$273,$B$5,'Data Weekly'!$D$2:$D$273,$A12) -> 236 | J12: =SUMIFS('Data Weekly'!$N$2:$N$273,'Data Weekly'!$A$2:$A$273,$B$5,'Data Weekly'!$D$2:$D$273,$A12) -> 0 | K12: =SUMIFS('Data Weekly'!$O$2:$O$273,'Data Weekly'!$A$2:$A$273,$B$5,'Data Weekly'!$D$2:$D$273,$A12) -> 0 | L12: =SUMIFS('Data Weekly'!$P$2:$P$273,'Data Weekly'!$A$2:$A$273,$B$5,'Data Weekly'!$D$2:$D$273,$A12) -> 0 | M12: =SUMIFS('Data Weekly'!$Q$2:$Q$273,'Data Weekly'!$A$2:$A$273,$B$5,'Data Weekly'!$D$2:$D$273,$A12) -> 14 | N12: =SUMIFS('Data Weekly'!$R$2:$R$273,'Data Weekly'!$A$2:$A$273,$B$5,'Data Weekly'!$D$2:$D$273,$A12) -> 1387 | O12: =IF(OR(LEFT($A12,1)="W",LEFT($A12,10)="Sales + P1"),SUMIFS('Data Weekly'!$S$2:$S$273,'Data Weekly'!$A$2:$A$273,$B$5,'Data Weekly'!$D$2:$D$273,$A12),"") -> 0.13051581 | P12: =SUMIFS('Data Weekly'!$T$2:$T$273,'Data Weekly'!$A$2:$A$273,$B$5,'Data Weekly'!$D$2:$D$273,$A12) -> 0 | Q12: =IFERROR(LOOKUP(2,1/(('Data Weekly'!$A$2:$A$273=$B$5)*('Data Weekly'!$D$2:$D$273=$A12)),'Data Weekly'!$U$2:$U$273),"") -> Global Follow Up · frozen weekly history
A13: W08 | B13: =SUMIFS('Data Weekly'!$F$2:$F$273,'Data Weekly'!$A$2:$A$273,$B$5,'Data Weekly'!$D$2:$D$273,$A13) -> 310 | C13: =SUMIFS('Data Weekly'!$G$2:$G$273,'Data Weekly'!$A$2:$A$273,$B$5,'Data Weekly'!$D$2:$D$273,$A13) -> 214 | D13: =SUMIFS('Data Weekly'!$H$2:$H$273,'Data Weekly'!$A$2:$A$273,$B$5,'Data Weekly'!$D$2:$D$273,$A13) -> 165 | E13: =SUMIFS('Data Weekly'!$I$2:$I$273,'Data Weekly'!$A$2:$A$273,$B$5,'Data Weekly'!$D$2:$D$273,$A13) -> 9 | F13: =SUMIFS('Data Weekly'!$J$2:$J$273,'Data Weekly'!$A$2:$A$273,$B$5,'Data Weekly'!$D$2:$D$273,$A13) -> 0 | G13: =SUMIFS('Data Weekly'!$K$2:$K$273,'Data Weekly'!$A$2:$A$273,$B$5,'Data Weekly'!$D$2:$D$273,$A13) -> 439 | H13: =SUMIFS('Data Weekly'!$L$2:$L$273,'Data Weekly'!$A$2:$A$273,$B$5,'Data Weekly'!$D$2:$D$273,$A13) -> 0 | I13: =SUMIFS('Data Weekly'!$M$2:$M$273,'Data Weekly'!$A$2:$A$273,$B$5,'Data Weekly'!$D$2:$D$273,$A13) -> 236 | J13: =SUMIFS('Data Weekly'!$N$2:$N$273,'Data Weekly'!$A$2:$A$273,$B$5,'Data Weekly'!$D$2:$D$273,$A13) -> 0 | K13: =SUMIFS('Data Weekly'!$O$2:$O$273,'Data Weekly'!$A$2:$A$273,$B$5,'Data Weekly'!$D$2:$D$273,$A13) -> 0 | L13: =SUMIFS('Data Weekly'!$P$2:$P$273,'Data Weekly'!$A$2:$A$273,$B$5,'Data Weekly'!$D$2:$D$273,$A13) -> 0 | M13: =SUMIFS('Data Weekly'!$Q$2:$Q$273,'Data Weekly'!$A$2:$A$273,$B$5,'Data Weekly'!$D$2:$D$273,$A13) -> 14 | N13: =SUMIFS('Data Weekly'!$R$2:$R$273,'Data Weekly'!$A$2:$A$273,$B$5,'Data Weekly'!$D$2:$D$273,$A13) -> 1387 | O13: =IF(OR(LEFT($A13,1)="W",LEFT($A13,10)="Sales + P1"),SUMIFS('Data Weekly'!$S$2:$S$273,'Data Weekly'!$A$2:$A$273,$B$5,'Data Weekly'!$D$2:$D$273,$A13),"") -> 0.13051581 | P13: =SUMIFS('Data Weekly'!$T$2:$T$273,'Data Weekly'!$A$2:$A$273,$B$5,'Data Weekly'!$D$2:$D$273,$A13) -> 0 | Q13: =IFERROR(LOOKUP(2,1/(('Data Weekly'!$A$2:$A$273=$B$5)*('Data Weekly'!$D$2:$D$273=$A13)),'Data Weekly'!$U$2:$U$273),"") -> Global Follow Up · frozen weekly history
A14: W09 | B14: =SUMIFS('Data Weekly'!$F$2:$F$273,'Data Weekly'!$A$2:$A$273,$B$5,'Data Weekly'!$D$2:$D$273,$A14) -> 310 | C14: =SUMIFS('Data Weekly'!$G$2:$G$273,'Data Weekly'!$A$2:$A$273,$B$5,'Data Weekly'!$D$2:$D$273,$A14) -> 49 | D14: =SUMIFS('Data Weekly'!$H$2:$H$273,'Data Weekly'!$A$2:$A$273,$B$5,'Data Weekly'!$D$2:$D$273,$A14) -> 326 | E14: =SUMIFS('Data Weekly'!$I$2:$I$273,'Data Weekly'!$A$2:$A$273,$B$5,'Data Weekly'!$D$2:$D$273,$A14) -> 28 | F14: =SUMIFS('Data Weekly'!$J$2:$J$273,'Data Weekly'!$A$2:$A$273,$B$5,'Data Weekly'!$D$2:$D$273,$A14) -> 0 | G14: =SUMIFS('Data Weekly'!$K$2:$K$273,'Data Weekly'!$A$2:$A$273,$B$5,'Data Weekly'!$D$2:$D$273,$A14) -> 434 | H14: =SUMIFS('Data Weekly'!$L$2:$L$273,'Data Weekly'!$A$2:$A$273,$B$5,'Data Weekly'!$D$2:$D$273,$A14) -> 0 | I14: =SUMIFS('Data Weekly'!$M$2:$M$273,'Data Weekly'!$A$2:$A$273,$B$5,'Data Weekly'!$D$2:$D$273,$A14) -> 236 | J14: =SUMIFS('Data Weekly'!$N$2:$N$273,'Data Weekly'!$A$2:$A$273,$B$5,'Data Weekly'!$D$2:$D$273,$A14) -> 0 | K14: =SUMIFS('Data Weekly'!$O$2:$O$273,'Data Weekly'!$A$2:$A$273,$B$5,'Data Weekly'!$D$2:$D$273,$A14) -> 0 | L14: =SUMIFS('Data Weekly'!$P$2:$P$273,'Data Weekly'!$A$2:$A$273,$B$5,'Data Weekly'!$D$2:$D$273,$A14) -> 0 | M14: =SUMIFS('Data Weekly'!$Q$2:$Q$273,'Data Weekly'!$A$2:$A$273,$B$5,'Data Weekly'!$D$2:$D$273,$A14) -> 14 | N14: =SUMIFS('Data Weekly'!$R$2:$R$273,'Data Weekly'!$A$2:$A$273,$B$5,'Data Weekly'!$D$2:$D$273,$A14) -> 1397 | O14: =IF(OR(LEFT($A14,1)="W",LEFT($A14,10)="Sales + P1"),SUMIFS('Data Weekly'!$S$2:$S$273,'Data Weekly'!$A$2:$A$273,$B$5,'Data Weekly'!$D$2:$D$273,$A14),"") -> 0.1314568 | P14: =SUMIFS('Data Weekly'!$T$2:$T$273,'Data Weekly'!$A$2:$A$273,$B$5,'Data Weekly'!$D$2:$D$273,$A14) -> 10 | Q14: =IFERROR(LOOKUP(2,1/(('Data Weekly'!$A$2:$A$273=$B$5)*('Data Weekly'!$D$2:$D$273=$A14)),'Data Weekly'!$U$2:$U$273),"") -> Global Follow Up · frozen weekly history
A15: W10 | B15: =SUMIFS('Data Weekly'!$F$2:$F$273,'Data Weekly'!$A$2:$A$273,$B$5,'Data Weekly'!$D$2:$D$273,$A15) -> 310 | C15: =SUMIFS('Data Weekly'!$G$2:$G$273,'Data Weekly'!$A$2:$A$273,$B$5,'Data Weekly'!$D$2:$D$273,$A15) -> 49 | D15: =SUMIFS('Data Weekly'!$H$2:$H$273,'Data Weekly'!$A$2:$A$273,$B$5,'Data Weekly'!$D$2:$D$273,$A15) -> 330 | E15: =SUMIFS('Data Weekly'!$I$2:$I$273,'Data Weekly'!$A$2:$A$273,$B$5,'Data Weekly'!$D$2:$D$273,$A15) -> 28 | F15: =SUMIFS('Data Weekly'!$J$2:$J$273,'Data Weekly'!$A$2:$A$273,$B$5,'Data Weekly'!$D$2:$D$273,$A15) -> 0 | G15: =SUMIFS('Data Weekly'!$K$2:$K$273,'Data Weekly'!$A$2:$A$273,$B$5,'Data Weekly'!$D$2:$D$273,$A15) -> 434 | H15: =SUMIFS('Data Weekly'!$L$2:$L$273,'Data Weekly'!$A$2:$A$273,$B$5,'Data Weekly'!$D$2:$D$273,$A15) -> 0 | I15: =SUMIFS('Data Weekly'!$M$2:$M$273,'Data Weekly'!$A$2:$A$273,$B$5,'Data Weekly'!$D$2:$D$273,$A15) -> 243 | J15: =SUMIFS('Data Weekly'!$N$2:$N$273,'Data Weekly'!$A$2:$A$273,$B$5,'Data Weekly'!$D$2:$D$273,$A15) -> 0 | K15: =SUMIFS('Data Weekly'!$O$2:$O$273,'Data Weekly'!$A$2:$A$273,$B$5,'Data Weekly'!$D$2:$D$273,$A15) -> 0 | L15: =SUMIFS('Data Weekly'!$P$2:$P$273,'Data Weekly'!$A$2:$A$273,$B$5,'Data Weekly'!$D$2:$D$273,$A15) -> 0 | M15: =SUMIFS('Data Weekly'!$Q$2:$Q$273,'Data Weekly'!$A$2:$A$273,$B$5,'Data Weekly'!$D$2:$D$273,$A15) -> 14 | N15: =SUMIFS('Data Weekly'!$R$2:$R$273,'Data Weekly'!$A$2:$A$273,$B$5,'Data Weekly'!$D$2:$D$273,$A15) -> 1408 | O15: =IF(OR(LEFT($A15,1)="W",LEFT($A15,10)="Sales + P1"),SUMIFS('Data Weekly'!$S$2:$S$273,'Data Weekly'!$A$2:$A$273,$B$5,'Data Weekly'!$D$2:$D$273,$A15),"") -> 0.1324919 | P15: =SUMIFS('Data Weekly'!$T$2:$T$273,'Data Weekly'!$A$2:$A$273,$B$5,'Data Weekly'!$D$2:$D$273,$A15) -> 11 | Q15: =IFERROR(LOOKUP(2,1/(('Data Weekly'!$A$2:$A$273=$B$5)*('Data Weekly'!$D$2:$D$273=$A15)),'Data Weekly'!$U$2:$U$273),"") -> Global Follow Up · frozen weekly history
A16: W11 | B16: =SUMIFS('Data Weekly'!$F$2:$F$273,'Data Weekly'!$A$2:$A$273,$B$5,'Data Weekly'!$D$2:$D$273,$A16) -> 310 | C16: =SUMIFS('Data Weekly'!$G$2:$G$273,'Data Weekly'!$A$2:$A$273,$B$5,'Data Weekly'!$D$2:$D$273,$A16) -> 49 | D16: =SUMIFS('Data Weekly'!$H$2:$H$273,'Data Weekly'!$A$2:$A$273,$B$5,'Data Weekly'!$D$2:$D$273,$A16) -> 278 | E16: =SUMIFS('Data Weekly'!$I$2:$I$273,'Data Weekly'!$A$2:$A$273,$B$5,'Data Weekly'!$D$2:$D$273,$A16) -> 193 | F16: =SUMIFS('Data Weekly'!$J$2:$J$273,'Data Weekly'!$A$2:$A$273,$B$5,'Data Weekly'!$D$2:$D$273,$A16) -> 0 | G16: =SUMIFS('Data Weekly'!$K$2:$K$273,'Data Weekly'!$A$2:$A$273,$B$5,'Data Weekly'!$D$2:$D$273,$A16) -> 439 | H16: =SUMIFS('Data Weekly'!$L$2:$L$273,'Data Weekly'!$A$2:$A$273,$B$5,'Data Weekly'!$D$2:$D$273,$A16) -> 0 | I16: =SUMIFS('Data Weekly'!$M$2:$M$273,'Data Weekly'!$A$2:$A$273,$B$5,'Data Weekly'!$D$2:$D$273,$A16) -> 342 | J16: =SUMIFS('Data Weekly'!$N$2:$N$273,'Data Weekly'!$A$2:$A$273,$B$5,'Data Weekly'!$D$2:$D$273,$A16) -> 0 | K16: =SUMIFS('Data Weekly'!$O$2:$O$273,'Data Weekly'!$A$2:$A$273,$B$5,'Data Weekly'!$D$2:$D$273,$A16) -> 0 | L16: =SUMIFS('Data Weekly'!$P$2:$P$273,'Data Weekly'!$A$2:$A$273,$B$5,'Data Weekly'!$D$2:$D$273,$A16) -> 0 | M16: =SUMIFS('Data Weekly'!$Q$2:$Q$273,'Data Weekly'!$A$2:$A$273,$B$5,'Data Weekly'!$D$2:$D$273,$A16) -> 14 | N16: =SUMIFS('Data Weekly'!$R$2:$R$273,'Data Weekly'!$A$2:$A$273,$B$5,'Data Weekly'!$D$2:$D$273,$A16) -> 1625 | O16: =IF(OR(LEFT($A16,1)="W",LEFT($A16,10)="Sales + P1"),SUMIFS('Data Weekly'!$S$2:$S$273,'Data Weekly'!$A$2:$A$273,$B$5,'Data Weekly'!$D$2:$D$273,$A16),"") -> 0.15291146 | P16: =SUMIFS('Data Weekly'!$T$2:$T$273,'Data Weekly'!$A$2:$A$273,$B$5,'Data Weekly'!$D$2:$D$273,$A16) -> 217 | Q16: =IFERROR(LOOKUP(2,1/(('Data Weekly'!$A$2:$A$273=$B$5)*('Data Weekly'!$D$2:$D$273=$A16)),'Data Weekly'!$U$2:$U$273),"") -> Global Follow Up · frozen weekly history
A17: W12 | B17: =SUMIFS('Data Weekly'!$F$2:$F$273,'Data Weekly'!$A$2:$A$273,$B$5,'Data Weekly'!$D$2:$D$273,$A17) -> 310 | C17: =SUMIFS('Data Weekly'!$G$2:$G$273,'Data Weekly'!$A$2:$A$273,$B$5,'Data Weekly'!$D$2:$D$273,$A17) -> 49 | D17: =SUMIFS('Data Weekly'!$H$2:$H$273,'Data Weekly'!$A$2:$A$273,$B$5,'Data Weekly'!$D$2:$D$273,$A17) -> 304 | E17: =SUMIFS('Data Weekly'!$I$2:$I$273,'Data Weekly'!$A$2:$A$273,$B$5,'Data Weekly'!$D$2:$D$273,$A17) -> 257 | F17: =SUMIFS('Data Weekly'!$J$2:$J$273,'Data Weekly'!$A$2:$A$273,$B$5,'Data Weekly'!$D$2:$D$273,$A17) -> 1 | G17: =SUMIFS('Data Weekly'!$K$2:$K$273,'Data Weekly'!$A$2:$A$273,$B$5,'Data Weekly'!$D$2:$D$273,$A17) -> 847 | H17: =SUMIFS('Data Weekly'!$L$2:$L$273,'Data Weekly'!$A$2:$A$273,$B$5,'Data Weekly'!$D$2:$D$273,$A17) -> 96 | I17: =SUMIFS('Data Weekly'!$M$2:$M$273,'Data Weekly'!$A$2:$A$273,$B$5,'Data Weekly'!$D$2:$D$273,$A17) -> 342 | J17: =SUMIFS('Data Weekly'!$N$2:$N$273,'Data Weekly'!$A$2:$A$273,$B$5,'Data Weekly'!$D$2:$D$273,$A17) -> 0 | K17: =SUMIFS('Data Weekly'!$O$2:$O$273,'Data Weekly'!$A$2:$A$273,$B$5,'Data Weekly'!$D$2:$D$273,$A17) -> 0 | L17: =SUMIFS('Data Weekly'!$P$2:$P$273,'Data Weekly'!$A$2:$A$273,$B$5,'Data Weekly'!$D$2:$D$273,$A17) -> 0 | M17: =SUMIFS('Data Weekly'!$Q$2:$Q$273,'Data Weekly'!$A$2:$A$273,$B$5,'Data Weekly'!$D$2:$D$273,$A17) -> 14 | N17: =SUMIFS('Data Weekly'!$R$2:$R$273,'Data Weekly'!$A$2:$A$273,$B$5,'Data Weekly'!$D$2:$D$273,$A17) -> 2220 | O17: =IF(OR(LEFT($A17,1)="W",LEFT($A17,10)="Sales + P1"),SUMIFS('Data Weekly'!$S$2:$S$273,'Data Weekly'!$A$2:$A$273,$B$5,'Data Weekly'!$D$2:$D$273,$A17),"") -> 0.20890057 | P17: =SUMIFS('Data Weekly'!$T$2:$T$273,'Data Weekly'!$A$2:$A$273,$B$5,'Data Weekly'!$D$2:$D$273,$A17) -> 595 | Q17: =IFERROR(LOOKUP(2,1/(('Data Weekly'!$A$2:$A$273=$B$5)*('Data Weekly'!$D$2:$D$273=$A17)),'Data Weekly'!$U$2:$U$273),"") -> Global Follow Up · frozen weekly history
A18: W13 | B18: =SUMIFS('Data Weekly'!$F$2:$F$273,'Data Weekly'!$A$2:$A$273,$B$5,'Data Weekly'!$D$2:$D$273,$A18) -> 310 | C18: =SUMIFS('Data Weekly'!$G$2:$G$273,'Data Weekly'!$A$2:$A$273,$B$5,'Data Weekly'!$D$2:$D$273,$A18) -> 49 | D18: =SUMIFS('Data Weekly'!$H$2:$H$273,'Data Weekly'!$A$2:$A$273,$B$5,'Data Weekly'!$D$2:$D$273,$A18) -> 266 | E18: =SUMIFS('Data Weekly'!$I$2:$I$273,'Data Weekly'!$A$2:$A$273,$B$5,'Data Weekly'!$D$2:$D$273,$A18) -> 250 | F18: =SUMIFS('Data Weekly'!$J$2:$J$273,'Data Weekly'!$A$2:$A$273,$B$5,'Data Weekly'!$D$2:$D$273,$A18) -> 1 | G18: =SUMIFS('Data Weekly'!$K$2:$K$273,'Data Weekly'!$A$2:$A$273,$B$5,'Data Weekly'!$D$2:$D$273,$A18) -> 567 | H18: =SUMIFS('Data Weekly'!$L$2:$L$273,'Data Weekly'!$A$2:$A$273,$B$5,'Data Weekly'!$D$2:$D$273,$A18) -> 58 | I18: =SUMIFS('Data Weekly'!$M$2:$M$273,'Data Weekly'!$A$2:$A$273,$B$5,'Data Weekly'!$D$2:$D$273,$A18) -> 342 | J18: =SUMIFS('Data Weekly'!$N$2:$N$273,'Data Weekly'!$A$2:$A$273,$B$5,'Data Weekly'!$D$2:$D$273,$A18) -> 0 | K18: =SUMIFS('Data Weekly'!$O$2:$O$273,'Data Weekly'!$A$2:$A$273,$B$5,'Data Weekly'!$D$2:$D$273,$A18) -> 0 | L18: =SUMIFS('Data Weekly'!$P$2:$P$273,'Data Weekly'!$A$2:$A$273,$B$5,'Data Weekly'!$D$2:$D$273,$A18) -> 0 | M18: =SUMIFS('Data Weekly'!$Q$2:$Q$273,'Data Weekly'!$A$2:$A$273,$B$5,'Data Weekly'!$D$2:$D$273,$A18) -> 14 | N18: =SUMIFS('Data Weekly'!$R$2:$R$273,'Data Weekly'!$A$2:$A$273,$B$5,'Data Weekly'!$D$2:$D$273,$A18) -> 1857 | O18: =IF(OR(LEFT($A18,1)="W",LEFT($A18,10)="Sales + P1"),SUMIFS('Data Weekly'!$S$2:$S$273,'Data Weekly'!$A$2:$A$273,$B$5,'Data Weekly'!$D$2:$D$273,$A18),"") -> 0.17474251 | P18: =SUMIFS('Data Weekly'!$T$2:$T$273,'Data Weekly'!$A$2:$A$273,$B$5,'Data Weekly'!$D$2:$D$273,$A18) -> -363 | Q18: =IFERROR(LOOKUP(2,1/(('Data Weekly'!$A$2:$A$273=$B$5)*('Data Weekly'!$D$2:$D$273=$A18)),'Data Weekly'!$U$2:$U$273),"") -> Global Follow Up · frozen weekly history
A19: W14 | B19: =SUMIFS('Data Weekly'!$F$2:$F$273,'Data Weekly'!$A$2:$A$273,$B$5,'Data Weekly'!$D$2:$D$273,$A19) -> 310 | C19: =SUMIFS('Data Weekly'!$G$2:$G$273,'Data Weekly'!$A$2:$A$273,$B$5,'Data Weekly'!$D$2:$D$273,$A19) -> 49 | D19: =SUMIFS('Data Weekly'!$H$2:$H$273,'Data Weekly'!$A$2:$A$273,$B$5,'Data Weekly'!$D$2:$D$273,$A19) -> 251 | E19: =SUMIFS('Data Weekly'!$I$2:$I$273,'Data Weekly'!$A$2:$A$273,$B$5,'Data Weekly'!$D$2:$D$273,$A19) -> 312 | F19: =SUMIFS('Data Weekly'!$J$2:$J$273,'Data Weekly'!$A$2:$A$273,$B$5,'Data Weekly'!$D$2:$D$273,$A19) -> 62 | G19: =SUMIFS('Data Weekly'!$K$2:$K$273,'Data Weekly'!$A$2:$A$273,$B$5,'Data Weekly'!$D$2:$D$273,$A19) -> 581 | H19: =SUMIFS('Data Weekly'!$L$2:$L$273,'Data Weekly'!$A$2:$A$273,$B$5,'Data Weekly'!$D$2:$D$273,$A19) -> 0 | I19: =SUMIFS('Data Weekly'!$M$2:$M$273,'Data Weekly'!$A$2:$A$273,$B$5,'Data Weekly'!$D$2:$D$273,$A19) -> 349 | J19: =SUMIFS('Data Weekly'!$N$2:$N$273,'Data Weekly'!$A$2:$A$273,$B$5,'Data Weekly'!$D$2:$D$273,$A19) -> 0 | K19: =SUMIFS('Data Weekly'!$O$2:$O$273,'Data Weekly'!$A$2:$A$273,$B$5,'Data Weekly'!$D$2:$D$273,$A19) -> 0 | L19: =SUMIFS('Data Weekly'!$P$2:$P$273,'Data Weekly'!$A$2:$A$273,$B$5,'Data Weekly'!$D$2:$D$273,$A19) -> 0 | M19: =SUMIFS('Data Weekly'!$Q$2:$Q$273,'Data Weekly'!$A$2:$A$273,$B$5,'Data Weekly'!$D$2:$D$273,$A19) -> 14 | N19: =SUMIFS('Data Weekly'!$R$2:$R$273,'Data Weekly'!$A$2:$A$273,$B$5,'Data Weekly'!$D$2:$D$273,$A19) -> 1928 | O19: =IF(OR(LEFT($A19,1)="W",LEFT($A19,10)="Sales + P1"),SUMIFS('Data Weekly'!$S$2:$S$273,'Data Weekly'!$A$2:$A$273,$B$5,'Data Weekly'!$D$2:$D$273,$A19),"") -> 0.18142356 | P19: =SUMIFS('Data Weekly'!$T$2:$T$273,'Data Weekly'!$A$2:$A$273,$B$5,'Data Weekly'!$D$2:$D$273,$A19) -> 71 | Q19: =IFERROR(LOOKUP(2,1/(('Data Weekly'!$A$2:$A$273=$B$5)*('Data Weekly'!$D$2:$D$273=$A19)),'Data Weekly'!$U$2:$U$273),"") -> Global Follow Up · frozen weekly history
A20: W15 | B20: =SUMIFS('Data Weekly'!$F$2:$F$273,'Data Weekly'!$A$2:$A$273,$B$5,'Data Weekly'!$D$2:$D$273,$A20) -> 310 | C20: =SUMIFS('Data Weekly'!$G$2:$G$273,'Data Weekly'!$A$2:$A$273,$B$5,'Data Weekly'!$D$2:$D$273,$A20) -> 49 | D20: =SUMIFS('Data Weekly'!$H$2:$H$273,'Data Weekly'!$A$2:$A$273,$B$5,'Data Weekly'!$D$2:$D$273,$A20) -> 251 | E20: =SUMIFS('Data Weekly'!$I$2:$I$273,'Data Weekly'!$A$2:$A$273,$B$5,'Data Weekly'!$D$2:$D$273,$A20) -> 321 | F20: =SUMIFS('Data Weekly'!$J$2:$J$273,'Data Weekly'!$A$2:$A$273,$B$5,'Data Weekly'!$D$2:$D$273,$A20) -> 73 | G20: =SUMIFS('Data Weekly'!$K$2:$K$273,'Data Weekly'!$A$2:$A$273,$B$5,'Data Weekly'!$D$2:$D$273,$A20) -> 572 | H20: =SUMIFS('Data Weekly'!$L$2:$L$273,'Data Weekly'!$A$2:$A$273,$B$5,'Data Weekly'!$D$2:$D$273,$A20) -> 0 | I20: =SUMIFS('Data Weekly'!$M$2:$M$273,'Data Weekly'!$A$2:$A$273,$B$5,'Data Weekly'!$D$2:$D$273,$A20) -> 349 | J20: =SUMIFS('Data Weekly'!$N$2:$N$273,'Data Weekly'!$A$2:$A$273,$B$5,'Data Weekly'!$D$2:$D$273,$A20) -> 0 | K20: =SUMIFS('Data Weekly'!$O$2:$O$273,'Data Weekly'!$A$2:$A$273,$B$5,'Data Weekly'!$D$2:$D$273,$A20) -> 0 | L20: =SUMIFS('Data Weekly'!$P$2:$P$273,'Data Weekly'!$A$2:$A$273,$B$5,'Data Weekly'!$D$2:$D$273,$A20) -> 0 | M20: =SUMIFS('Data Weekly'!$Q$2:$Q$273,'Data Weekly'!$A$2:$A$273,$B$5,'Data Weekly'!$D$2:$D$273,$A20) -> 14 | N20: =SUMIFS('Data Weekly'!$R$2:$R$273,'Data Weekly'!$A$2:$A$273,$B$5,'Data Weekly'!$D$2:$D$273,$A20) -> 1939 | O20: =IF(OR(LEFT($A20,1)="W",LEFT($A20,10)="Sales + P1"),SUMIFS('Data Weekly'!$S$2:$S$273,'Data Weekly'!$A$2:$A$273,$B$5,'Data Weekly'!$D$2:$D$273,$A20),"") -> 0.18245865 | P20: =SUMIFS('Data Weekly'!$T$2:$T$273,'Data Weekly'!$A$2:$A$273,$B$5,'Data Weekly'!$D$2:$D$273,$A20) -> 11 | Q20: =IFERROR(LOOKUP(2,1/(('Data Weekly'!$A$2:$A$273=$B$5)*('Data Weekly'!$D$2:$D$273=$A20)),'Data Weekly'!$U$2:$U$273),"") -> Global Follow Up · frozen weekly history
... A42: Sales + P1 W35 | B42: =SUMIFS('Data Weekly'!$F$2:$F$273,'Data Weekly'!$A$2:$A$273,$B$5,'Data Weekly'!$D$2:$D$273,$A42) -> 310 | C42: =SUMIFS('Data Weekly'!$G$2:$G$273,'Data Weekly'!$A$2:$A$273,$B$5,'Data Weekly'!$D$2:$D$273,$A42) -> 49 | D42: =SUMIFS('Data Weekly'!$H$2:$H$273,'Data Weekly'!$A$2:$A$273,$B$5,'Data Weekly'!$D$2:$D$273,$A42) -> 252 | E42: =SUMIFS('Data Weekly'!$I$2:$I$273,'Data Weekly'!$A$2:$A$273,$B$5,'Data Weekly'!$D$2:$D$273,$A42) -> 328 | F42: =SUMIFS('Data Weekly'!$J$2:$J$273,'Data Weekly'!$A$2:$A$273,$B$5,'Data Weekly'!$D$2:$D$273,$A42) -> 242 | G42: =SUMIFS('Data Weekly'!$K$2:$K$273,'Data Weekly'!$A$2:$A$273,$B$5,'Data Weekly'!$D$2:$D$273,$A42) -> 665 | H42: =SUMIFS('Data Weekly'!$L$2:$L$273,'Data Weekly'!$A$2:$A$273,$B$5,'Data Weekly'!$D$2:$D$273,$A42) -> 118.9134 | I42: =SUMIFS('Data Weekly'!$M$2:$M$273,'Data Weekly'!$A$2:$A$273,$B$5,'Data Weekly'!$D$2:$D$273,$A42) -> 77 | J42: =SUMIFS('Data Weekly'!$N$2:$N$273,'Data Weekly'!$A$2:$A$273,$B$5,'Data Weekly'!$D$2:$D$273,$A42) -> 658 | K42: =SUMIFS('Data Weekly'!$O$2:$O$273,'Data Weekly'!$A$2:$A$273,$B$5,'Data Weekly'!$D$2:$D$273,$A42) -> 220 | L42: =SUMIFS('Data Weekly'!$P$2:$P$273,'Data Weekly'!$A$2:$A$273,$B$5,'Data Weekly'!$D$2:$D$273,$A42) -> 245 | M42: =SUMIFS('Data Weekly'!$Q$2:$Q$273,'Data Weekly'!$A$2:$A$273,$B$5,'Data Weekly'!$D$2:$D$273,$A42) -> 68 | N42: =SUMIFS('Data Weekly'!$R$2:$R$273,'Data Weekly'!$A$2:$A$273,$B$5,'Data Weekly'!$D$2:$D$273,$A42) -> 3232.9134 | O42: =IF(OR(LEFT($A42,1)="W",LEFT($A42,10)="Sales + P1"),SUMIFS('Data Weekly'!$S$2:$S$273,'Data Weekly'!$A$2:$A$273,$B$5,'Data Weekly'!$D$2:$D$273,$A42),"") -> 0.30421507 | P42: =SUMIFS('Data Weekly'!$T$2:$T$273,'Data Weekly'!$A$2:$A$273,$B$5,'Data Weekly'!$D$2:$D$273,$A42) -> 0 | Q42: =IFERROR(LOOKUP(2,1/(('Data Weekly'!$A$2:$A$273=$B$5)*('Data Weekly'!$D$2:$D$273=$A42)),'Data Weekly'!$U$2:$U$273),"") -> Hybrid monthly history + pipeline workbook

Sheet Data Weekly
A1: Scope | B1: Business Unit | C1: Region | D1: Record | E1: Week | F1: Jan | G1: Feb | H1: Mar | I1: Apr | J1: May | K1: Jun | L1: Jul | M1: Aug | N1: Sep | O1: Oct | P1: Nov | Q1: Dec | R1: FY Total | S1: Coverage | T1: WoW | U1: Source
A2: PDA | B2: Asia (PDA + PDN + PGC) | C2: Asia | D2: Budget | E2: 0 | F2: 842.1969 | G2: 889.09173 | H2: 920.68852 | I2: 912.37542 | J2: 873.5492 | K2: 937.03791 | L2: 877.69877 | M2: 889.68641 | N2: 867.79987 | O2: 845.67323 | P2: 853.76019 | Q2: 917.50696 | R2: 10627.065 | U2: Approved Budget 2026
A3: PDA | B3: Asia (PDA + PDN + PGC) | C3: Asia | D3: W05 | E3: 5 | F3: 281 | G3: 20.45 | H3: 295.02 | I3: 9.14 | J3: 0 | K3: 0 | L3: 434 | M3: 239.09 | N3: 0 | O3: 0 | P3: 0 | Q3: 13.87 | R3: 1292.57 | S3: 0.12163001 | U3: Global Follow Up · frozen weekly history
A4: PDA | B4: Asia (PDA + PDN + PGC) | C4: Asia | D4: W06 | E4: 6 | F4: 310 | G4: 214 | H4: 165 | I4: 9 | J4: 0 | K4: 439 | L4: 0 | M4: 236 | N4: 0 | O4: 0 | P4: 0 | Q4: 14 | R4: 1387 | S4: 0.13051581 | T4: 94.43 | U4: Global Follow Up · frozen weekly history
A5: PDA | B5: Asia (PDA + PDN + PGC) | C5: Asia | D5: W07 | E5: 7 | F5: 310 | G5: 214 | H5: 165 | I5: 9 | J5: 0 | K5: 439 | L5: 0 | M5: 236 | N5: 0 | O5: 0 | P5: 0 | Q5: 14 | R5: 1387 | S5: 0.13051581 | T5: 0 | U5: Global Follow Up · frozen weekly history
A6: PDA | B6: Asia (PDA + PDN + PGC) | C6: Asia | D6: W08 | E6: 8 | F6: 310 | G6: 214 | H6: 165 | I6: 9 | J6: 0 | K6: 439 | L6: 0 | M6: 236 | N6: 0 | O6: 0 | P6: 0 | Q6: 14 | R6: 1387 | S6: 0.13051581 | T6: 0 | U6: Global Follow Up · frozen weekly history
A7: PDA | B7: Asia (PDA + PDN + PGC) | C7: Asia | D7: W09 | E7: 9 | F7: 310 | G7: 49 | H7: 326 | I7: 28 | J7: 0 | K7: 434 | L7: 0 | M7: 236 | N7: 0 | O7: 0 | P7: 0 | Q7: 14 | R7: 1397 | S7: 0.1314568 | T7: 10 | U7: Global Follow Up · frozen weekly history
A8: PDA | B8: Asia (PDA + PDN + PGC) | C8: Asia | D8: W10 | E8: 10 | F8: 310 | G8: 49 | H8: 330 | I8: 28 | J8: 0 | K8: 434 | L8: 0 | M8: 243 | N8: 0 | O8: 0 | P8: 0 | Q8: 14 | R8: 1408 | S8: 0.1324919 | T8: 11 | U8: Global Follow Up · frozen weekly history
A9: PDA | B9: Asia (PDA + PDN + PGC) | C9: Asia | D9: W11 | E9: 11 | F9: 310 | G9: 49 | H9: 278 | I9: 193 | J9: 0 | K9: 439 | L9: 0 | M9: 342 | N9: 0 | O9: 0 | P9: 0 | Q9: 14 | R9: 1625 | S9: 0.15291146 | T9: 217 | U9: Global Follow Up · frozen weekly history
A10: PDA | B10: Asia (PDA + PDN + PGC) | C10: Asia | D10: W12 | E10: 12 | F10: 310 | G10: 49 | H10: 304 | I10: 257 | J10: 1 | K10: 847 | L10: 96 | M10: 342 | N10: 0 | O10: 0 | P10: 0 | Q10: 14 | R10: 2220 | S10: 0.20890057 | T10: 595 | U10: Global Follow Up · frozen weekly history
A11: PDA | B11: Asia (PDA + PDN + PGC) | C11: Asia | D11: W13 | E11: 13 | F11: 310 | G11: 49 | H11: 266 | I11: 250 | J11: 1 | K11: 567 | L11: 58 | M11: 342 | N11: 0 | O11: 0 | P11: 0 | Q11: 14 | R11: 1857 | S11: 0.17474251 | T11: -363 | U11: Global Follow Up · frozen weekly history
A12: PDA | B12: Asia (PDA + PDN + PGC) | C12: Asia | D12: W14 | E12: 14 | F12: 310 | G12: 49 | H12: 251 | I12: 312 | J12: 62 | K12: 581 | L12: 0 | M12: 349 | N12: 0 | O12: 0 | P12: 0 | Q12: 14 | R12: 1928 | S12: 0.18142356 | T12: 71 | U12: Global Follow Up · frozen weekly history
A13: PDA | B13: Asia (PDA + PDN + PGC) | C13: Asia | D13: W15 | E13: 15 | F13: 310 | G13: 49 | H13: 251 | I13: 321 | J13: 73 | K13: 572 | L13: 0 | M13: 349 | N13: 0 | O13: 0 | P13: 0 | Q13: 14 | R13: 1939 | S13: 0.18245865 | T13: 11 | U13: Global Follow Up · frozen weekly history
A14: PDA | B14: Asia (PDA + PDN + PGC) | C14: Asia | D14: W16 | E14: 16 | F14: 310 | G14: 49 | H14: 251 | I14: 314 | J14: 81 | K14: 568 | L14: 0 | M14: 336 | N14: 0 | O14: 0 | P14: 0 | Q14: 0 | R14: 1909 | S14: 0.17963567 | T14: -30 | U14: Global Follow Up · frozen weekly history
A15: PDA | B15: Asia (PDA + PDN + PGC) | C15: Asia | D15: W17 | E15: 17 | F15: 310 | G15: 49 | H15: 251 | I15: 328 | J15: 159 | K15: 499 | L15: 0 | M15: 336 | N15: 0 | O15: 0 | P15: 0 | Q15: 32 | R15: 1964 | S15: 0.18481114 | T15: 55 | U15: Global Follow Up · frozen weekly history
... A33: PDA | B33: Asia (PDA + PDN + PGC) | C33: Asia | D33: W35 | E33: 35 | F33: 310 | G33: 49 | H33: 251 | I33: 328 | J33: 242 | K33: 665 | L33: 118.9134 | M33: 77 | N33: 602 | O33: 167 | P33: 90 | Q33: 62 | R33: 2961.9134 | S33: 0.27871415 | T33: 65 | U33: Jan–Jun Global Follow Up · Jul–Dec entity dashboards
A34: PDA | B34: Asia (PDA + PDN + PGC) | C34: Asia | D34: P1 W35 | E34: 35 | F34: 0 | G34: 0 | H34: 1 | I34: 0 | J34: 0 | K34: 0 | L34: 0 | M34: 0 | N34: 56 | O34: 53 | P34: 155 | Q34: 6 | R34: 271 | U34: Pipeline workbook
A35: PDA | B35: Asia (PDA + PDN + PGC) | C35: Asia | D35: Sales + P1 W35 | E35: 35 | F35: 310 | G35: 49 | H35: 252 | I35: 328 | J35: 242 | K35: 665 | L35: 118.9134 | M35: 77 | N35: 658 | O35: 220 | P35: 245 | Q35: 68 | R35: 3232.9134 | S35: 0.30421507 | U35: Hybrid monthly history + pipeline workbook
A36: PDE | B36: Prugent Diam Europe | C36: Europe | D36: Budget | E36: 0 | F36: 1610 | G36: 1250 | H36: 1905 | I36: 5110 | J36: 1950 | K36: 2600 | L36: 1360 | M36: 1100 | N36: 2300 | O36: 1250 | P36: 2480 | Q36: 2000 | R36: 24915 | U36: Approved Budget 2026
A37: PDE | B37: Prugent Diam Europe | C37: Europe | D37: W05 | E37: 5 | F37: 1037 | G37: 380 | H37: 3471 | I37: 5838 | J37: 1359 | K37: 453 | L37: 0 | M37: 0 | N37: 0 | O37: 0 | P37: 0 | Q37: 0 | R37: 12538 | S37: 0.50323099 | U37: Global Follow Up · frozen weekly history
A38: PDE | B38: Prugent Diam Europe | C38: Europe | D38: W06 | E38: 6 | F38: 1013 | G38: 355 | H38: 3561 | I38: 6029 | J38: 787 | K38: 1033 | L38: 4 | M38: 4 | N38: 3 | O38: 0 | P38: 0 | Q38: 0 | R38: 12789 | S38: 0.51330524 | T38: 251 | U38: Global Follow Up · frozen weekly history
A39: PDE | B39: Prugent Diam Europe | C39: Europe | D39: W07 | E39: 7 | F39: 1031 | G39: 357 | H39: 3562 | I39: 6196 | J39: 1186 | K39: 1033 | L39: 4 | M39: 4 | N39: 4 | O39: 0 | P39: 0 | Q39: 0 | R39: 13377 | S39: 0.53690548 | T39: 588 | U39: Global Follow Up · frozen weekly history
A40: PDE | B40: Prugent Diam Europe | C40: Europe | D40: W08 | E40: 8 | F40: 1031 | G40: 356 | H40: 3614 | I40: 6282 | J40: 1186 | K40: 1545 | L40: 4 | M40: 4 | N40: 4 | O40: 0 | P40: 0 | Q40: 0 | R40: 14026 | S40: 0.56295404 | T40: 649 | U40: Global Follow Up · frozen weekly history
A41: PDE | B41: Prugent Diam Europe | C41: Europe | D41: W09 | E41: 9 | F41: 1031 | G41: 356 | H41: 3616 | I41: 6329 | J41: 1192 | K41: 1545 | L41: 4 | M41: 4 | N41: 4 | O41: 0 | P41: 0 | Q41: 0 | R41: 14081 | S41: 0.56516155 | T41: 55 | U41: Global Follow Up · frozen weekly history
A42: PDE | B42: Prugent Diam Europe | C42: Europe | D42: W10 | E42: 10 | F42: 1031 | G42: 312 | H42: 3570 | I42: 5799 | J42: 1801 | K42: 1714 | L42: 4 | M42: 4 | N42: 4 | O42: 0 | P42: 0 | Q42: 0 | R42: 14239 | S42: 0.57150311 | T42: 158 | U42: Global Follow Up · frozen weekly history
A43: PDE | B43: Prugent Diam Europe | C43: Europe | D43: W11 | E43: 11 | F43: 1031 | G43: 312 | H43: 3570 | I43: 5799 | J43: 1801 | K43: 1714 | L43: 4 | M43: 4 | N43: 4 | O43: 0 | P43: 0 | Q43: 0 | R43: 14239 | S43: 0.57150311 | T43: 0 | U43: Global Follow Up · frozen weekly history
A44: PDE | B44: Prugent Diam Europe | C44: Europe | D44: W12 | E44: 12 | F44: 1031 | G44: 312 | H44: 3565 | I44: 5824 | J44: 2090 | K44: 1243 | L44: 628 | M44: 4 | N44: 4 | O44: 0 | P44: 0 | Q44: 0 | R44: 14701 | S44: 0.59004616 | T44: 462 | U44: Global Follow Up · frozen weekly history
A45: PDE | B45: Prugent Diam Europe | C45: Europe | D45: W13 | E45: 13 | F45: 1031 | G45: 312 | H45: 3457 | I45: 5943 | J45: 2107 | K45: 1250 | L45: 635 | M45: 4 | N45: 4 | O45: 0 | P45: 0 | Q45: 0 | R45: 14743 | S45: 0.59173189 | T45: 42 | U45: Global Follow Up · frozen weekly history
A46: PDE | B46: Prugent Diam Europe | C46: Europe | D46: W14 | E46: 14 | F46: 1031 | G46: 312 | H46: 3238 | I46: 6154 | J46: 1518 | K46: 1866 | L46: 635 | M46: 4 | N46: 4 | O46: 0 | P46: 0 | Q46: 0 | R46: 14762 | S46: 0.59249448 | T46: 19 | U46: Global Follow Up · frozen weekly history
A47: PDE | B47: Prugent Diam Europe | C47: Europe | D47: W15 | E47: 15 | F47: 1031 | G47: 312 | H47: 3234 | I47: 6154.3 | J47: 1487 | K47: 2404 | L47: 184 | M47: 4 | N47: 4 | O47: 0 | P47: 0 | Q47: 0 | R47: 14814.3 | S47: 0.59459362 | T47: 52.3 | U47: Global Follow Up · frozen weekly history
A48: PDE | B48: Prugent Diam Europe | C48: Europe | D48: W16 | E48: 16 | F48: 1031 | G48: 312 | H48: 3234 | I48: 6199.3 | J48: 1491 | K48: 2414 | L48: 184 | M48: 4 | N48: 4 | O48: 0 | P48: 0 | Q48: 0 | R48: 14873.3 | S48: 0.59696167 | T48: 59 | U48: Global Follow Up · frozen weekly history
A49: PDE | B49: Prugent Diam Europe | C49: Europe | D49: W17 | E49: 17 | F49: 1031 | G49: 312 | H49: 3234 | I49: 6199.3 | J49: 1491 | K49: 2414 | L49: 199 | M49: 4 | N49: 4 | O49: 0 | P49: 0 | Q49: 0 | R49: 14888.3 | S49: 0.59756372 | T49: 15 | U49: Global Follow Up · frozen weekly history
... A67: PDE | B67: Prugent Diam Europe | C67: Europe | D67: W35 | E67: 35 | F67: 1031 | G67: 312 | H67: 3234 | I67: 6046 | J67: 1581 | K67: 2336 | L67: 768.10195 | M67: 585.89805 | N67: 2456 | O67: 903 | P67: 735 | Q67: 78 | R67: 20066 | S67: 0.80537829 | T67: 44 | U67: Jan–Jun Global Follow Up · Jul–Dec entity dashboards
A68: PDE | B68: Prugent Diam Europe | C68: Europe | D68: P1 W35 | E68: 35 | F68: 0 | G68: 0 | H68: 0 | I68: 0 | J68: 0 | K68: 0 | L68: 0 | M68: 5 | N68: 15 | O68: 40 | P68: 223 | Q68: 510 | R68: 793 | U68: Pipeline workbook
A69: PDE | B69: Prugent Diam Europe | C69: Europe | D69: Sales + P1 W35 | E69: 35 | F69: 1031 | G69: 312 | H69: 3234 | I69: 6046 | J69: 1581 | K69: 2336 | L69: 768.10195 | M69: 590.89805 | N69: 2471 | O69: 943 | P69: 958 | Q69: 588 | R69: 20859 | S69: 0.8372065 | U69: Hybrid monthly history + pipeline workbook
A70: PDP | B70: Prugent Diam Portugal | C70: Europe | D70: Budget | E70: 0 | F70: 1200 | G70: 1350 | H70: 1550 | I70: 1650 | J70: 1750 | K70: 1350 | L70: 1100 | M70: 200 | N70: 1700 | O70: 1750 | P70: 700 | Q70: 200 | R70: 14500 | U70: Approved Budget 2026
A71: PDP | B71: Prugent Diam Portugal | C71: Europe | D71: W05 | E71: 5 | F71: 641 | G71: 1555 | H71: 788 | I71: 1676 | J71: 761 | K71: 61 | L71: 301 | M71: 0 | N71: 0 | O71: 0 | P71: 0 | Q71: 133 | R71: 5916 | S71: 0.408 | U71: Global Follow Up · frozen weekly history
A72: PDP | B72: Prugent Diam Portugal | C72: Europe | D72: W06 | E72: 6 | F72: 624 | G72: 1559 | H72: 788 | I72: 1594 | J72: 857 | K72: 61 | L72: 301 | M72: 0 | N72: 0 | O72: 0 | P72: 0 | Q72: 133 | R72: 5917 | S72: 0.40806897 | T72: 1 | U72: Global Follow Up · frozen weekly history
A73: PDP | B73: Prugent Diam Portugal | C73: Europe | D73: W07 | E73: 7 | F73: 524 | G73: 575 | H73: 1685 | I73: 1585 | J73: 1210 | K73: 60 | L73: 290 | M73: 0 | N73: 0 | O73: 0 | P73: 0 | Q73: 130 | R73: 6059 | S73: 0.41786207 | T73: 142 | U73: Global Follow Up · frozen weekly history
A74: PDP | B74: Prugent Diam Portugal | C74: Europe | D74: W08 | E74: 8 | F74: 524 | G74: 620 | H74: 1640 | I74: 1755 | J74: 995 | K74: 60 | L74: 290 | M74: 0 | N74: 0 | O74: 0 | P74: 0 | Q74: 130 | R74: 6014 | S74: 0.41475862 | T74: -45 | U74: Global Follow Up · frozen weekly history
...

Sheet Budget Recap
A1: DIAM · BUDGET RECAP
A3: W35 · 30 Aug 2026 · Global view · All sales · Sales + P1 · Reporting unit EUR K · FX 1 EUR = 1.18 USD
A5: MONTHLY POSITION · EUR K
A6: Jan–Jun 2026 is the frozen Global Follow Up management baseline; Jul–Dec follows the current entity-dashboard snapshot.
A7: Region | B7: Business Unit | C7: Metric | D7: Jan | E7: Feb | F7: Mar | G7: Apr | H7: May | I7: Jun | J7: Jul | K7: Aug | L7: Sep | M7: Oct | N7: Nov | O7: Dec | P7: FY Total | Q7: Coverage | R7: Gap
A8: Asia | B8: PDA · Asia (PDA + PDN + PGC) | C8: Budget | D8: 842.1969 | E8: 889.09173 | F8: 920.68852 | G8: 912.37542 | H8: 873.5492 | I8: 937.03791 | J8: 877.69877 | K8: 889.68641 | L8: 867.79987 | M8: 845.67323 | N8: 853.76019 | O8: 917.50696 | P8: 10627.065
C9: Sales | D9: 310 | E9: 49 | F9: 251 | G9: 328 | H9: 242 | I9: 665 | J9: 118.9134 | K9: 77 | L9: 602 | M9: 167 | N9: 90 | O9: 62 | P9: 2961.9134
C10: P1 | D10: 0 | E10: 0 | F10: 1 | G10: 0 | H10: 0 | I10: 0 | J10: 0 | K10: 0 | L10: 56 | M10: 53 | N10: 155 | O10: 6 | P10: 271
C11: Sales + P1 | D11: 310 | E11: 49 | F11: 252 | G11: 328 | H11: 242 | I11: 665 | J11: 118.9134 | K11: 77 | L11: 658 | M11: 220 | N11: 245 | O11: 68 | P11: 3232.9134 | Q11: 0.30421507 | R11: -7394.1517
A12: Europe | B12: PDE · Prugent Diam Europe | C12: Budget | D12: 1610 | E12: 1250 | F12: 1905 | G12: 5110 | H12: 1950 | I12: 2600 | J12: 1360 | K12: 1100 | L12: 2300 | M12: 1250 | N12: 2480 | O12: 2000 | P12: 24915
C13: Sales | D13: 1031 | E13: 312 | F13: 3234 | G13: 6046 | H13: 1581 | I13: 2336 | J13: 768.10195 | K13: 585.89805 | L13: 2456 | M13: 903 | N13: 735 | O13: 78 | P13: 20066
C14: P1 | D14: 0 | E14: 0 | F14: 0 | G14: 0 | H14: 0 | I14: 0 | J14: 0 | K14: 5 | L14: 15 | M14: 40 | N14: 223 | O14: 510 | P14: 793
C15: Sales + P1 | D15: 1031 | E15: 312 | F15: 3234 | G15: 6046 | H15: 1581 | I15: 2336 | J15: 768.10195 | K15: 590.89805 | L15: 2471 | M15: 943 | N15: 958 | O15: 588 | P15: 20859 | Q15: 0.8372065 | R15: -4056
A16: Europe | B16: PDP · Prugent Diam Portugal | C16: Budget | D16: 1200 | E16: 1350 | F16: 1550 | G16: 1650 | H16: 1750 | I16: 1350 | J16: 1100 | K16: 200 | L16: 1700 | M16: 1750 | N16: 700 | O16: 200 | P16: 14500
C17: Sales | D17: 524 | E17: 677 | F17: 1167 | G17: 1565 | H17: 1145 | I17: 620 | J17: 1035.3975 | K17: 525 | L17: 1240 | M17: 895 | N17: 995 | O17: 265 | P17: 10653.398
C18: P1 | D18: 0 | E18: 0 | F18: 0 | G18: 0 | H18: 0 | I18: 0 | J18: 0 | K18: 0 | L18: 0 | M18: 138 | N18: 173 | O18: 175 | P18: 486
C19: Sales + P1 | D19: 524 | E19: 677 | F19: 1167 | G19: 1565 | H19: 1145 | I19: 620 | J19: 1035.3975 | K19: 525 | L19: 1240 | M19: 1033 | N19: 1168 | O19: 440 | P19: 11139.398 | Q19: 0.76823431 | R19: -3360.6025
A20: Europe | B20: PSG · Prugent Services GmbH | C20: Budget | D20: 70 | E20: 190 | F20: 215 | G20: 130 | H20: 140 | I20: 100 | J20: 80 | K20: 90 | L20: 190 | M20: 120 | N20: 110 | O20: 65 | P20: 1500
C21: Sales | D21: 104 | E21: 84 | F21: 216 | G21: 157 | H21: 170 | I21: 185 | J21: 146.2 | K21: 161.8 | L21: 128 | M21: 120 | N21: 160 | O21: 51 | P21: 1683
C22: P1 | D22: 0 | E22: 0 | F22: 0 | G22: 0 | H22: 0 | I22: 0 | J22: 0 | K22: 0 | L22: 0 | M22: 0 | N22: 0 | O22: 0 | P22: 0
C23: Sales + P1 | D23: 104 | E23: 84 | F23: 216 | G23: 157 | H23: 170 | I23: 185 | J23: 146.2 | K23: 161.8 | L23: 128 | M23: 120 | N23: 160 | O23: 51 | P23: 1683 | Q23: 1.122 | R23: 183
A24: Americas | B24: PUS · Prugent America | C24: Budget | D24: 542.90126 | E24: 620.45859 | F24: 542.90126 | G24: 517.04882 | H24: 499.81386 | I24: 534.28378 | J24: 499.81386 | K24: 517.04882 | L24: 499.81386 | M24: 534.28378 | N24: 499.81386 | O24: 517.04882 | P24: 6325.2306
C25: Sales | D25: 461 | E25: 517 | F25: 484.89142 | G25: 502.57742 | H25: 535.03142 | I25: 516.38732 | J25: 419.42227 | K25: 597.27353 | L25: 594.67924 | M25: 634.21935 | N25: 568.13985 | O25: 601.76692 | P25: 6432.3887
C26: P1 | D26: 0 | E26: 0 | F26: 0 | G26: 0 | H26: 0 | I26: 0 | J26: 0 | K26: 0 | L26: 0 | M26: 0 | N26: 0 | O26: 0 | P26: 0
C27: Sales + P1 | D27: 461 | E27: 517 | F27: 484.89142 | G27: 502.57742 | H27: 535.03142 | I27: 516.38732 | J27: 419.42227 | K27: 597.27353 | L27: 594.67924 | M27: 634.21935 | N27: 568.13985 | O27: 601.76692 | P27: 6432.3887 | Q27: 1.0169414 | R27: 107.15813
A28: Americas | B28: DMX · Diam Mexico | C28: Budget | D28: 569.48266 | E28: 802.65089 | F28: 934.82847 | G28: 979.17813 | H28: 830.12291 | I28: 830.12291 | J28: 919.51018 | K28: 822.50963 | L28: 1365.1624 | M28: 1338.4241 | N28: 1337.6903 | O28: 589.34141 | P28: 11319.024
C29: Sales | D29: 666 | E29: 734.83644 | F29: 442.37288 | G29: 431 | H29: 462 | I29: 980.50847 | J29: 599.3839 | K29: 545.82742 | L29: 1646.6921 | M29: 1524.4958 | N29: 1655.2451 | O29: 1511.2822 | P29: 11199.644
C30: P1 | D30: 0 | E30: 0 | F30: 0 | G30: 0 | H30: 0 | I30: 0 | J30: 0 | K30: 0 | L30: 0 | M30: 0 | N30: 0 | O30: 120 | P30: 120
C31: Sales + P1 | D31: 666 | E31: 734.83644 | F31: 442.37288 | G31: 431 | H31: 462 | I31: 980.50847 | J31: 599.3839 | K31: 545.82742 | L31: 1646.6921 | M31: 1524.4958 | N31: 1655.2451 | O31: 1631.2822 | P31: 11319.644 | Q31: 1.0000548 | R31: 0.6203067
A32: Americas | B32: DBR · Diam Brazil | C32: Budget | D32: 1539.9073 | E32: 1500.2927 | F32: 1596.2284 | G32: 1874.2901 | H32: 1326.8997 | I32: 963.53367 | J32: 1465.7406 | K32: 1305.2572 | L32: 1142.8752 | M32: 1004.9202 | N32: 753.94327 | O32: 949.9913 | P32: 15423.88
C33: Sales | D33: 1324 | E33: 1257 | F33: 1091 | G33: 2177 | H33: 1150 | I33: 1259 | J33: 2194.4483 | K33: 1492.6836 | L33: 1487.992 | M33: 1164.9985 | N33: 306.95796 | O33: 149.89878 | P33: 15054.979
C34: P1 | D34: 0 | E34: 0 | F34: 0 | G34: 0 | H34: 0 | I34: 0 | J34: 0 | K34: 0 | L34: 0 | M34: 139 | N34: 37 | O34: 0 | P34: 176
C35: Sales + P1 | D35: 1324 | E35: 1257 | F35: 1091 | G35: 2177 | H35: 1150 | I35: 1259 | J35: 2194.4483 | K35: 1492.6836 | L35: 1487.992 | M35: 1303.9985 | N35: 343.95796 | O35: 149.89878 | P35: 15230.979 | Q35: 0.9874934 | R35: -192.90036
A36: Americas | B36: FFLEX · Fieldflex USA | C36: Budget | D36: 200 | E36: 200 | F36: 200 | G36: 200 | H36: 200 | I36: 200 | J36: 200 | K36: 200 | L36: 200 | M36: 200 | N36: 200 | O36: 200 | P36: 2400
C37: Sales | D37: 87.572356 | E37: 94.44778 | F37: 128.89501 | G37: 110.92606 | H37: 134.52164 | I37: 161.11546 | J37: 116.59734 | K37: 173.17703 | L37: 621.6931 | M37: 399.71967 | N37: 7.5179915 | O37: 28.813559 | P37: 2064.997
C38: P1 | D38: 0 | E38: 0 | F38: 0 | G38: 0 | H38: 0 | I38: 0 | J38: 0 | K38: 0 | L38: 0 | M38: 0 | N38: 0 | O38: 0 | P38: 0
C39: Sales + P1 | D39: 87.572356 | E39: 94.44778 | F39: 128.89501 | G39: 110.92606 | H39: 134.52164 | I39: 161.11546 | J39: 116.59734 | K39: 173.17703 | L39: 621.6931 | M39: 399.71967 | N39: 7.5179915 | O39: 28.813559 | P39: 2064.997 | Q39: 0.86041541 | R39: -335.00301
A42: CUMULATIVE BY REGION · EUR K
A44: Region | B44: Metric | C44: Jan | D44: Feb | E44: Mar | F44: Apr | G44: May | H44: Jun | I44: Jul | J44: Aug | K44: Sep | L44: Oct | M44: Nov | N44: Dec | O44: FY Total
A45: Asia | B45: Budget | C45: 842.1969 | D45: 1731.2886 | E45: 2651.9771 | F45: 3564.3526 | G45: 4437.9018 | H45: 5374.9397 | I45: 6252.6384 | J45: 7142.3248 | K45: 8010.1247 | L45: 8855.7979 | M45: 9709.5581 | N45: 10627.065 | O45: 10627.065
...

Sheet Chart Data
A1: Region | B1: Metric | C1: Jan | D1: Feb | E1: Mar | F1: Apr | G1: May | H1: Jun | I1: Jul | J1: Aug | K1: Sep | L1: Oct | M1: Nov | N1: Dec | P1: Business Unit | Q1: Metric | R1: Jan | S1: Feb | T1: Mar | U1: Apr | V1: May | W1: Jun | X1: Jul | Y1: Aug | Z1: Sep | AA1: Oct | AB1: Nov | AC1: Dec | AE1: Month | AF1: Budget | AG1: Sales | AH1: Sales + P1 | AJ1: Month | AK1: Budget | AL1: Sales | AM1: Sales + P1
A2: Asia | B2: Budget | C2: 842.1969 | D2: 1731.2886 | E2: 2651.9771 | F2: 3564.3526 | G2: 4437.9018 | H2: 5374.9397 | I2: 6252.6384 | J2: 7142.3248 | K2: 8010.1247 | L2: 8855.7979 | M2: 9709.5581 | N2: 10627.065 | P2: PDA | Q2: Budget | R2: 842.1969 | S2: 1731.2886 | T2: 2651.9771 | U2: 3564.3526 | V2: 4437.9018 | W2: 5374.9397 | X2: 6252.6384 | Y2: 7142.3248 | Z2: 8010.1247 | AA2: 8855.7979 | AB2: 9709.5581 | AC2: 10627.065 | AE2: Jan | AF2: =SUMIFS($C$2:$C$10,$A$2:$A$10,'Budget Recap'!$B$58,$B$2:$B$10,AF$1) -> 842.1969 | AG2: =SUMIFS($C$2:$C$10,$A$2:$A$10,'Budget Recap'!$B$58,$B$2:$B$10,AG$1) -> 310 | AH2: =SUMIFS($C$2:$C$10,$A$2:$A$10,'Budget Recap'!$B$58,$B$2:$B$10,AH$1) -> 310 | AJ2: Jan | AK2: =SUMIFS($R$2:$R$25,$P$2:$P$25,'Budget Recap'!$K$58,$Q$2:$Q$25,AK$1) -> 842.1969 | AL2: =SUMIFS($R$2:$R$25,$P$2:$P$25,'Budget Recap'!$K$58,$Q$2:$Q$25,AL$1) -> 310 | AM2: =SUMIFS($R$2:$R$25,$P$2:$P$25,'Budget Recap'!$K$58,$Q$2:$Q$25,AM$1) -> 310
A3: Asia | B3: Sales | C3: 310 | D3: 359 | E3: 610 | F3: 938 | G3: 1180 | H3: 1845 | I3: 1963.9134 | J3: 2040.9134 | K3: 2642.9134 | L3: 2809.9134 | M3: 2899.9134 | N3: 2961.9134 | P3: PDA | Q3: Sales | R3: 310 | S3: 359 | T3: 610 | U3: 938 | V3: 1180 | W3: 1845 | X3: 1963.9134 | Y3: 2040.9134 | Z3: 2642.9134 | AA3: 2809.9134 | AB3: 2899.9134 | AC3: 2961.9134 | AE3: Feb | AF3: =SUMIFS($D$2:$D$10,$A$2:$A$10,'Budget Recap'!$B$58,$B$2:$B$10,AF$1) -> 1731.2886 | AG3: =SUMIFS($D$2:$D$10,$A$2:$A$10,'Budget Recap'!$B$58,$B$2:$B$10,AG$1) -> 359 | AH3: =SUMIFS($D$2:$D$10,$A$2:$A$10,'Budget Recap'!$B$58,$B$2:$B$10,AH$1) -> 359 | AJ3: Feb | AK3: =SUMIFS($S$2:$S$25,$P$2:$P$25,'Budget Recap'!$K$58,$Q$2:$Q$25,AK$1) -> 1731.2886 | AL3: =SUMIFS($S$2:$S$25,$P$2:$P$25,'Budget Recap'!$K$58,$Q$2:$Q$25,AL$1) -> 359 | AM3: =SUMIFS($S$2:$S$25,$P$2:$P$25,'Budget Recap'!$K$58,$Q$2:$Q$25,AM$1) -> 359
A4: Asia | B4: Sales + P1 | C4: 310 | D4: 359 | E4: 611 | F4: 939 | G4: 1181 | H4: 1846 | I4: 1964.9134 | J4: 2041.9134 | K4: 2699.9134 | L4: 2919.9134 | M4: 3164.9134 | N4: 3232.9134 | P4: PDA | Q4: Sales + P1 | R4: 310 | S4: 359 | T4: 611 | U4: 939 | V4: 1181 | W4: 1846 | X4: 1964.9134 | Y4: 2041.9134 | Z4: 2699.9134 | AA4: 2919.9134 | AB4: 3164.9134 | AC4: 3232.9134 | AE4: Mar | AF4: =SUMIFS($E$2:$E$10,$A$2:$A$10,'Budget Recap'!$B$58,$B$2:$B$10,AF$1) -> 2651.9771 | AG4: =SUMIFS($E$2:$E$10,$A$2:$A$10,'Budget Recap'!$B$58,$B$2:$B$10,AG$1) -> 610 | AH4: =SUMIFS($E$2:$E$10,$A$2:$A$10,'Budget Recap'!$B$58,$B$2:$B$10,AH$1) -> 611 | AJ4: Mar | AK4: =SUMIFS($T$2:$T$25,$P$2:$P$25,'Budget Recap'!$K$58,$Q$2:$Q$25,AK$1) -> 2651.9771 | AL4: =SUMIFS($T$2:$T$25,$P$2:$P$25,'Budget Recap'!$K$58,$Q$2:$Q$25,AL$1) -> 610 | AM4: =SUMIFS($T$2:$T$25,$P$2:$P$25,'Budget Recap'!$K$58,$Q$2:$Q$25,AM$1) -> 611
A5: Europe | B5: Budget | C5: 2880 | D5: 5670 | E5: 9340 | F5: 16230 | G5: 20070 | H5: 24120 | I5: 26660 | J5: 28050 | K5: 32240 | L5: 35360 | M5: 38650 | N5: 40915 | P5: PDE | Q5: Budget | R5: 1610 | S5: 2860 | T5: 4765 | U5: 9875 | V5: 11825 | W5: 14425 | X5: 15785 | Y5: 16885 | Z5: 19185 | AA5: 20435 | AB5: 22915 | AC5: 24915 | AE5: Apr | AF5: =SUMIFS($F$2:$F$10,$A$2:$A$10,'Budget Recap'!$B$58,$B$2:$B$10,AF$1) -> 3564.3526 | AG5: =SUMIFS($F$2:$F$10,$A$2:$A$10,'Budget Recap'!$B$58,$B$2:$B$10,AG$1) -> 938 | AH5: =SUMIFS($F$2:$F$10,$A$2:$A$10,'Budget Recap'!$B$58,$B$2:$B$10,AH$1) -> 939 | AJ5: Apr | AK5: =SUMIFS($U$2:$U$25,$P$2:$P$25,'Budget Recap'!$K$58,$Q$2:$Q$25,AK$1) -> 3564.3526 | AL5: =SUMIFS($U$2:$U$25,$P$2:$P$25,'Budget Recap'!$K$58,$Q$2:$Q$25,AL$1) -> 938 | AM5: =SUMIFS($U$2:$U$25,$P$2:$P$25,'Budget Recap'!$K$58,$Q$2:$Q$25,AM$1) -> 939
A6: Europe | B6: Sales | C6: 1659 | D6: 2732 | E6: 7349 | F6: 15117 | G6: 18013 | H6: 21154 | I6: 23103.699 | J6: 24376.398 | K6: 28200.398 | L6: 30118.398 | M6: 32008.398 | N6: 32402.398 | P6: PDE | Q6: Sales | R6: 1031 | S6: 1343 | T6: 4577 | U6: 10623 | V6: 12204 | W6: 14540 | X6: 15308.102 | Y6: 15894 | Z6: 18350 | AA6: 19253 | AB6: 19988 | AC6: 20066 | AE6: May | AF6: =SUMIFS($G$2:$G$10,$A$2:$A$10,'Budget Recap'!$B$58,$B$2:$B$10,AF$1) -> 4437.9018 | AG6: =SUMIFS($G$2:$G$10,$A$2:$A$10,'Budget Recap'!$B$58,$B$2:$B$10,AG$1) -> 1180 | AH6: =SUMIFS($G$2:$G$10,$A$2:$A$10,'Budget Recap'!$B$58,$B$2:$B$10,AH$1) -> 1181 | AJ6: May | AK6: =SUMIFS($V$2:$V$25,$P$2:$P$25,'Budget Recap'!$K$58,$Q$2:$Q$25,AK$1) -> 4437.9018 | AL6: =SUMIFS($V$2:$V$25,$P$2:$P$25,'Budget Recap'!$K$58,$Q$2:$Q$25,AL$1) -> 1180 | AM6: =SUMIFS($V$2:$V$25,$P$2:$P$25,'Budget Recap'!$K$58,$Q$2:$Q$25,AM$1) -> 1181
A7: Europe | B7: Sales + P1 | C7: 1659 | D7: 2732 | E7: 7349 | F7: 15117 | G7: 18013 | H7: 21154 | I7: 23103.699 | J7: 24381.398 | K7: 28220.398 | L7: 30316.398 | M7: 32602.398 | N7: 33681.398 | P7: PDE | Q7: Sales + P1 | R7: 1031 | S7: 1343 | T7: 4577 | U7: 10623 | V7: 12204 | W7: 14540 | X7: 15308.102 | Y7: 15899 | Z7: 18370 | AA7: 19313 | AB7: 20271 | AC7: 20859 | AE7: Jun | AF7: =SUMIFS($H$2:$H$10,$A$2:$A$10,'Budget Recap'!$B$58,$B$2:$B$10,AF$1) -> 5374.9397 | AG7: =SUMIFS($H$2:$H$10,$A$2:$A$10,'Budget Recap'!$B$58,$B$2:$B$10,AG$1) -> 1845 | AH7: =SUMIFS($H$2:$H$10,$A$2:$A$10,'Budget Recap'!$B$58,$B$2:$B$10,AH$1) -> 1846 | AJ7: Jun | AK7: =SUMIFS($W$2:$W$25,$P$2:$P$25,'Budget Recap'!$K$58,$Q$2:$Q$25,AK$1) -> 5374.9397 | AL7: =SUMIFS($W$2:$W$25,$P$2:$P$25,'Budget Recap'!$K$58,$Q$2:$Q$25,AL$1) -> 1845 | AM7: =SUMIFS($W$2:$W$25,$P$2:$P$25,'Budget Recap'!$K$58,$Q$2:$Q$25,AM$1) -> 1846
A8: Americas | B8: Budget | C8: 2852.2912 | D8: 5975.6934 | E8: 9249.6515 | F8: 12820.169 | G8: 15677.005 | H8: 18204.945 | I8: 21290.01 | J8: 24134.826 | K8: 27342.677 | L8: 30420.305 | M8: 33211.753 | N8: 35468.134 | P8: PDP | Q8: Budget | R8: 1200 | S8: 2550 | T8: 4100 | U8: 5750 | V8: 7500 | W8: 8850 | X8: 9950 | Y8: 10150 | Z8: 11850 | AA8: 13600 | AB8: 14300 | AC8: 14500 | AE8: Jul | AF8: =SUMIFS($I$2:$I$10,$A$2:$A$10,'Budget Recap'!$B$58,$B$2:$B$10,AF$1) -> 6252.6384 | AG8: =SUMIFS($I$2:$I$10,$A$2:$A$10,'Budget Recap'!$B$58,$B$2:$B$10,AG$1) -> 1963.9134 | AH8: =SUMIFS($I$2:$I$10,$A$2:$A$10,'Budget Recap'!$B$58,$B$2:$B$10,AH$1) -> 1964.9134 | AJ8: Jul | AK8: =SUMIFS($X$2:$X$25,$P$2:$P$25,'Budget Recap'!$K$58,$Q$2:$Q$25,AK$1) -> 6252.6384 | AL8: =SUMIFS($X$2:$X$25,$P$2:$P$25,'Budget Recap'!$K$58,$Q$2:$Q$25,AL$1) -> 1963.9134 | AM8: =SUMIFS($X$2:$X$25,$P$2:$P$25,'Budget Recap'!$K$58,$Q$2:$Q$25,AM$1) -> 1964.9134
A9: Americas | B9: Sales | C9: 2538.5724 | D9: 5141.8566 | E9: 7289.0159 | F9: 10510.519 | G9: 12792.072 | H9: 15709.084 | I9: 19038.936 | J9: 21847.897 | K9: 26198.954 | L9: 29922.387 | M9: 32460.248 | N9: 34752.009 | P9: PDP | Q9: Sales | R9: 524 | S9: 1201 | T9: 2368 | U9: 3933 | V9: 5078 | W9: 5698 | X9: 6733.3975 | Y9: 7258.3975 | Z9: 8498.3975 | AA9: 9393.3975 | AB9: 10388.398 | AC9: 10653.398 | AE9: Aug | AF9: =SUMIFS($J$2:$J$10,$A$2:$A$10,'Budget Recap'!$B$58,$B$2:$B$10,AF$1) -> 7142.3248 | AG9: =SUMIFS($J$2:$J$10,$A$2:$A$10,'Budget Recap'!$B$58,$B$2:$B$10,AG$1) -> 2040.9134 | AH9: =SUMIFS($J$2:$J$10,$A$2:$A$10,'Budget Recap'!$B$58,$B$2:$B$10,AH$1) -> 2041.9134 | AJ9: Aug | AK9: =SUMIFS($Y$2:$Y$25,$P$2:$P$25,'Budget Recap'!$K$58,$Q$2:$Q$25,AK$1) -> 7142.3248 | AL9: =SUMIFS($Y$2:$Y$25,$P$2:$P$25,'Budget Recap'!$K$58,$Q$2:$Q$25,AL$1) -> 2040.9134 | AM9: =SUMIFS($Y$2:$Y$25,$P$2:$P$25,'Budget Recap'!$K$58,$Q$2:$Q$25,AM$1) -> 2041.9134
A10: Americas | B10: Sales + P1 | C10: 2538.5724 | D10: 5141.8566 | E10: 7289.0159 | F10: 10510.519 | G10: 12792.072 | H10: 15709.084 | I10: 19038.936 | J10: 21847.897 | K10: 26198.954 | L10: 30061.387 | M10: 32636.248 | N10: 35048.009 | P10: PDP | Q10: Sales + P1 | R10: 524 | S10: 1201 | T10: 2368 | U10: 3933 | V10: 5078 | W10: 5698 | X10: 6733.3975 | Y10: 7258.3975 | Z10: 8498.3975 | AA10: 9531.3975 | AB10: 10699.398 | AC10: 11139.398 | AE10: Sep | AF10: =SUMIFS($K$2:$K$10,$A$2:$A$10,'Budget Recap'!$B$58,$B$2:$B$10,AF$1) -> 8010.1247 | AG10: =SUMIFS($K$2:$K$10,$A$2:$A$10,'Budget Recap'!$B$58,$B$2:$B$10,AG$1) -> 2642.9134 | AH10: =SUMIFS($K$2:$K$10,$A$2:$A$10,'Budget Recap'!$B$58,$B$2:$B$10,AH$1) -> 2699.9134 | AJ10: Sep | AK10: =SUMIFS($Z$2:$Z$25,$P$2:$P$25,'Budget Recap'!$K$58,$Q$2:$Q$25,AK$1) -> 8010.1247 | AL10: =SUMIFS($Z$2:$Z$25,$P$2:$P$25,'Budget Recap'!$K$58,$Q$2:$Q$25,AL$1) -> 2642.9134 | AM10: =SUMIFS($Z$2:$Z$25,$P$2:$P$25,'Budget Recap'!$K$58,$Q$2:$Q$25,AM$1) -> 2699.9134
P11: PSG | Q11: Budget | R11: 70 | S11: 260 | T11: 475 | U11: 605 | V11: 745 | W11: 845 | X11: 925 | Y11: 1015 | Z11: 1205 | AA11: 1325 | AB11: 1435 | AC11: 1500 | AE11: Oct | AF11: =SUMIFS($L$2:$L$10,$A$2:$A$10,'Budget Recap'!$B$58,$B$2:$B$10,AF$1) -> 8855.7979 | AG11: =SUMIFS($L$2:$L$10,$A$2:$A$10,'Budget Recap'!$B$58,$B$2:$B$10,AG$1) -> 2809.9134 | AH11: =SUMIFS($L$2:$L$10,$A$2:$A$10,'Budget Recap'!$B$58,$B$2:$B$10,AH$1) -> 2919.9134 | AJ11: Oct | AK11: =SUMIFS($AA$2:$AA$25,$P$2:$P$25,'Budget Recap'!$K$58,$Q$2:$Q$25,AK$1) -> 8855.7979 | AL11: =SUMIFS($AA$2:$AA$25,$P$2:$P$25,'Budget Recap'!$K$58,$Q$2:$Q$25,AL$1) -> 2809.9134 | AM11: =SUMIFS($AA$2:$AA$25,$P$2:$P$25,'Budget Recap'!$K$58,$Q$2:$Q$25,AM$1) -> 2919.9134
P12: PSG | Q12: Sales | R12: 104 | S12: 188 | T12: 404 | U12: 561 | V12: 731 | W12: 916 | X12: 1062.2 | Y12: 1224 | Z12: 1352 | AA12: 1472 | AB12: 1632 | AC12: 1683 | AE12: Nov | AF12: =SUMIFS($M$2:$M$10,$A$2:$A$10,'Budget Recap'!$B$58,$B$2:$B$10,AF$1) -> 9709.5581 | AG12: =SUMIFS($M$2:$M$10,$A$2:$A$10,'Budget Recap'!$B$58,$B$2:$B$10,AG$1) -> 2899.9134 | AH12: =SUMIFS($M$2:$M$10,$A$2:$A$10,'Budget Recap'!$B$58,$B$2:$B$10,AH$1) -> 3164.9134 | AJ12: Nov | AK12: =SUMIFS($AB$2:$AB$25,$P$2:$P$25,'Budget Recap'!$K$58,$Q$2:$Q$25,AK$1) -> 9709.5581 | AL12: =SUMIFS($AB$2:$AB$25,$P$2:$P$25,'Budget Recap'!$K$58,$Q$2:$Q$25,AL$1) -> 2899.9134 | AM12: =SUMIFS($AB$2:$AB$25,$P$2:$P$25,'Budget Recap'!$K$58,$Q$2:$Q$25,AM$1) -> 3164.9134
P13: PSG | Q13: Sales + P1 | R13: 104 | S13: 188 | T13: 404 | U13: 561 | V13: 731 | W13: 916 | X13: 1062.2 | Y13: 1224 | Z13: 1352 | AA13: 1472 | AB13: 1632 | AC13: 1683 | AE13: Dec | AF13: =SUMIFS($N$2:$N$10,$A$2:$A$10,'Budget Recap'!$B$58,$B$2:$B$10,AF$1) -> 10627.065 | AG13: =SUMIFS($N$2:$N$10,$A$2:$A$10,'Budget Recap'!$B$58,$B$2:$B$10,AG$1) -> 2961.9134 | AH13: =SUMIFS($N$2:$N$10,$A$2:$A$10,'Budget Recap'!$B$58,$B$2:$B$10,AH$1) -> 3232.9134 | AJ13: Dec | AK13: =SUMIFS($AC$2:$AC$25,$P$2:$P$25,'Budget Recap'!$K$58,$Q$2:$Q$25,AK$1) -> 10627.065 | AL13: =SUMIFS($AC$2:$AC$25,$P$2:$P$25,'Budget Recap'!$K$58,$Q$2:$Q$25,AL$1) -> 2961.9134 | AM13: =SUMIFS($AC$2:$AC$25,$P$2:$P$25,'Budget Recap'!$K$58,$Q$2:$Q$25,AM$1) -> 3232.9134
P14: PUS | Q14: Budget | R14: 542.90126 | S14: 1163.3599 | T14: 1706.2611 | U14: 2223.3099 | V14: 2723.1238 | W14: 3257.4076 | X14: 3757.2214 | Y14: 4274.2703 | Z14: 4774.0841 | AA14: 5308.3679 | AB14: 5808.1818 | AC14: 6325.2306
P15: PUS | Q15: Sales | R15: 461 | S15: 978 | T15: 1462.8914 | U15: 1965.4688 | V15: 2500.5003 | W15: 3016.8876 | X15: 3436.3098 | Y15: 4033.5834 | Z15: 4628.2626 | AA15: 5262.482 | AB15: 5830.6218 | AC15: 6432.3887
P16: PUS | Q16: Sales + P1 | R16: 461 | S16: 978 | T16: 1462.8914 | U16: 1965.4688 | V16: 2500.5003 | W16: 3016.8876 | X16: 3436.3098 | Y16: 4033.5834 | Z16: 4628.2626 | AA16: 5262.482 | AB16: 5830.6218 | AC16: 6432.3887
P17: DMX | Q17: Budget | R17: 569.48266 | S17: 1372.1336 | T17: 2306.962 | U17: 3286.1402 | V17: 4116.2631 | W17: 4946.386 | X17: 5865.8962 | Y17: 6688.4058 | Z17: 8053.5682 | AA17: 9391.9923 | AB17: 10729.683 | AC17: 11319.024
P18: DMX | Q18: Sales | R18: 666 | S18: 1400.8364 | T18: 1843.2093 | U18: 2274.2093 | V18: 2736.2093 | W18: 3716.7178 | X18: 4316.1017 | Y18: 4861.9291 | Z18: 6508.6213 | AA18: 8033.117 | AB18: 9688.3621 | AC18: 11199.644
P19: DMX | Q19: Sales + P1 | R19: 666 | S19: 1400.8364 | T19: 1843.2093 | U19: 2274.2093 | V19: 2736.2093 | W19: 3716.7178 | X19: 4316.1017 | Y19: 4861.9291 | Z19: 6508.6213 | AA19: 8033.117 | AB19: 9688.3621 | AC19: 11319.644
P20: DBR | Q20: Budget | R20: 1539.9073 | S20: 3040.2 | T20: 4636.4284 | U20: 6510.7184 | V20: 7837.6181 | W20: 8801.1517 | X20: 10266.892 | Y20: 11572.15 | Z20: 12715.025 | AA20: 13719.945 | AB20: 14473.888 | AC20: 15423.88
P21: DBR | Q21: Sales | R21: 1324 | S21: 2581 | T21: 3672 | U21: 5849 | V21: 6999 | W21: 8258 | X21: 10452.448 | Y21: 11945.132 | Z21: 13433.124 | AA21: 14598.122 | AB21: 14905.08 | AC21: 15054.979
P22: DBR | Q22: Sales + P1 | R22: 1324 | S22: 2581 | T22: 3672 | U22: 5849 | V22: 6999 | W22: 8258 | X22: 10452.448 | Y22: 11945.132 | Z22: 13433.124 | AA22: 14737.122 | AB22: 15081.08 | AC22: 15230.979
P23: FFLEX | Q23: Budget | R23: 200 | S23: 400 | T23: 600 | U23: 800 | V23: 1000 | W23: 1200 | X23: 1400 | Y23: 1600 | Z23: 1800 | AA23: 2000 | AB23: 2200 | AC23: 2400
P24: FFLEX | Q24: Sales | R24: 87.572356 | S24: 182.02014 | T24: 310.91514 | U24: 421.8412 | V24: 556.36284 | W24: 717.4783 | X24: 834.07564 | Y24: 1007.2527 | Z24: 1628.9458 | AA24: 2028.6654 | AB24: 2036.1834 | AC24: 2064.997
P25: FFLEX | Q25: Sales + P1 | R25: 87.572356 | S25: 182.02014 | T25: 310.91514 | U25: 421.8412 | V25: 556.36284 | W25: 717.4783 | X25: 834.07564 | Y25: 1007.2527 | Z25: 1628.9458 | AA25: 2028.6654 | AB25: 2036.1834 | AC25: 2064.997

Sheet Management Checks
A1: DIAM · MANAGEMENT CHECKS
A3: W35 · 30 Aug 2026 · Global view · All sales · Sales + P1 · Reporting unit EUR K · FX 1 EUR = 1.18 USD
A5: 0 item(s) to review
